Workbook
Name \0: '[1]PNT-QUOT-#3'!#REF!
Name \0: '[1]PNT-QUOT-#3'!#REF!
Name \a: #REF!
Name \a: #REF!
Name \a: #REF!
Name \P: #REF!
Name \P: #REF!
Name \P: #REF!
Name \z: #N/A
Name _: #REF!
Name _: #REF!
Name _?: #REF!
Name _?: #REF!
Name _?쨲?f: #REF!
Name _?쨲?f: #REF!
Name _________________MN1: #REF!
Name _________________MN1: #REF!
Name _________________MN2: #REF!
Name _________________MN2: #REF!
Name _________________MT1: #REF!
Name _________________MT1: #REF!
Name _________________MT2: #REF!
Name _________________tg427: #REF!
Name _________________UT2: #REF!
Name ________________atn1: #REF!
Name ________________atn10: #REF!
Name ________________atn2: #REF!
Name ________________atn3: #REF!
Name ________________atn4: #REF!
Name ________________atn5: #REF!
Name ________________atn6: #REF!
Name ________________atn7: #REF!
Name ________________atn8: #REF!
Name ________________atn9: #REF!
Name ________________CON1: #REF!
Name ________________CON2: #REF!
Name ________________cpd1: #REF!
Name ________________cpd2: #REF!
Name ________________deo1: #REF!
Name ________________deo10: #REF!
Name ________________deo2: #REF!
Name ________________deo3: #REF!
Name ________________deo4: #REF!
Name ________________deo5: #REF!
Name ________________deo6: #REF!
Name ________________deo7: #REF!
Name ________________deo8: #REF!
Name ________________deo9: #REF!
Name ________________khu7: #REF!
Name ________________nc151: #REF!
Name ________________NET2: #REF!
Name ________________tct5: #REF!
Name ________________TH20: #REF!
Name ________________xx3: #REF!
Name ________________xx4: #REF!
Name ________________xx5: #REF!
Name ________________xx6: #REF!
Name ________________xx7: #REF!
Name ______________Cau2: #REF!
Name ______________deo6: #REF!

Sheet TH1
C3: STT | D3: Tên | E3: Lĩnh vực HĐ | G3: Tên viết tắt
C4: 1 | D4: DV Quang Phát | E4: Bê Tông, TMDV Xi sắt | G4: =C4&"."&D4 -> 1.DV Quang Phát
C5: 2 | D5: BT Quang Phát | E5: Bê Tông, TMDV Xi sắt | G5: =C5&"."&D5 -> 2.BT Quang Phát
C6: 3 | D6: Kim Quang Phát | E6: Chăn nuôi gà giống và gà thịt | G6: =C6&"."&D6 -> 3.Kim Quang Phát
C7: 4 | D7: Kim Mỹ Linh | E7: Thương mại | G7: =C7&"."&D7 -> 4.Kim Mỹ Linh
C8: 5 | D8: Vạn Xuân | E8: Thương mại | G8: =C8&"."&D8 -> 5.Vạn Xuân
C9: 6 | G9: =C9&"."&D9 -> 6.
C14: NỘI DUNG
C16: 1 | D16: THÔNG TIN CHUNG
C17: 1.1 | D17: Lịch sử hình thành
C18: 1.2 | D18: Cấu trúc Sở hữu
C19: 1.3 | D19: Hoạt động (SP) | E19: đang cập nhật
C20: 1.4 | D20: Pháp nhân - NM
C21: 1.5 | D21: Công suất | E21: đang cập nhật
C23: 2 | D23: BÁO CÁO TÀI CHÍNH
C24: 2.1 | D24: BC_Phap nhan | E24: (Thuế)
C25: 2.2 | D25: BC_Năm | E25: (Thuế)
C26: 2.3 | D26: BC_San pham | E26: Chưa có dữ liệu
C27: 2.4 | D27: BC_Hoat dong | E27: Chưa có dữ liệu

Sheet 1.PL (VND) 
B2: KẾT QUẢ HOẠT ĐỘNG KINH DOANH | F2: Trước điều chỉnh | J2: Trước điều chỉnh | O2: Trước điều chỉnh | T2: Trước điều chỉnh | Y2: Trước điều chỉnh | AD2: Trước điều chỉnh | AJ2: Điều chỉnh | AO2: Điều chỉnh | AT2: Điều chỉnh | AY2: Điều chỉnh | BD2: Điều chỉnh | BI2: Điều chỉnh | BN2: Sau điều chỉnh | BS2: Sau điều chỉnh | BX2: Sau điều chỉnh | CM2: Sau điều chỉnh | CR2: Sau điều chỉnh | CW2: Điều chỉnh Nội bộ | DB2: Sau điều chỉnh nộ bộ
AH4: =$AH$5&$AJ$2&AH6 -> 1.DV Quang PhátĐiều chỉnh 2020 | AI4: =$AH$5&AI6 -> 1.DV Quang Phát2021 | AJ4: =$AH$5&$AJ$2&AJ6 -> 1.DV Quang PhátĐiều chỉnh 2022 | AK4: =$AH$5&$AJ$2&AK6 -> 1.DV Quang PhátĐiều chỉnh 2023 | AM4: =$AM5&$AJ$2&AM6 -> 2.BT Quang PhátĐiều chỉnh 2020 | AN4: =$AM5&$AJ$2&AN6 -> 2.BT Quang PhátĐiều chỉnh 2021 | AO4: =$AM5&$AJ$2&AO6 -> 2.BT Quang PhátĐiều chỉnh 2022 | AP4: =$AM5&$AJ$2&AP6 -> 2.BT Quang PhátĐiều chỉnh 2023 | AR4: =$AR$5&$AT$2&AR6 -> 3.Kim Quang PhátĐiều chỉnh 2020 | AS4: =$AR$5&$AT$2&AS6 -> 3.Kim Quang PhátĐiều chỉnh 2021 | AT4: =$AR$5&AT6 -> 3.Kim Quang Phát2022 | AU4: =$AR$5&$AT$2&AU6 -> 3.Kim Quang PhátĐiều chỉnh 2023 | AW4: =$AW$5&$AT$2&AW6 -> 4.Kim Mỹ LinhĐiều chỉnh 2020 | AX4: =$AW$5&$AT$2&AX6 -> 4.Kim Mỹ LinhĐiều chỉnh 2021 | AY4: =$AW$5&$AT$2&AY6 -> 4.Kim Mỹ LinhĐiều chỉnh 2022 | AZ4: =$AW$5&$AT$2&AZ6 -> 4.Kim Mỹ LinhĐiều chỉnh 2023 | BB4: =$BB$5&$AT$2&BB6 -> 5.Vạn XuânĐiều chỉnh 2020 | BC4: =$BB$5&$AT$2&BC6 -> 5.Vạn XuânĐiều chỉnh 2021 | BD4: =$BB$5&$AT$2&BD6 -> 5.Vạn XuânĐiều chỉnh 2022 | BE4: =$BB$5&$AT$2&BE6 -> 5.Vạn XuânĐiều chỉnh 2023 | BG4: =$BG5&$BI$2&BG6 -> 6.Điều chỉnh 2020 | BH4: =$BG5&$BI$2&BH6 -> 6.Điều chỉnh 2021 | BI4: =$BG5&$BI$2&BI6 -> 6.Điều chỉnh 2022 | BJ4: =$BG5&$BI$2&BJ6 -> 6.Điều chỉnh 2023 | CU4: ="ButruNB"&CU6 -> ButruNB2020 | CV4: ="ButruNB"&CV6 -> ButruNB2021 | CW4: ="ButruNB"&CW6 -> ButruNB2022 | CX4: ="ButruNB"&CX6 -> ButruNB2023
B5: Chỉ tiêu | C5: Mã số | D5: ='TH1'!G4 -> 1.DV Quang Phát | I5: ='TH1'!G5 -> 2.BT Quang Phát | N5: ='TH1'!G6 -> 3.Kim Quang Phát | S5: ='TH1'!G7 -> 4.Kim Mỹ Linh | X5: ='TH1'!G8 -> 5.Vạn Xuân | AC5: ='TH1'!G9 -> 6. | AH5: ='TH1'!G4 -> 1.DV Quang Phát | AM5: ='TH1'!G5 -> 2.BT Quang Phát | AR5: ='TH1'!G6 -> 3.Kim Quang Phát | AW5: ='TH1'!G7 -> 4.Kim Mỹ Linh | BB5: ='TH1'!G8 -> 5.Vạn Xuân | BG5: ='TH1'!G9 -> 6. | BL5: =AH5 -> 1.DV Quang Phát | BQ5: ='TH1'!G5 -> 2.BT Quang Phát | BV5: ='TH1'!G6 -> 3.Kim Quang Phát | CA5: ='TH1'!G7 -> 4.Kim Mỹ Linh | CF5: ='TH1'!G8 -> 5.Vạn Xuân | CK5: ='TH1'!G9 -> 6. | CP5: Tổng | CU5: Tổng | CZ5: Tổng
B6: 1000000000 | D6: 2020 | E6: 2021 | F6: 2022 | G6: 2023 | I6: 2020 | J6: 2021 | K6: 2022 | L6: 2023 | N6: 2020 | O6: 2021 | P6: 2022 | Q6: 2023 | S6: 2020 | T6: 2021 | U6: 2022 | V6: 2023 | X6: 2020 | Y6: 2021 | Z6: 2022 | AA6: 2023 | AC6: 2020 | AD6: 2021 | AE6: 2022 | AF6: 2023 | AH6: 2020 | AI6: 2021 | AJ6: 2022 | AK6: 2023 | AM6: 2020 | AN6: 2021 | AO6: 2022 | AP6: 2023 | AR6: 2020 | AS6: 2021 | AT6: 2022 | AU6: 2023 | AW6: 2020 | AX6: 2021 | AY6: 2022 | AZ6: 2023 | BB6: 2020 | BC6: 2021 | BD6: 2022 | BE6: 2023 | BG6: 2020 | BH6: 2021 | BI6: 2022 | BJ6: 2023 | BL6: 2020 | BM6: 2021 | BN6: 2022 | BO6: 2023 | BQ6: 2020 | BR6: 2021 | BS6: 2022 | BT6: 2023 | BV6: 2020 | BW6: 2021 | BX6: 2022 | BY6: 2023 | CA6: 2020 | CB6: 2021 | CC6: 2022 | CD6: 2023 | CF6: 2020 | CG6: 2021 | CH6: 2022 | CI6: 2023 | CK6: 2020 | CL6: 2021 | CM6: 2022 | CN6: 2023 | CP6: 2020 | CQ6: 2021 | CR6: 2022 | CS6: 2023 | CU6: 2020 | CV6: 2021 | CW6: 2022 | CX6: 2023 | CZ6: 2020 | DA6: 2021 | DB6: 2022 | DC6: 2023
B8: 1. Doanh thu bán hàng | C8: 01 | D8: 272815509098 | E8: 361225907557 | F8: 423679605375 | G8: 441344076314 | I8: 0 | J8: 41462536713 | K8: 69811635749 | L8: 74678752638 | N8: 59548559255 | O8: 54917326996 | P8: 64008838727 | Q8: 58809727981 | S8: 20700982927 | T8: 43997295527 | U8: 45487103106 | V8: 43100304580 | AH8: =-SUMIFS('1.DC_Ra soat'!$L:$L,'1.DC_Ra soat'!$F:$F,'1.PL (VND) '!AH$4,'1.DC_Ra soat'!$H:$H,'1.PL (VND) '!$C8)+SUMIFS('1.DC_Ra soat'!$L:$L,'1.DC_Ra soat'!$F:$F,'1.PL (VND) '!AH$4,'1.DC_Ra soat'!$I:$I,'1.PL (VND) '!$C8) -> 0 | AI8: =-SUMIFS('1.DC_Ra soat'!$L:$L,'1.DC_Ra soat'!$F:$F,'1.PL (VND) '!AI$4,'1.DC_Ra soat'!$H:$H,'1.PL (VND) '!$C8)+SUMIFS('1.DC_Ra soat'!$L:$L,'1.DC_Ra soat'!$F:$F,'1.PL (VND) '!AI$4,'1.DC_Ra soat'!$I:$I,'1.PL (VND) '!$C8) -> 0 | AJ8: =-SUMIFS('1.DC_Ra soat'!$L:$L,'1.DC_Ra soat'!$F:$F,'1.PL (VND) '!AJ$4,'1.DC_Ra soat'!$H:$H,'1.PL (VND) '!$C8)+SUMIFS('1.DC_Ra soat'!$L:$L,'1.DC_Ra soat'!$F:$F,'1.PL (VND) '!AJ$4,'1.DC_Ra soat'!$I:$I,'1.PL (VND) '!$C8) -> 0 | AK8: =-SUMIFS('1.DC_Ra soat'!$L:$L,'1.DC_Ra soat'!$F:$F,'1.PL (VND) '!AK$4,'1.DC_Ra soat'!$H:$H,'1.PL (VND) '!$C8)+SUMIFS('1.DC_Ra soat'!$L:$L,'1.DC_Ra soat'!$F:$F,'1.PL (VND) '!AK$4,'1.DC_Ra soat'!$I:$I,'1.PL (VND) '!$C8) -> 0 | AM8: =-SUMIFS('1.DC_Ra soat'!$L:$L,'1.DC_Ra soat'!$F:$F,'1.PL (VND) '!AM$4,'1.DC_Ra soat'!$H:$H,'1.PL (VND) '!$C8)+SUMIFS('1.DC_Ra soat'!$L:$L,'1.DC_Ra soat'!$F:$F,'1.PL (VND) '!AM$4,'1.DC_Ra soat'!$I:$I,'1.PL (VND) '!$C8) -> 0 | AN8: =-SUMIFS('1.DC_Ra soat'!$L:$L,'1.DC_Ra soat'!$F:$F,'1.PL (VND) '!AN$4,'1.DC_Ra soat'!$H:$H,'1.PL (VND) '!$C8)+SUMIFS('1.DC_Ra soat'!$L:$L,'1.DC_Ra soat'!$F:$F,'1.PL (VND) '!AN$4,'1.DC_Ra soat'!$I:$I,'1.PL (VND) '!$C8) -> 0 | AO8: =-SUMIFS('1.DC_Ra soat'!$L:$L,'1.DC_Ra soat'!$F:$F,'1.PL (VND) '!AO$4,'1.DC_Ra soat'!$H:$H,'1.PL (VND) '!$C8)+SUMIFS('1.DC_Ra soat'!$L:$L,'1.DC_Ra soat'!$F:$F,'1.PL (VND) '!AO$4,'1.DC_Ra soat'!$I:$I,'1.PL (VND) '!$C8) -> 0 | AP8: =-SUMIFS('1.DC_Ra soat'!$L:$L,'1.DC_Ra soat'!$F:$F,'1.PL (VND) '!AP$4,'1.DC_Ra soat'!$H:$H,'1.PL (VND) '!$C8)+SUMIFS('1.DC_Ra soat'!$L:$L,'1.DC_Ra soat'!$F:$F,'1.PL (VND) '!AP$4,'1.DC_Ra soat'!$I:$I,'1.PL (VND) '!$C8) -> 0 | AR8: =-SUMIFS('1.DC_Ra soat'!$L:$L,'1.DC_Ra soat'!$F:$F,'1.PL (VND) '!AR$4,'1.DC_Ra soat'!$H:$H,'1.PL (VND) '!$C8)+SUMIFS('1.DC_Ra soat'!$L:$L,'1.DC_Ra soat'!$F:$F,'1.PL (VND) '!AR$4,'1.DC_Ra soat'!$I:$I,'1.PL (VND) '!$C8) -> 0 | AS8: =-SUMIFS('1.DC_Ra soat'!$L:$L,'1.DC_Ra soat'!$F:$F,'1.PL (VND) '!AS$4,'1.DC_Ra soat'!$H:$H,'1.PL (VND) '!$C8)+SUMIFS('1.DC_Ra soat'!$L:$L,'1.DC_Ra soat'!$F:$F,'1.PL (VND) '!AS$4,'1.DC_Ra soat'!$I:$I,'1.PL (VND) '!$C8) -> 0 | AT8: =-SUMIFS('1.DC_Ra soat'!$L:$L,'1.DC_Ra soat'!$F:$F,'1.PL (VND) '!AT$4,'1.DC_Ra soat'!$H:$H,'1.PL (VND) '!$C8)+SUMIFS('1.DC_Ra soat'!$L:$L,'1.DC_Ra soat'!$F:$F,'1.PL (VND) '!AT$4,'1.DC_Ra soat'!$I:$I,'1.PL (VND) '!$C8) -> 0 | AU8: =-SUMIFS('1.DC_Ra soat'!$L:$L,'1.DC_Ra soat'!$F:$F,'1.PL (VND) '!AU$4,'1.DC_Ra soat'!$H:$H,'1.PL (VND) '!$C8)+SUMIFS('1.DC_Ra soat'!$L:$L,'1.DC_Ra soat'!$F:$F,'1.PL (VND) '!AU$4,'1.DC_Ra soat'!$I:$I,'1.PL (VND) '!$C8) -> 0 | AW8: =-SUMIFS('1.DC_Ra soat'!$L:$L,'1.DC_Ra soat'!$F:$F,'1.PL (VND) '!AW$4,'1.DC_Ra soat'!$H:$H,'1.PL (VND) '!$C8)+SUMIFS('1.DC_Ra soat'!$L:$L,'1.DC_Ra soat'!$F:$F,'1.PL (VND) '!AW$4,'1.DC_Ra soat'!$I:$I,'1.PL (VND) '!$C8) -> 0 | AX8: =-SUMIFS('1.DC_Ra soat'!$L:$L,'1.DC_Ra soat'!$F:$F,'1.PL (VND) '!AX$4,'1.DC_Ra soat'!$H:$H,'1.PL (VND) '!$C8)+SUMIFS('1.DC_Ra soat'!$L:$L,'1.DC_Ra soat'!$F:$F,'1.PL (VND) '!AX$4,'1.DC_Ra soat'!$I:$I,'1.PL (VND) '!$C8) -> 0 | AY8: =-SUMIFS('1.DC_Ra soat'!$L:$L,'1.DC_Ra soat'!$F:$F,'1.PL (VND) '!AY$4,'1.DC_Ra soat'!$H:$H,'1.PL (VND) '!$C8)+SUMIFS('1.DC_Ra soat'!$L:$L,'1.DC_Ra soat'!$F:$F,'1.PL (VND) '!AY$4,'1.DC_Ra soat'!$I:$I,'1.PL (VND) '!$C8) -> 0 | AZ8: =-SUMIFS('1.DC_Ra soat'!$L:$L,'1.DC_Ra soat'!$F:$F,'1.PL (VND) '!AZ$4,'1.DC_Ra soat'!$H:$H,'1.PL (VND) '!$C8)+SUMIFS('1.DC_Ra soat'!$L:$L,'1.DC_Ra soat'!$F:$F,'1.PL (VND) '!AZ$4,'1.DC_Ra soat'!$I:$I,'1.PL (VND) '!$C8) -> 0 | BB8: =-SUMIFS('1.DC_Ra soat'!$L:$L,'1.DC_Ra soat'!$F:$F,'1.PL (VND) '!BB$4,'1.DC_Ra soat'!$H:$H,'1.PL (VND) '!$C8)+SUMIFS('1.DC_Ra soat'!$L:$L,'1.DC_Ra soat'!$F:$F,'1.PL (VND) '!BB$4,'1.DC_Ra soat'!$I:$I,'1.PL (VND) '!$C8) -> 0 | BC8: =-SUMIFS('1.DC_Ra soat'!$L:$L,'1.DC_Ra soat'!$F:$F,'1.PL (VND) '!BC$4,'1.DC_Ra soat'!$H:$H,'1.PL (VND) '!$C8)+SUMIFS('1.DC_Ra soat'!$L:$L,'1.DC_Ra soat'!$F:$F,'1.PL (VND) '!BC$4,'1.DC_Ra soat'!$I:$I,'1.PL (VND) '!$C8) -> 0 | BD8: =-SUMIFS('1.DC_Ra soat'!$L:$L,'1.DC_Ra soat'!$F:$F,'1.PL (VND) '!BD$4,'1.DC_Ra soat'!$H:$H,'1.PL (VND) '!$C8)+SUMIFS('1.DC_Ra soat'!$L:$L,'1.DC_Ra soat'!$F:$F,'1.PL (VND) '!BD$4,'1.DC_Ra soat'!$I:$I,'1.PL (VND) '!$C8) -> 0 | BE8: =-SUMIFS('1.DC_Ra soat'!$L:$L,'1.DC_Ra soat'!$F:$F,'1.PL (VND) '!BE$4,'1.DC_Ra soat'!$H:$H,'1.PL (VND) '!$C8)+SUMIFS('1.DC_Ra soat'!$L:$L,'1.DC_Ra soat'!$F:$F,'1.PL (VND) '!BE$4,'1.DC_Ra soat'!$I:$I,'1.PL (VND) '!$C8) -> 0 | BG8: =-SUMIFS('1.DC_Ra soat'!$L:$L,'1.DC_Ra soat'!$F:$F,'1.PL (VND) '!BG$4,'1.DC_Ra soat'!$H:$H,'1.PL (VND) '!$C8)+SUMIFS('1.DC_Ra soat'!$L:$L,'1.DC_Ra soat'!$F:$F,'1.PL (VND) '!BG$4,'1.DC_Ra soat'!$I:$I,'1.PL (VND) '!$C8) -> 0 | BH8: =-SUMIFS('1.DC_Ra soat'!$L:$L,'1.DC_Ra soat'!$F:$F,'1.PL (VND) '!BH$4,'1.DC_Ra soat'!$H:$H,'1.PL (VND) '!$C8)+SUMIFS('1.DC_Ra soat'!$L:$L,'1.DC_Ra soat'!$F:$F,'1.PL (VND) '!BH$4,'1.DC_Ra soat'!$I:$I,'1.PL (VND) '!$C8) -> 0 | BI8: =-SUMIFS('1.DC_Ra soat'!$L:$L,'1.DC_Ra soat'!$F:$F,'1.PL (VND) '!BI$4,'1.DC_Ra soat'!$H:$H,'1.PL (VND) '!$C8)+SUMIFS('1.DC_Ra soat'!$L:$L,'1.DC_Ra soat'!$F:$F,'1.PL (VND) '!BI$4,'1.DC_Ra soat'!$I:$I,'1.PL (VND) '!$C8) -> 0 | BJ8: =-SUMIFS('1.DC_Ra soat'!$L:$L,'1.DC_Ra soat'!$F:$F,'1.PL (VND) '!BJ$4,'1.DC_Ra soat'!$H:$H,'1.PL (VND) '!$C8)+SUMIFS('1.DC_Ra soat'!$L:$L,'1.DC_Ra soat'!$F:$F,'1.PL (VND) '!BJ$4,'1.DC_Ra soat'!$I:$I,'1.PL (VND) '!$C8) -> 0 | BL8: =D8+AH8 -> 272815509098 | BM8: =E8+AI8 -> 361225907557 | BN8: =F8+AJ8 -> 423679605375 | BO8: =G8+AK8 -> 441344076314 | BQ8: =I8+AM8 -> 0 | BR8: =J8+AN8 -> 41462536713 | BS8: =K8+AO8 -> 69811635749 | BT8: =L8+AP8 -> 74678752638 | BV8: =N8+AR8 -> 59548559255 | BW8: =O8+AS8 -> 54917326996 | BX8: =P8+AT8 -> 64008838727 | BY8: =Q8+AU8 -> 58809727981 | CA8: =S8+AW8 -> 20700982927 | CB8: =T8+AX8 -> 43997295527 | CC8: =U8+AY8 -> 45487103106 | CD8: =V8+AZ8 -> 43100304580 | CF8: =X8+BB8 -> 0 | CG8: =Y8+BC8 -> 0 | CH8: =Z8+BD8 -> 0 | CI8: =AA8+BE8 -> 0 | CK8: =AC8+BG8 -> 0 | CL8: =AD8+BH8 -> 0 | CM8: =AE8+BI8 -> 0 | CN8: =AF8+BJ8 -> 0 | CP8: =SUMIF($BL$6:$CD$6,CP$6,$BL8:$CD8) -> 353065051280 | CQ8: =SUMIF($BL$6:$CD$6,CQ$6,$BL8:$CD8) -> 501603066793 | CR8: =SUMIF($BL$6:$CD$6,CR$6,$BL8:$CD8) -> 602987182957 | CS8: =SUMIF($BL$6:$CD$6,CS$6,$BL8:$CD8) -> 617932861513 | CU8: =-SUMIFS('1.DC_Ra soat'!$L:$L,'1.DC_Ra soat'!$F:$F,'1.PL (VND) '!CU$4,'1.DC_Ra soat'!$H:$H,'1.PL (VND) '!$C8)+SUMIFS('1.DC_Ra soat'!$L:$L,'1.DC_Ra soat'!$F:$F,'1.PL (VND) '!CU$4,'1.DC_Ra soat'!$I:$I,'1.PL (VND) '!$C8) -> 0 | CV8: =-SUMIFS('1.DC_Ra soat'!$L:$L,'1.DC_Ra soat'!$F:$F,'1.PL (VND) '!CV$4,'1.DC_Ra soat'!$H:$H,'1.PL (VND) '!$C8)+SUMIFS('1.DC_Ra soat'!$L:$L,'1.DC_Ra soat'!$F:$F,'1.PL (VND) '!CV$4,'1.DC_Ra soat'!$I:$I,'1.PL (VND) '!$C8) -> 0 | CW8: =-SUMIFS('1.DC_Ra soat'!$L:$L,'1.DC_Ra soat'!$F:$F,'1.PL (VND) '!CW$4,'1.DC_Ra soat'!$H:$H,'1.PL (VND) '!$C8)+SUMIFS('1.DC_Ra soat'!$L:$L,'1.DC_Ra soat'!$F:$F,'1.PL (VND) '!CW$4,'1.DC_Ra soat'!$I:$I,'1.PL (VND) '!$C8) -> -97491273670 | CX8: =-SUMIFS('1.DC_Ra soat'!$L:$L,'1.DC_Ra soat'!$F:$F,'1.PL (VND) '!CX$4,'1.DC_Ra soat'!$H:$H,'1.PL (VND) '!$C8)+SUMIFS('1.DC_Ra soat'!$L:$L,'1.DC_Ra soat'!$F:$F,'1.PL (VND) '!CX$4,'1.DC_Ra soat'!$I:$I,'1.PL (VND) '!$C8) -> -85934511540 | CZ8: =CP8+CU8 -> 353065051280 | DA8: =CQ8+CV8 -> 501603066793 | DB8: =CR8+CW8 -> 505495909287 | DC8: =CS8+CX8 -> 531998349973
B9: 2. Các khoản giảm trừ | C9: 02 | F9: 311800426 | G9: 0 | I9: 0 | J9: 0 | K9: 0 | L9: 0 | AH9: =SUMIFS('1.DC_Ra soat'!$L:$L,'1.DC_Ra soat'!$F:$F,'1.PL (VND) '!AH$4,'1.DC_Ra soat'!$H:$H,'1.PL (VND) '!$C9)-SUMIFS('1.DC_Ra soat'!$L:$L,'1.DC_Ra soat'!$F:$F,'1.PL (VND) '!AH$4,'1.DC_Ra soat'!$I:$I,'1.PL (VND) '!$C9) -> 0 | AI9: =SUMIFS('1.DC_Ra soat'!$L:$L,'1.DC_Ra soat'!$F:$F,'1.PL (VND) '!AI$4,'1.DC_Ra soat'!$H:$H,'1.PL (VND) '!$C9)-SUMIFS('1.DC_Ra soat'!$L:$L,'1.DC_Ra soat'!$F:$F,'1.PL (VND) '!AI$4,'1.DC_Ra soat'!$I:$I,'1.PL (VND) '!$C9) -> 0 | AJ9: =SUMIFS('1.DC_Ra soat'!$L:$L,'1.DC_Ra soat'!$F:$F,'1.PL (VND) '!AJ$4,'1.DC_Ra soat'!$H:$H,'1.PL (VND) '!$C9)-SUMIFS('1.DC_Ra soat'!$L:$L,'1.DC_Ra soat'!$F:$F,'1.PL (VND) '!AJ$4,'1.DC_Ra soat'!$I:$I,'1.PL (VND) '!$C9) -> 0 | AK9: =SUMIFS('1.DC_Ra soat'!$L:$L,'1.DC_Ra soat'!$F:$F,'1.PL (VND) '!AK$4,'1.DC_Ra soat'!$H:$H,'1.PL (VND) '!$C9)-SUMIFS('1.DC_Ra soat'!$L:$L,'1.DC_Ra soat'!$F:$F,'1.PL (VND) '!AK$4,'1.DC_Ra soat'!$I:$I,'1.PL (VND) '!$C9) -> 0 | AM9: =SUMIFS('1.DC_Ra soat'!$L:$L,'1.DC_Ra soat'!$F:$F,'1.PL (VND) '!AM$4,'1.DC_Ra soat'!$H:$H,'1.PL (VND) '!$C9)-SUMIFS('1.DC_Ra soat'!$L:$L,'1.DC_Ra soat'!$F:$F,'1.PL (VND) '!AM$4,'1.DC_Ra soat'!$I:$I,'1.PL (VND) '!$C9) -> 0 | AN9: =SUMIFS('1.DC_Ra soat'!$L:$L,'1.DC_Ra soat'!$F:$F,'1.PL (VND) '!AN$4,'1.DC_Ra soat'!$H:$H,'1.PL (VND) '!$C9)-SUMIFS('1.DC_Ra soat'!$L:$L,'1.DC_Ra soat'!$F:$F,'1.PL (VND) '!AN$4,'1.DC_Ra soat'!$I:$I,'1.PL (VND) '!$C9) -> 0 | AO9: =SUMIFS('1.DC_Ra soat'!$L:$L,'1.DC_Ra soat'!$F:$F,'1.PL (VND) '!AO$4,'1.DC_Ra soat'!$H:$H,'1.PL (VND) '!$C9)-SUMIFS('1.DC_Ra soat'!$L:$L,'1.DC_Ra soat'!$F:$F,'1.PL (VND) '!AO$4,'1.DC_Ra soat'!$I:$I,'1.PL (VND) '!$C9) -> 0 | AP9: =SUMIFS('1.DC_Ra soat'!$L:$L,'1.DC_Ra soat'!$F:$F,'1.PL (VND) '!AP$4,'1.DC_Ra soat'!$H:$H,'1.PL (VND) '!$C9)-SUMIFS('1.DC_Ra soat'!$L:$L,'1.DC_Ra soat'!$F:$F,'1.PL (VND) '!AP$4,'1.DC_Ra soat'!$I:$I,'1.PL (VND) '!$C9) -> 0 | AR9: =SUMIFS('1.DC_Ra soat'!$L:$L,'1.DC_Ra soat'!$F:$F,'1.PL (VND) '!AR$4,'1.DC_Ra soat'!$H:$H,'1.PL (VND) '!$C9)-SUMIFS('1.DC_Ra soat'!$L:$L,'1.DC_Ra soat'!$F:$F,'1.PL (VND) '!AR$4,'1.DC_Ra soat'!$I:$I,'1.PL (VND) '!$C9) -> 0 | AS9: =SUMIFS('1.DC_Ra soat'!$L:$L,'1.DC_Ra soat'!$F:$F,'1.PL (VND) '!AS$4,'1.DC_Ra soat'!$H:$H,'1.PL (VND) '!$C9)-SUMIFS('1.DC_Ra soat'!$L:$L,'1.DC_Ra soat'!$F:$F,'1.PL (VND) '!AS$4,'1.DC_Ra soat'!$I:$I,'1.PL (VND) '!$C9) -> 0 | AT9: =SUMIFS('1.DC_Ra soat'!$L:$L,'1.DC_Ra soat'!$F:$F,'1.PL (VND) '!AT$4,'1.DC_Ra soat'!$H:$H,'1.PL (VND) '!$C9)-SUMIFS('1.DC_Ra soat'!$L:$L,'1.DC_Ra soat'!$F:$F,'1.PL (VND) '!AT$4,'1.DC_Ra soat'!$I:$I,'1.PL (VND) '!$C9) -> 0 | AU9: =SUMIFS('1.DC_Ra soat'!$L:$L,'1.DC_Ra soat'!$F:$F,'1.PL (VND) '!AU$4,'1.DC_Ra soat'!$H:$H,'1.PL (VND) '!$C9)-SUMIFS('1.DC_Ra soat'!$L:$L,'1.DC_Ra soat'!$F:$F,'1.PL (VND) '!AU$4,'1.DC_Ra soat'!$I:$I,'1.PL (VND) '!$C9) -> 0 | AW9: =SUMIFS('1.DC_Ra soat'!$L:$L,'1.DC_Ra soat'!$F:$F,'1.PL (VND) '!AW$4,'1.DC_Ra soat'!$H:$H,'1.PL (VND) '!$C9)-SUMIFS('1.DC_Ra soat'!$L:$L,'1.DC_Ra soat'!$F:$F,'1.PL (VND) '!AW$4,'1.DC_Ra soat'!$I:$I,'1.PL (VND) '!$C9) -> 0 | AX9: =SUMIFS('1.DC_Ra soat'!$L:$L,'1.DC_Ra soat'!$F:$F,'1.PL (VND) '!AX$4,'1.DC_Ra soat'!$H:$H,'1.PL (VND) '!$C9)-SUMIFS('1.DC_Ra soat'!$L:$L,'1.DC_Ra soat'!$F:$F,'1.PL (VND) '!AX$4,'1.DC_Ra soat'!$I:$I,'1.PL (VND) '!$C9) -> 0 | AY9: =SUMIFS('1.DC_Ra soat'!$L:$L,'1.DC_Ra soat'!$F:$F,'1.PL (VND) '!AY$4,'1.DC_Ra soat'!$H:$H,'1.PL (VND) '!$C9)-SUMIFS('1.DC_Ra soat'!$L:$L,'1.DC_Ra soat'!$F:$F,'1.PL (VND) '!AY$4,'1.DC_Ra soat'!$I:$I,'1.PL (VND) '!$C9) -> 0 | AZ9: =SUMIFS('1.DC_Ra soat'!$L:$L,'1.DC_Ra soat'!$F:$F,'1.PL (VND) '!AZ$4,'1.DC_Ra soat'!$H:$H,'1.PL (VND) '!$C9)-SUMIFS('1.DC_Ra soat'!$L:$L,'1.DC_Ra soat'!$F:$F,'1.PL (VND) '!AZ$4,'1.DC_Ra soat'!$I:$I,'1.PL (VND) '!$C9) -> 0 | BB9: =SUMIFS('1.DC_Ra soat'!$L:$L,'1.DC_Ra soat'!$F:$F,'1.PL (VND) '!BB$4,'1.DC_Ra soat'!$H:$H,'1.PL (VND) '!$C9)-SUMIFS('1.DC_Ra soat'!$L:$L,'1.DC_Ra soat'!$F:$F,'1.PL (VND) '!BB$4,'1.DC_Ra soat'!$I:$I,'1.PL (VND) '!$C9) -> 0 | BC9: =SUMIFS('1.DC_Ra soat'!$L:$L,'1.DC_Ra soat'!$F:$F,'1.PL (VND) '!BC$4,'1.DC_Ra soat'!$H:$H,'1.PL (VND) '!$C9)-SUMIFS('1.DC_Ra soat'!$L:$L,'1.DC_Ra soat'!$F:$F,'1.PL (VND) '!BC$4,'1.DC_Ra soat'!$I:$I,'1.PL (VND) '!$C9) -> 0 | BD9: =SUMIFS('1.DC_Ra soat'!$L:$L,'1.DC_Ra soat'!$F:$F,'1.PL (VND) '!BD$4,'1.DC_Ra soat'!$H:$H,'1.PL (VND) '!$C9)-SUMIFS('1.DC_Ra soat'!$L:$L,'1.DC_Ra soat'!$F:$F,'1.PL (VND) '!BD$4,'1.DC_Ra soat'!$I:$I,'1.PL (VND) '!$C9) -> 0 | BE9: =SUMIFS('1.DC_Ra soat'!$L:$L,'1.DC_Ra soat'!$F:$F,'1.PL (VND) '!BE$4,'1.DC_Ra soat'!$H:$H,'1.PL (VND) '!$C9)-SUMIFS('1.DC_Ra soat'!$L:$L,'1.DC_Ra soat'!$F:$F,'1.PL (VND) '!BE$4,'1.DC_Ra soat'!$I:$I,'1.PL (VND) '!$C9) -> 0 | BG9: =SUMIFS('1.DC_Ra soat'!$L:$L,'1.DC_Ra soat'!$F:$F,'1.PL (VND) '!BG$4,'1.DC_Ra soat'!$H:$H,'1.PL (VND) '!$C9)-SUMIFS('1.DC_Ra soat'!$L:$L,'1.DC_Ra soat'!$F:$F,'1.PL (VND) '!BG$4,'1.DC_Ra soat'!$I:$I,'1.PL (VND) '!$C9) -> 0 | BH9: =SUMIFS('1.DC_Ra soat'!$L:$L,'1.DC_Ra soat'!$F:$F,'1.PL (VND) '!BH$4,'1.DC_Ra soat'!$H:$H,'1.PL (VND) '!$C9)-SUMIFS('1.DC_Ra soat'!$L:$L,'1.DC_Ra soat'!$F:$F,'1.PL (VND) '!BH$4,'1.DC_Ra soat'!$I:$I,'1.PL (VND) '!$C9) -> 0 | BI9: =SUMIFS('1.DC_Ra soat'!$L:$L,'1.DC_Ra soat'!$F:$F,'1.PL (VND) '!BI$4,'1.DC_Ra soat'!$H:$H,'1.PL (VND) '!$C9)-SUMIFS('1.DC_Ra soat'!$L:$L,'1.DC_Ra soat'!$F:$F,'1.PL (VND) '!BI$4,'1.DC_Ra soat'!$I:$I,'1.PL (VND) '!$C9) -> 0 | BJ9: =SUMIFS('1.DC_Ra soat'!$L:$L,'1.DC_Ra soat'!$F:$F,'1.PL (VND) '!BJ$4,'1.DC_Ra soat'!$H:$H,'1.PL (VND) '!$C9)-SUMIFS('1.DC_Ra soat'!$L:$L,'1.DC_Ra soat'!$F:$F,'1.PL (VND) '!BJ$4,'1.DC_Ra soat'!$I:$I,'1.PL (VND) '!$C9) -> 0 | BL9: =D9+AH9 -> 0 | BM9: =E9+AI9 -> 0 | BN9: =F9+AJ9 -> 311800426 | BO9: =G9+AK9 -> 0 | BQ9: =I9+AM9 -> 0 | BR9: =J9+AN9 -> 0 | BS9: =K9+AO9 -> 0 | BT9: =L9+AP9 -> 0 | BV9: =N9+AR9 -> 0 | BW9: =O9+AS9 -> 0 | BX9: =P9+AT9 -> 0 | BY9: =Q9+AU9 -> 0 | CA9: =S9+AW9 -> 0 | CB9: =T9+AX9 -> 0 | CC9: =U9+AY9 -> 0 | CD9: =V9+AZ9 -> 0 | CF9: =X9+BB9 -> 0 | CG9: =Y9+BC9 -> 0 | CH9: =Z9+BD9 -> 0 | CI9: =AA9+BE9 -> 0 | CK9: =AC9+BG9 -> 0 | CL9: =AD9+BH9 -> 0 | CM9: =AE9+BI9 -> 0 | CN9: =AF9+BJ9 -> 0 | CP9: =SUMIF($BL$6:$CD$6,CP$6,$BL9:$CD9) -> 0 | CQ9: =SUMIF($BL$6:$CD$6,CQ$6,$BL9:$CD9) -> 0 | CR9: =SUMIF($BL$6:$CD$6,CR$6,$BL9:$CD9) -> 311800426 | CS9: =SUMIF($BL$6:$CD$6,CS$6,$BL9:$CD9) -> 0 | CU9: =-SUMIFS('1.DC_Ra soat'!$L:$L,'1.DC_Ra soat'!$F:$F,'1.PL (VND) '!CU$4,'1.DC_Ra soat'!$H:$H,'1.PL (VND) '!$C9)+SUMIFS('1.DC_Ra soat'!$L:$L,'1.DC_Ra soat'!$F:$F,'1.PL (VND) '!CU$4,'1.DC_Ra soat'!$I:$I,'1.PL (VND) '!$C9) -> 0 | CV9: =-SUMIFS('1.DC_Ra soat'!$L:$L,'1.DC_Ra soat'!$F:$F,'1.PL (VND) '!CV$4,'1.DC_Ra soat'!$H:$H,'1.PL (VND) '!$C9)+SUMIFS('1.DC_Ra soat'!$L:$L,'1.DC_Ra soat'!$F:$F,'1.PL (VND) '!CV$4,'1.DC_Ra soat'!$I:$I,'1.PL (VND) '!$C9) -> 0 | CW9: =-SUMIFS('1.DC_Ra soat'!$L:$L,'1.DC_Ra soat'!$F:$F,'1.PL (VND) '!CW$4,'1.DC_Ra soat'!$H:$H,'1.PL (VND) '!$C9)+SUMIFS('1.DC_Ra soat'!$L:$L,'1.DC_Ra soat'!$F:$F,'1.PL (VND) '!CW$4,'1.DC_Ra soat'!$I:$I,'1.PL (VND) '!$C9) -> 0 | CX9: =-SUMIFS('1.DC_Ra soat'!$L:$L,'1.DC_Ra soat'!$F:$F,'1.PL (VND) '!CX$4,'1.DC_Ra soat'!$H:$H,'1.PL (VND) '!$C9)+SUMIFS('1.DC_Ra soat'!$L:$L,'1.DC_Ra soat'!$F:$F,'1.PL (VND) '!CX$4,'1.DC_Ra soat'!$I:$I,'1.PL (VND) '!$C9) -> 0 | CZ9: =CP9+CU9 -> 0 | DA9: =CQ9+CV9 -> 0 | DB9: =CR9+CW9 -> 311800426 | DC9: =CS9+CX9 -> 0
B10: 3. Doanh thu thuần bán hàng | C10: 10 | D10: =D8-D9 -> 272815509098 | E10: =SUM(E8:E9) -> 361225907557 | F10: =SUM(F8:F9) -> 423991405801 | G10: =G8-G9 -> 441344076314 | I10: =I8-I9 -> 0 | J10: =J8-J9 -> 41462536713 | K10: =K8-K9 -> 69811635749 | L10: =L8-L9 -> 74678752638 | N10: =N8-N9 -> 59548559255 | O10: =O8-O9 -> 54917326996 | P10: =P8-P9 -> 64008838727 | Q10: =Q8-Q9 -> 58809727981 | S10: =S8-S9 -> 20700982927 | T10: =T8-T9 -> 43997295527 | U10: =U8-U9 -> 45487103106 | V10: =V8-V9 -> 43100304580 | X10: =X8-X9 -> 0 | Y10: =Y8-Y9 -> 0 | Z10: =Z8-Z9 -> 0 | AA10: =AA8-AA9 -> 0 | AC10: =AC8-AC9 -> 0 | AD10: =AD8-AD9 -> 0 | AE10: =AE8-AE9 -> 0 | AF10: =AF8-AF9 -> 0 | AH10: =AH8-AH9 -> 0 | AI10: =SUM(AI8:AI9) -> 0 | AJ10: =SUM(AJ8:AJ9) -> 0 | AK10: =SUM(AK8:AK9) -> 0 | AM10: =AM8-AM9 -> 0 | AN10: =AN8-AN9 -> 0 | AO10: =AO8-AO9 -> 0 | AP10: =AP8-AP9 -> 0 | AR10: =AR8-AR9 -> 0 | AS10: =AS8-AS9 -> 0 | AT10: =AT8-AT9 -> 0 | AU10: =AU8-AU9 -> 0 | AW10: =AW8-AW9 -> 0 | AX10: =AX8-AX9 -> 0 | AY10: =AY8-AY9 -> 0 | AZ10: =AZ8-AZ9 -> 0 | BB10: =BB8-BB9 -> 0 | BC10: =BC8-BC9 -> 0 | BD10: =BD8-BD9 -> 0 | BG10: =BG8-BG9 -> 0 | BH10: =BH8-BH9 -> 0 | BI10: =BI8-BI9 -> 0 | BL10: =D10+AH10 -> 272815509098 | BM10: =E10+AI10 -> 361225907557 | BN10: =F10+AJ10 -> 423991405801 | BO10: =G10+AK10 -> 441344076314 | BQ10: =I10+AM10 -> 0 | BR10: =J10+AN10 -> 41462536713 | BS10: =K10+AO10 -> 69811635749 | BT10: =L10+AP10 -> 74678752638 | BV10: =N10+AR10 -> 59548559255 | BW10: =O10+AS10 -> 54917326996 | BX10: =P10+AT10 -> 64008838727 | BY10: =Q10+AU10 -> 58809727981 | CA10: =S10+AW10 -> 20700982927 | CB10: =T10+AX10 -> 43997295527 | CC10: =U10+AY10 -> 45487103106 | CD10: =V10+AZ10 -> 43100304580 | CF10: =X10+BB10 -> 0 | CG10: =Y10+BC10 -> 0 | CH10: =Z10+BD10 -> 0 | CI10: =AA10+BE10 -> 0 | CK10: =AC10+BG10 -> 0 | CL10: =AD10+BH10 -> 0 | CM10: =AE10+BI10 -> 0 | CN10: =AF10+BJ10 -> 0 | CP10: =SUMIF($BL$6:$CD$6,CP$6,$BL10:$CD10) -> 353065051280 | CQ10: =SUMIF($BL$6:$CD$6,CQ$6,$BL10:$CD10) -> 501603066793 | CR10: =SUMIF($BL$6:$CD$6,CR$6,$BL10:$CD10) -> 603298983383 | CS10: =SUMIF($BL$6:$CD$6,CS$6,$BL10:$CD10) -> 617932861513 | CU10: =CU8-CU9 -> 0 | CV10: =CV8-CV9 -> 0 | CW10: =CW8-CW9 -> -97491273670 | CX10: =CX8-CX9 -> -85934511540 | CZ10: =CP10+CU10 -> 353065051280 | DA10: =CQ10+CV10 -> 501603066793 | DB10: =CR10+CW10 -> 505807709713 | DC10: =CS10+CX10 -> 531998349973
B11: 4. Giá vốn hàng bán | C11: 11 | D11: 258558885567 | E11: 344462402703 | F11: 407464072565 | G11: 407961793699 | J11: 39077128120 | K11: 70442604236 | L11: 41666803163 | N11: 53813171869 | O11: 47543364530 | P11: 60151917597 | Q11: 58359783404 | S11: 20334102810 | T11: 41893581101 | U11: 44696628066 | V11: 42396032419 | AH11: =SUMIFS('1.DC_Ra soat'!$L:$L,'1.DC_Ra soat'!$F:$F,'1.PL (VND) '!AH$4,'1.DC_Ra soat'!$H:$H,'1.PL (VND) '!$C11)-SUMIFS('1.DC_Ra soat'!$L:$L,'1.DC_Ra soat'!$F:$F,'1.PL (VND) '!AH$4,'1.DC_Ra soat'!$I:$I,'1.PL (VND) '!$C11) -> 0 | AI11: =SUMIFS('1.DC_Ra soat'!$L:$L,'1.DC_Ra soat'!$F:$F,'1.PL (VND) '!AI$4,'1.DC_Ra soat'!$H:$H,'1.PL (VND) '!$C11)-SUMIFS('1.DC_Ra soat'!$L:$L,'1.DC_Ra soat'!$F:$F,'1.PL (VND) '!AI$4,'1.DC_Ra soat'!$I:$I,'1.PL (VND) '!$C11) -> 0 | AJ11: =SUMIFS('1.DC_Ra soat'!$L:$L,'1.DC_Ra soat'!$F:$F,'1.PL (VND) '!AJ$4,'1.DC_Ra soat'!$H:$H,'1.PL (VND) '!$C11)-SUMIFS('1.DC_Ra soat'!$L:$L,'1.DC_Ra soat'!$F:$F,'1.PL (VND) '!AJ$4,'1.DC_Ra soat'!$I:$I,'1.PL (VND) '!$C11) -> 5249296703 | AK11: =SUMIFS('1.DC_Ra soat'!$L:$L,'1.DC_Ra soat'!$F:$F,'1.PL (VND) '!AK$4,'1.DC_Ra soat'!$H:$H,'1.PL (VND) '!$C11)-SUMIFS('1.DC_Ra soat'!$L:$L,'1.DC_Ra soat'!$F:$F,'1.PL (VND) '!AK$4,'1.DC_Ra soat'!$I:$I,'1.PL (VND) '!$C11) -> 1073603888 | AM11: =SUMIFS('1.DC_Ra soat'!$L:$L,'1.DC_Ra soat'!$F:$F,'1.PL (VND) '!AM$4,'1.DC_Ra soat'!$H:$H,'1.PL (VND) '!$C11)-SUMIFS('1.DC_Ra soat'!$L:$L,'1.DC_Ra soat'!$F:$F,'1.PL (VND) '!AM$4,'1.DC_Ra soat'!$I:$I,'1.PL (VND) '!$C11) -> 0 | AN11: =SUMIFS('1.DC_Ra soat'!$L:$L,'1.DC_Ra soat'!$F:$F,'1.PL (VND) '!AN$4,'1.DC_Ra soat'!$H:$H,'1.PL (VND) '!$C11)-SUMIFS('1.DC_Ra soat'!$L:$L,'1.DC_Ra soat'!$F:$F,'1.PL (VND) '!AN$4,'1.DC_Ra soat'!$I:$I,'1.PL (VND) '!$C11) -> 0 | AO11: =SUMIFS('1.DC_Ra soat'!$L:$L,'1.DC_Ra soat'!$F:$F,'1.PL (VND) '!AO$4,'1.DC_Ra soat'!$H:$H,'1.PL (VND) '!$C11)-SUMIFS('1.DC_Ra soat'!$L:$L,'1.DC_Ra soat'!$F:$F,'1.PL (VND) '!AO$4,'1.DC_Ra soat'!$I:$I,'1.PL (VND) '!$C11) -> 0 | AP11: =SUMIFS('1.DC_Ra soat'!$L:$L,'1.DC_Ra soat'!$F:$F,'1.PL (VND) '!AP$4,'1.DC_Ra soat'!$H:$H,'1.PL (VND) '!$C11)-SUMIFS('1.DC_Ra soat'!$L:$L,'1.DC_Ra soat'!$F:$F,'1.PL (VND) '!AP$4,'1.DC_Ra soat'!$I:$I,'1.PL (VND) '!$C11) -> 0 | AR11: =SUMIFS('1.DC_Ra soat'!$L:$L,'1.DC_Ra soat'!$F:$F,'1.PL (VND) '!AR$4,'1.DC_Ra soat'!$H:$H,'1.PL (VND) '!$C11)-SUMIFS('1.DC_Ra soat'!$L:$L,'1.DC_Ra soat'!$F:$F,'1.PL (VND) '!AR$4,'1.DC_Ra soat'!$I:$I,'1.PL (VND) '!$C11) -> 0 | AS11: =SUMIFS('1.DC_Ra soat'!$L:$L,'1.DC_Ra soat'!$F:$F,'1.PL (VND) '!AS$4,'1.DC_Ra soat'!$H:$H,'1.PL (VND) '!$C11)-SUMIFS('1.DC_Ra soat'!$L:$L,'1.DC_Ra soat'!$F:$F,'1.PL (VND) '!AS$4,'1.DC_Ra soat'!$I:$I,'1.PL (VND) '!$C11) -> 0 | AT11: =SUMIFS('1.DC_Ra soat'!$L:$L,'1.DC_Ra soat'!$F:$F,'1.PL (VND) '!AT$4,'1.DC_Ra soat'!$H:$H,'1.PL (VND) '!$C11)-SUMIFS('1.DC_Ra soat'!$L:$L,'1.DC_Ra soat'!$F:$F,'1.PL (VND) '!AT$4,'1.DC_Ra soat'!$I:$I,'1.PL (VND) '!$C11) -> 0 | AU11: =SUMIFS('1.DC_Ra soat'!$L:$L,'1.DC_Ra soat'!$F:$F,'1.PL (VND) '!AU$4,'1.DC_Ra soat'!$H:$H,'1.PL (VND) '!$C11)-SUMIFS('1.DC_Ra soat'!$L:$L,'1.DC_Ra soat'!$F:$F,'1.PL (VND) '!AU$4,'1.DC_Ra soat'!$I:$I,'1.PL (VND) '!$C11) -> 0 | AW11: =SUMIFS('1.DC_Ra soat'!$L:$L,'1.DC_Ra soat'!$F:$F,'1.PL (VND) '!AW$4,'1.DC_Ra soat'!$H:$H,'1.PL (VND) '!$C11)-SUMIFS('1.DC_Ra soat'!$L:$L,'1.DC_Ra soat'!$F:$F,'1.PL (VND) '!AW$4,'1.DC_Ra soat'!$I:$I,'1.PL (VND) '!$C11) -> 0 | AX11: =SUMIFS('1.DC_Ra soat'!$L:$L,'1.DC_Ra soat'!$F:$F,'1.PL (VND) '!AX$4,'1.DC_Ra soat'!$H:$H,'1.PL (VND) '!$C11)-SUMIFS('1.DC_Ra soat'!$L:$L,'1.DC_Ra soat'!$F:$F,'1.PL (VND) '!AX$4,'1.DC_Ra soat'!$I:$I,'1.PL (VND) '!$C11) -> 0 | AY11: =SUMIFS('1.DC_Ra soat'!$L:$L,'1.DC_Ra soat'!$F:$F,'1.PL (VND) '!AY$4,'1.DC_Ra soat'!$H:$H,'1.PL (VND) '!$C11)-SUMIFS('1.DC_Ra soat'!$L:$L,'1.DC_Ra soat'!$F:$F,'1.PL (VND) '!AY$4,'1.DC_Ra soat'!$I:$I,'1.PL (VND) '!$C11) -> 0 | AZ11: =SUMIFS('1.DC_Ra soat'!$L:$L,'1.DC_Ra soat'!$F:$F,'1.PL (VND) '!AZ$4,'1.DC_Ra soat'!$H:$H,'1.PL (VND) '!$C11)-SUMIFS('1.DC_Ra soat'!$L:$L,'1.DC_Ra soat'!$F:$F,'1.PL (VND) '!AZ$4,'1.DC_Ra soat'!$I:$I,'1.PL (VND) '!$C11) -> 0 | BB11: =SUMIFS('1.DC_Ra soat'!$L:$L,'1.DC_Ra soat'!$F:$F,'1.PL (VND) '!BB$4,'1.DC_Ra soat'!$H:$H,'1.PL (VND) '!$C11)-SUMIFS('1.DC_Ra soat'!$L:$L,'1.DC_Ra soat'!$F:$F,'1.PL (VND) '!BB$4,'1.DC_Ra soat'!$I:$I,'1.PL (VND) '!$C11) -> 0 | BC11: =SUMIFS('1.DC_Ra soat'!$L:$L,'1.DC_Ra soat'!$F:$F,'1.PL (VND) '!BC$4,'1.DC_Ra soat'!$H:$H,'1.PL (VND) '!$C11)-SUMIFS('1.DC_Ra soat'!$L:$L,'1.DC_Ra soat'!$F:$F,'1.PL (VND) '!BC$4,'1.DC_Ra soat'!$I:$I,'1.PL (VND) '!$C11) -> 0 | BD11: =SUMIFS('1.DC_Ra soat'!$L:$L,'1.DC_Ra soat'!$F:$F,'1.PL (VND) '!BD$4,'1.DC_Ra soat'!$H:$H,'1.PL (VND) '!$C11)-SUMIFS('1.DC_Ra soat'!$L:$L,'1.DC_Ra soat'!$F:$F,'1.PL (VND) '!BD$4,'1.DC_Ra soat'!$I:$I,'1.PL (VND) '!$C11) -> 0 | BE11: =SUMIFS('1.DC_Ra soat'!$L:$L,'1.DC_Ra soat'!$F:$F,'1.PL (VND) '!BE$4,'1.DC_Ra soat'!$H:$H,'1.PL (VND) '!$C11)-SUMIFS('1.DC_Ra soat'!$L:$L,'1.DC_Ra soat'!$F:$F,'1.PL (VND) '!BE$4,'1.DC_Ra soat'!$I:$I,'1.PL (VND) '!$C11) -> 0 | BG11: =SUMIFS('1.DC_Ra soat'!$L:$L,'1.DC_Ra soat'!$F:$F,'1.PL (VND) '!BG$4,'1.DC_Ra soat'!$H:$H,'1.PL (VND) '!$C11)-SUMIFS('1.DC_Ra soat'!$L:$L,'1.DC_Ra soat'!$F:$F,'1.PL (VND) '!BG$4,'1.DC_Ra soat'!$I:$I,'1.PL (VND) '!$C11) -> 0 | BH11: =SUMIFS('1.DC_Ra soat'!$L:$L,'1.DC_Ra soat'!$F:$F,'1.PL (VND) '!BH$4,'1.DC_Ra soat'!$H:$H,'1.PL (VND) '!$C11)-SUMIFS('1.DC_Ra soat'!$L:$L,'1.DC_Ra soat'!$F:$F,'1.PL (VND) '!BH$4,'1.DC_Ra soat'!$I:$I,'1.PL (VND) '!$C11) -> 0 | BI11: =SUMIFS('1.DC_Ra soat'!$L:$L,'1.DC_Ra soat'!$F:$F,'1.PL (VND) '!BI$4,'1.DC_Ra soat'!$H:$H,'1.PL (VND) '!$C11)-SUMIFS('1.DC_Ra soat'!$L:$L,'1.DC_Ra soat'!$F:$F,'1.PL (VND) '!BI$4,'1.DC_Ra soat'!$I:$I,'1.PL (VND) '!$C11) -> 0 | BJ11: =SUMIFS('1.DC_Ra soat'!$L:$L,'1.DC_Ra soat'!$F:$F,'1.PL (VND) '!BJ$4,'1.DC_Ra soat'!$H:$H,'1.PL (VND) '!$C11)-SUMIFS('1.DC_Ra soat'!$L:$L,'1.DC_Ra soat'!$F:$F,'1.PL (VND) '!BJ$4,'1.DC_Ra soat'!$I:$I,'1.PL (VND) '!$C11) -> 0 | BL11: =D11+AH11 -> 258558885567 | BM11: =E11+AI11 -> 344462402703 | BN11: =F11+AJ11 -> 412713369268 | BO11: =G11+AK11 -> 409035397587 | BQ11: =I11+AM11 -> 0 | BR11: =J11+AN11 -> 39077128120 | BS11: =K11+AO11 -> 70442604236 | BT11: =L11+AP11 -> 41666803163 | BV11: =N11+AR11 -> 53813171869 | BW11: =O11+AS11 -> 47543364530 | BX11: =P11+AT11 -> 60151917597 | BY11: =Q11+AU11 -> 58359783404 | CA11: =S11+AW11 -> 20334102810 | CB11: =T11+AX11 -> 41893581101 | CC11: =U11+AY11 -> 44696628066 | CD11: =V11+AZ11 -> 42396032419 | CF11: =X11+BB11 -> 0 | CG11: =Y11+BC11 -> 0 | CH11: =Z11+BD11 -> 0 | CI11: =AA11+BE11 -> 0 | CK11: =AC11+BG11 -> 0 | CL11: =AD11+BH11 -> 0 | CM11: =AE11+BI11 -> 0 | CN11: =AF11+BJ11 -> 0 | CP11: =SUMIF($BL$6:$CD$6,CP$6,$BL11:$CD11) -> 332706160246 | CQ11: =SUMIF($BL$6:$CD$6,CQ$6,$BL11:$CD11) -> 472976476454 | CR11: =SUMIF($BL$6:$CD$6,CR$6,$BL11:$CD11) -> 588004519167 | CS11: =SUMIF($BL$6:$CD$6,CS$6,$BL11:$CD11) -> 551458016573 | CU11: =SUMIFS('1.DC_Ra soat'!$L:$L,'1.DC_Ra soat'!$F:$F,'1.PL (VND) '!CU$4,'1.DC_Ra soat'!$H:$H,'1.PL (VND) '!$C11)-SUMIFS('1.DC_Ra soat'!$L:$L,'1.DC_Ra soat'!$F:$F,'1.PL (VND) '!CU$4,'1.DC_Ra soat'!$I:$I,'1.PL (VND) '!$C11) -> 0 | CV11: =SUMIFS('1.DC_Ra soat'!$L:$L,'1.DC_Ra soat'!$F:$F,'1.PL (VND) '!CV$4,'1.DC_Ra soat'!$H:$H,'1.PL (VND) '!$C11)-SUMIFS('1.DC_Ra soat'!$L:$L,'1.DC_Ra soat'!$F:$F,'1.PL (VND) '!CV$4,'1.DC_Ra soat'!$I:$I,'1.PL (VND) '!$C11) -> 0 | CW11: =SUMIFS('1.DC_Ra soat'!$L:$L,'1.DC_Ra soat'!$F:$F,'1.PL (VND) '!CW$4,'1.DC_Ra soat'!$H:$H,'1.PL (VND) '!$C11)-SUMIFS('1.DC_Ra soat'!$L:$L,'1.DC_Ra soat'!$F:$F,'1.PL (VND) '!CW$4,'1.DC_Ra soat'!$I:$I,'1.PL (VND) '!$C11) -> -97491273670 | CX11: =SUMIFS('1.DC_Ra soat'!$L:$L,'1.DC_Ra soat'!$F:$F,'1.PL (VND) '!CX$4,'1.DC_Ra soat'!$H:$H,'1.PL (VND) '!$C11)-SUMIFS('1.DC_Ra soat'!$L:$L,'1.DC_Ra soat'!$F:$F,'1.PL (VND) '!CX$4,'1.DC_Ra soat'!$I:$I,'1.PL (VND) '!$C11) -> -85934511540 | CZ11: =CP11+CU11 -> 332706160246 | DA11: =CQ11+CV11 -> 472976476454 | DB11: =CR11+CW11 -> 490513245497 | DC11: =CS11+CX11 -> 465523505033
B12: 5. Lợi nhuận gộp về bán hàng | C12: 20 | D12: =D10-D11 -> 14256623531 | E12: =E10-E11 -> 16763504854 | F12: =F10-F11 -> 16527333236 | G12: =G10-G11 -> 33382282615 | I12: =I10-I11 -> 0 | J12: =J10-J11 -> 2385408593 | K12: =K10-K11 -> -630968487 | L12: =L10-L11 -> 33011949475 | N12: =N10-N11 -> 5735387386 | O12: =O10-O11 -> 7373962466 | P12: =P10-P11 -> 3856921130 | Q12: =Q10-Q11 -> 449944577 | S12: =S10-S11 -> 366880117 | T12: =T10-T11 -> 2103714426 | U12: =U10-U11 -> 790475040 | V12: =V10-V11 -> 704272161 | X12: =X10-X11 -> 0 | Y12: =Y10-Y11 -> 0 | Z12: =Z10-Z11 -> 0 | AA12: =AA10-AA11 -> 0 | AC12: =AC10-AC11 -> 0 | AD12: =AD10-AD11 -> 0 | AE12: =AE10-AE11 -> 0 | AF12: =AF10-AF11 -> 0 | AH12: =AH10-AH11 -> 0 | AI12: =AI10-AI11 -> 0 | AJ12: =AJ10-AJ11 -> -5249296703 | AK12: =AK10-AK11 -> -1073603888 | AM12: =AM10-AM11 -> 0 | AN12: =AN10-AN11 -> 0 | AO12: =AO10-AO11 -> 0 | AP12: =AP10-AP11 -> 0 | AR12: =AR10-AR11 -> 0 | AS12: =AS10-AS11 -> 0 | AT12: =AT10-AT11 -> 0 | AU12: =AU10-AU11 -> 0 | AW12: =AW10-AW11 -> 0 | AX12: =AX10-AX11 -> 0 | AY12: =AY10-AY11 -> 0 | AZ12: =AZ10-AZ11 -> 0 | BB12: =BB10-BB11 -> 0 | BC12: =BC10-BC11 -> 0 | BD12: =BD10-BD11 -> 0 | BG12: =BG10-BG11 -> 0 | BH12: =BH10-BH11 -> 0 | BI12: =BI10-BI11 -> 0 | BL12: =D12+AH12 -> 14256623531 | BM12: =E12+AI12 -> 16763504854 | BN12: =F12+AJ12 -> 11278036533 | BO12: =G12+AK12 -> 32308678727 | BQ12: =I12+AM12 -> 0 | BR12: =J12+AN12 -> 2385408593 | BS12: =K12+AO12 -> -630968487 | BT12: =L12+AP12 -> 33011949475 | BV12: =N12+AR12 -> 5735387386 | BW12: =O12+AS12 -> 7373962466 | BX12: =P12+AT12 -> 3856921130 | BY12: =Q12+AU12 -> 449944577 | CA12: =S12+AW12 -> 366880117 | CB12: =T12+AX12 -> 2103714426 | CC12: =U12+AY12 -> 790475040 | CD12: =V12+AZ12 -> 704272161 | CF12: =X12+BB12 -> 0 | CG12: =Y12+BC12 -> 0 | CH12: =Z12+BD12 -> 0 | CI12: =AA12+BE12 -> 0 | CK12: =AC12+BG12 -> 0 | CL12: =AD12+BH12 -> 0 | CM12: =AE12+BI12 -> 0 | CN12: =AF12+BJ12 -> 0 | CP12: =SUMIF($BL$6:$CD$6,CP$6,$BL12:$CD12) -> 20358891034 | CQ12: =SUMIF($BL$6:$CD$6,CQ$6,$BL12:$CD12) -> 28626590339 | CR12: =SUMIF($BL$6:$CD$6,CR$6,$BL12:$CD12) -> 15294464216 | CS12: =SUMIF($BL$6:$CD$6,CS$6,$BL12:$CD12) -> 66474844940 | CU12: =CU10-CU11 -> 0 | CV12: =CV10-CV11 -> 0 | CW12: =CW10-CW11 -> 0 | CX12: =CX10-CX11 -> 0 | CZ12: =CP12+CU12 -> 20358891034 | DA12: =CQ12+CV12 -> 28626590339 | DB12: =CR12+CW12 -> 15294464216 | DC12: =CS12+CX12 -> 66474844940
B13: 6. Doanh thu hoạt động tài chính | C13: 21 | D13: 833883 | E13: 524620 | F13: 2988510 | G13: 38735873 | I13: 1151 | J13: 28281 | K13: 135642 | L13: 99182 | N13: 87952 | O13: 42349 | P13: 154503 | Q13: 102331 | S13: 50076 | T13: 98187 | U13: 64876 | V13: 71367 | AH13: =-SUMIFS('1.DC_Ra soat'!$L:$L,'1.DC_Ra soat'!$F:$F,'1.PL (VND) '!AH$4,'1.DC_Ra soat'!$H:$H,'1.PL (VND) '!$C13)+SUMIFS('1.DC_Ra soat'!$L:$L,'1.DC_Ra soat'!$F:$F,'1.PL (VND) '!AH$4,'1.DC_Ra soat'!$I:$I,'1.PL (VND) '!$C13) -> 0 | AI13: =-SUMIFS('1.DC_Ra soat'!$L:$L,'1.DC_Ra soat'!$F:$F,'1.PL (VND) '!AI$4,'1.DC_Ra soat'!$H:$H,'1.PL (VND) '!$C13)+SUMIFS('1.DC_Ra soat'!$L:$L,'1.DC_Ra soat'!$F:$F,'1.PL (VND) '!AI$4,'1.DC_Ra soat'!$I:$I,'1.PL (VND) '!$C13) -> 0 | AJ13: =-SUMIFS('1.DC_Ra soat'!$L:$L,'1.DC_Ra soat'!$F:$F,'1.PL (VND) '!AJ$4,'1.DC_Ra soat'!$H:$H,'1.PL (VND) '!$C13)+SUMIFS('1.DC_Ra soat'!$L:$L,'1.DC_Ra soat'!$F:$F,'1.PL (VND) '!AJ$4,'1.DC_Ra soat'!$I:$I,'1.PL (VND) '!$C13) -> 0 | AK13: =-SUMIFS('1.DC_Ra soat'!$L:$L,'1.DC_Ra soat'!$F:$F,'1.PL (VND) '!AK$4,'1.DC_Ra soat'!$H:$H,'1.PL (VND) '!$C13)+SUMIFS('1.DC_Ra soat'!$L:$L,'1.DC_Ra soat'!$F:$F,'1.PL (VND) '!AK$4,'1.DC_Ra soat'!$I:$I,'1.PL (VND) '!$C13) -> 0 | AM13: =-SUMIFS('1.DC_Ra soat'!$L:$L,'1.DC_Ra soat'!$F:$F,'1.PL (VND) '!AM$4,'1.DC_Ra soat'!$H:$H,'1.PL (VND) '!$C13)+SUMIFS('1.DC_Ra soat'!$L:$L,'1.DC_Ra soat'!$F:$F,'1.PL (VND) '!AM$4,'1.DC_Ra soat'!$I:$I,'1.PL (VND) '!$C13) -> 0 | AN13: =-SUMIFS('1.DC_Ra soat'!$L:$L,'1.DC_Ra soat'!$F:$F,'1.PL (VND) '!AN$4,'1.DC_Ra soat'!$H:$H,'1.PL (VND) '!$C13)+SUMIFS('1.DC_Ra soat'!$L:$L,'1.DC_Ra soat'!$F:$F,'1.PL (VND) '!AN$4,'1.DC_Ra soat'!$I:$I,'1.PL (VND) '!$C13) -> 0 | AO13: =-SUMIFS('1.DC_Ra soat'!$L:$L,'1.DC_Ra soat'!$F:$F,'1.PL (VND) '!AO$4,'1.DC_Ra soat'!$H:$H,'1.PL (VND) '!$C13)+SUMIFS('1.DC_Ra soat'!$L:$L,'1.DC_Ra soat'!$F:$F,'1.PL (VND) '!AO$4,'1.DC_Ra soat'!$I:$I,'1.PL (VND) '!$C13) -> 0 | AP13: =-SUMIFS('1.DC_Ra soat'!$L:$L,'1.DC_Ra soat'!$F:$F,'1.PL (VND) '!AP$4,'1.DC_Ra soat'!$H:$H,'1.PL (VND) '!$C13)+SUMIFS('1.DC_Ra soat'!$L:$L,'1.DC_Ra soat'!$F:$F,'1.PL (VND) '!AP$4,'1.DC_Ra soat'!$I:$I,'1.PL (VND) '!$C13) -> 0 | AR13: =-SUMIFS('1.DC_Ra soat'!$L:$L,'1.DC_Ra soat'!$F:$F,'1.PL (VND) '!AR$4,'1.DC_Ra soat'!$H:$H,'1.PL (VND) '!$C13)+SUMIFS('1.DC_Ra soat'!$L:$L,'1.DC_Ra soat'!$F:$F,'1.PL (VND) '!AR$4,'1.DC_Ra soat'!$I:$I,'1.PL (VND) '!$C13) -> 0 | AS13: =-SUMIFS('1.DC_Ra soat'!$L:$L,'1.DC_Ra soat'!$F:$F,'1.PL (VND) '!AS$4,'1.DC_Ra soat'!$H:$H,'1.PL (VND) '!$C13)+SUMIFS('1.DC_Ra soat'!$L:$L,'1.DC_Ra soat'!$F:$F,'1.PL (VND) '!AS$4,'1.DC_Ra soat'!$I:$I,'1.PL (VND) '!$C13) -> 0 | AT13: =-SUMIFS('1.DC_Ra soat'!$L:$L,'1.DC_Ra soat'!$F:$F,'1.PL (VND) '!AT$4,'1.DC_Ra soat'!$H:$H,'1.PL (VND) '!$C13)+SUMIFS('1.DC_Ra soat'!$L:$L,'1.DC_Ra soat'!$F:$F,'1.PL (VND) '!AT$4,'1.DC_Ra soat'!$I:$I,'1.PL (VND) '!$C13) -> 0 | AU13: =-SUMIFS('1.DC_Ra soat'!$L:$L,'1.DC_Ra soat'!$F:$F,'1.PL (VND) '!AU$4,'1.DC_Ra soat'!$H:$H,'1.PL (VND) '!$C13)+SUMIFS('1.DC_Ra soat'!$L:$L,'1.DC_Ra soat'!$F:$F,'1.PL (VND) '!AU$4,'1.DC_Ra soat'!$I:$I,'1.PL (VND) '!$C13) -> 0 | AW13: =-SUMIFS('1.DC_Ra soat'!$L:$L,'1.DC_Ra soat'!$F:$F,'1.PL (VND) '!AW$4,'1.DC_Ra soat'!$H:$H,'1.PL (VND) '!$C13)+SUMIFS('1.DC_Ra soat'!$L:$L,'1.DC_Ra soat'!$F:$F,'1.PL (VND) '!AW$4,'1.DC_Ra soat'!$I:$I,'1.PL (VND) '!$C13) -> 0 | AX13: =-SUMIFS('1.DC_Ra soat'!$L:$L,'1.DC_Ra soat'!$F:$F,'1.PL (VND) '!AX$4,'1.DC_Ra soat'!$H:$H,'1.PL (VND) '!$C13)+SUMIFS('1.DC_Ra soat'!$L:$L,'1.DC_Ra soat'!$F:$F,'1.PL (VND) '!AX$4,'1.DC_Ra soat'!$I:$I,'1.PL (VND) '!$C13) -> 0 | AY13: =-SUMIFS('1.DC_Ra soat'!$L:$L,'1.DC_Ra soat'!$F:$F,'1.PL (VND) '!AY$4,'1.DC_Ra soat'!$H:$H,'1.PL (VND) '!$C13)+SUMIFS('1.DC_Ra soat'!$L:$L,'1.DC_Ra soat'!$F:$F,'1.PL (VND) '!AY$4,'1.DC_Ra soat'!$I:$I,'1.PL (VND) '!$C13) -> 0 | AZ13: =-SUMIFS('1.DC_Ra soat'!$L:$L,'1.DC_Ra soat'!$F:$F,'1.PL (VND) '!AZ$4,'1.DC_Ra soat'!$H:$H,'1.PL (VND) '!$C13)+SUMIFS('1.DC_Ra soat'!$L:$L,'1.DC_Ra soat'!$F:$F,'1.PL (VND) '!AZ$4,'1.DC_Ra soat'!$I:$I,'1.PL (VND) '!$C13) -> 0 | BB13: =-SUMIFS('1.DC_Ra soat'!$L:$L,'1.DC_Ra soat'!$F:$F,'1.PL (VND) '!BB$4,'1.DC_Ra soat'!$H:$H,'1.PL (VND) '!$C13)+SUMIFS('1.DC_Ra soat'!$L:$L,'1.DC_Ra soat'!$F:$F,'1.PL (VND) '!BB$4,'1.DC_Ra soat'!$I:$I,'1.PL (VND) '!$C13) -> 0 | BC13: =-SUMIFS('1.DC_Ra soat'!$L:$L,'1.DC_Ra soat'!$F:$F,'1.PL (VND) '!BC$4,'1.DC_Ra soat'!$H:$H,'1.PL (VND) '!$C13)+SUMIFS('1.DC_Ra soat'!$L:$L,'1.DC_Ra soat'!$F:$F,'1.PL (VND) '!BC$4,'1.DC_Ra soat'!$I:$I,'1.PL (VND) '!$C13) -> 0 | BD13: =-SUMIFS('1.DC_Ra soat'!$L:$L,'1.DC_Ra soat'!$F:$F,'1.PL (VND) '!BD$4,'1.DC_Ra soat'!$H:$H,'1.PL (VND) '!$C13)+SUMIFS('1.DC_Ra soat'!$L:$L,'1.DC_Ra soat'!$F:$F,'1.PL (VND) '!BD$4,'1.DC_Ra soat'!$I:$I,'1.PL (VND) '!$C13) -> 0 | BE13: =-SUMIFS('1.DC_Ra soat'!$L:$L,'1.DC_Ra soat'!$F:$F,'1.PL (VND) '!BE$4,'1.DC_Ra soat'!$H:$H,'1.PL (VND) '!$C13)+SUMIFS('1.DC_Ra soat'!$L:$L,'1.DC_Ra soat'!$F:$F,'1.PL (VND) '!BE$4,'1.DC_Ra soat'!$I:$I,'1.PL (VND) '!$C13) -> 0 | BG13: =-SUMIFS('1.DC_Ra soat'!$L:$L,'1.DC_Ra soat'!$F:$F,'1.PL (VND) '!BG$4,'1.DC_Ra soat'!$H:$H,'1.PL (VND) '!$C13)+SUMIFS('1.DC_Ra soat'!$L:$L,'1.DC_Ra soat'!$F:$F,'1.PL (VND) '!BG$4,'1.DC_Ra soat'!$I:$I,'1.PL (VND) '!$C13) -> 0 | BH13: =-SUMIFS('1.DC_Ra soat'!$L:$L,'1.DC_Ra soat'!$F:$F,'1.PL (VND) '!BH$4,'1.DC_Ra soat'!$H:$H,'1.PL (VND) '!$C13)+SUMIFS('1.DC_Ra soat'!$L:$L,'1.DC_Ra soat'!$F:$F,'1.PL (VND) '!BH$4,'1.DC_Ra soat'!$I:$I,'1.PL (VND) '!$C13) -> 0 | BI13: =-SUMIFS('1.DC_Ra soat'!$L:$L,'1.DC_Ra soat'!$F:$F,'1.PL (VND) '!BI$4,'1.DC_Ra soat'!$H:$H,'1.PL (VND) '!$C13)+SUMIFS('1.DC_Ra soat'!$L:$L,'1.DC_Ra soat'!$F:$F,'1.PL (VND) '!BI$4,'1.DC_Ra soat'!$I:$I,'1.PL (VND) '!$C13) -> 0 | BJ13: =-SUMIFS('1.DC_Ra soat'!$L:$L,'1.DC_Ra soat'!$F:$F,'1.PL (VND) '!BJ$4,'1.DC_Ra soat'!$H:$H,'1.PL (VND) '!$C13)+SUMIFS('1.DC_Ra soat'!$L:$L,'1.DC_Ra soat'!$F:$F,'1.PL (VND) '!BJ$4,'1.DC_Ra soat'!$I:$I,'1.PL (VND) '!$C13) -> 0 | BL13: =D13+AH13 -> 833883 | BM13: =E13+AI13 -> 524620 | BN13: =F13+AJ13 -> 2988510 | BO13: =G13+AK13 -> 38735873 | BQ13: =I13+AM13 -> 1151 | BR13: =J13+AN13 -> 28281 | BS13: =K13+AO13 -> 135642 | BT13: =L13+AP13 -> 99182 | BV13: =N13+AR13 -> 87952 | BW13: =O13+AS13 -> 42349 | BX13: =P13+AT13 -> 154503 | BY13: =Q13+AU13 -> 102331 | CA13: =S13+AW13 -> 50076 | CB13: =T13+AX13 -> 98187 | CC13: =U13+AY13 -> 64876 | CD13: =V13+AZ13 -> 71367 | CF13: =X13+BB13 -> 0 | CG13: =Y13+BC13 -> 0 | CH13: =Z13+BD13 -> 0 | CI13: =AA13+BE13 -> 0 | CK13: =AC13+BG13 -> 0 | CL13: =AD13+BH13 -> 0 | CM13: =AE13+BI13 -> 0 | CN13: =AF13+BJ13 -> 0 | CP13: =SUMIF($BL$6:$CD$6,CP$6,$BL13:$CD13) -> 973062 | CQ13: =SUMIF($BL$6:$CD$6,CQ$6,$BL13:$CD13) -> 693437 | CR13: =SUMIF($BL$6:$CD$6,CR$6,$BL13:$CD13) -> 3343531 | CS13: =SUMIF($BL$6:$CD$6,CS$6,$BL13:$CD13) -> 39008753 | CU13: =-SUMIFS('1.DC_Ra soat'!$L:$L,'1.DC_Ra soat'!$F:$F,'1.PL (VND) '!CU$4,'1.DC_Ra soat'!$H:$H,'1.PL (VND) '!$C13)+SUMIFS('1.DC_Ra soat'!$L:$L,'1.DC_Ra soat'!$F:$F,'1.PL (VND) '!CU$4,'1.DC_Ra soat'!$I:$I,'1.PL (VND) '!$C13) -> 0 | CV13: =-SUMIFS('1.DC_Ra soat'!$L:$L,'1.DC_Ra soat'!$F:$F,'1.PL (VND) '!CV$4,'1.DC_Ra soat'!$H:$H,'1.PL (VND) '!$C13)+SUMIFS('1.DC_Ra soat'!$L:$L,'1.DC_Ra soat'!$F:$F,'1.PL (VND) '!CV$4,'1.DC_Ra soat'!$I:$I,'1.PL (VND) '!$C13) -> 0 | CW13: =-SUMIFS('1.DC_Ra soat'!$L:$L,'1.DC_Ra soat'!$F:$F,'1.PL (VND) '!CW$4,'1.DC_Ra soat'!$H:$H,'1.PL (VND) '!$C13)+SUMIFS('1.DC_Ra soat'!$L:$L,'1.DC_Ra soat'!$F:$F,'1.PL (VND) '!CW$4,'1.DC_Ra soat'!$I:$I,'1.PL (VND) '!$C13) -> 0 | CX13: =-SUMIFS('1.DC_Ra soat'!$L:$L,'1.DC_Ra soat'!$F:$F,'1.PL (VND) '!CX$4,'1.DC_Ra soat'!$H:$H,'1.PL (VND) '!$C13)+SUMIFS('1.DC_Ra soat'!$L:$L,'1.DC_Ra soat'!$F:$F,'1.PL (VND) '!CX$4,'1.DC_Ra soat'!$I:$I,'1.PL (VND) '!$C13) -> 0 | CZ13: =CP13+CU13 -> 973062 | DA13: =CQ13+CV13 -> 693437 | DB13: =CR13+CW13 -> 3343531 | DC13: =CS13+CX13 -> 39008753
B14: 7. Chi phí tài chính | C14: 22 | D14: 8171598143 | E14: 4496061333 | F14: 8332900199 | G14: 12548808701 | J14: 725227638 | K14: 2586469172 | L14: 1890560444 | N14: 1336298435 | O14: 1675370773 | P14: 2178070579 | Q14: 2214890036 | S14: 296662990 | T14: 832438007 | U14: 1092759146 | V14: 1540066497 | AH14: =SUMIFS('1.DC_Ra soat'!$L:$L,'1.DC_Ra soat'!$F:$F,'1.PL (VND) '!AH$4,'1.DC_Ra soat'!$H:$H,'1.PL (VND) '!$C14)-SUMIFS('1.DC_Ra soat'!$L:$L,'1.DC_Ra soat'!$F:$F,'1.PL (VND) '!AH$4,'1.DC_Ra soat'!$I:$I,'1.PL (VND) '!$C14) -> 0 | AI14: =SUMIFS('1.DC_Ra soat'!$L:$L,'1.DC_Ra soat'!$F:$F,'1.PL (VND) '!AI$4,'1.DC_Ra soat'!$H:$H,'1.PL (VND) '!$C14)-SUMIFS('1.DC_Ra soat'!$L:$L,'1.DC_Ra soat'!$F:$F,'1.PL (VND) '!AI$4,'1.DC_Ra soat'!$I:$I,'1.PL (VND) '!$C14) -> 0 | AJ14: =SUMIFS('1.DC_Ra soat'!$L:$L,'1.DC_Ra soat'!$F:$F,'1.PL (VND) '!AJ$4,'1.DC_Ra soat'!$H:$H,'1.PL (VND) '!$C14)-SUMIFS('1.DC_Ra soat'!$L:$L,'1.DC_Ra soat'!$F:$F,'1.PL (VND) '!AJ$4,'1.DC_Ra soat'!$I:$I,'1.PL (VND) '!$C14) -> 5500420923 | AK14: =SUMIFS('1.DC_Ra soat'!$L:$L,'1.DC_Ra soat'!$F:$F,'1.PL (VND) '!AK$4,'1.DC_Ra soat'!$H:$H,'1.PL (VND) '!$C14)-SUMIFS('1.DC_Ra soat'!$L:$L,'1.DC_Ra soat'!$F:$F,'1.PL (VND) '!AK$4,'1.DC_Ra soat'!$I:$I,'1.PL (VND) '!$C14) -> 0 | AM14: =SUMIFS('1.DC_Ra soat'!$L:$L,'1.DC_Ra soat'!$F:$F,'1.PL (VND) '!AM$4,'1.DC_Ra soat'!$H:$H,'1.PL (VND) '!$C14)-SUMIFS('1.DC_Ra soat'!$L:$L,'1.DC_Ra soat'!$F:$F,'1.PL (VND) '!AM$4,'1.DC_Ra soat'!$I:$I,'1.PL (VND) '!$C14) -> 0 | AN14: =SUMIFS('1.DC_Ra soat'!$L:$L,'1.DC_Ra soat'!$F:$F,'1.PL (VND) '!AN$4,'1.DC_Ra soat'!$H:$H,'1.PL (VND) '!$C14)-SUMIFS('1.DC_Ra soat'!$L:$L,'1.DC_Ra soat'!$F:$F,'1.PL (VND) '!AN$4,'1.DC_Ra soat'!$I:$I,'1.PL (VND) '!$C14) -> 0 | AO14: =SUMIFS('1.DC_Ra soat'!$L:$L,'1.DC_Ra soat'!$F:$F,'1.PL (VND) '!AO$4,'1.DC_Ra soat'!$H:$H,'1.PL (VND) '!$C14)-SUMIFS('1.DC_Ra soat'!$L:$L,'1.DC_Ra soat'!$F:$F,'1.PL (VND) '!AO$4,'1.DC_Ra soat'!$I:$I,'1.PL (VND) '!$C14) -> 741540549 | AP14: =SUMIFS('1.DC_Ra soat'!$L:$L,'1.DC_Ra soat'!$F:$F,'1.PL (VND) '!AP$4,'1.DC_Ra soat'!$H:$H,'1.PL (VND) '!$C14)-SUMIFS('1.DC_Ra soat'!$L:$L,'1.DC_Ra soat'!$F:$F,'1.PL (VND) '!AP$4,'1.DC_Ra soat'!$I:$I,'1.PL (VND) '!$C14) -> 0 | AR14: =SUMIFS('1.DC_Ra soat'!$L:$L,'1.DC_Ra soat'!$F:$F,'1.PL (VND) '!AR$4,'1.DC_Ra soat'!$H:$H,'1.PL (VND) '!$C14)-SUMIFS('1.DC_Ra soat'!$L:$L,'1.DC_Ra soat'!$F:$F,'1.PL (VND) '!AR$4,'1.DC_Ra soat'!$I:$I,'1.PL (VND) '!$C14) -> 0 | AS14: =SUMIFS('1.DC_Ra soat'!$L:$L,'1.DC_Ra soat'!$F:$F,'1.PL (VND) '!AS$4,'1.DC_Ra soat'!$H:$H,'1.PL (VND) '!$C14)-SUMIFS('1.DC_Ra soat'!$L:$L,'1.DC_Ra soat'!$F:$F,'1.PL (VND) '!AS$4,'1.DC_Ra soat'!$I:$I,'1.PL (VND) '!$C14) -> 0 | AT14: =SUMIFS('1.DC_Ra soat'!$L:$L,'1.DC_Ra soat'!$F:$F,'1.PL (VND) '!AT$4,'1.DC_Ra soat'!$H:$H,'1.PL (VND) '!$C14)-SUMIFS('1.DC_Ra soat'!$L:$L,'1.DC_Ra soat'!$F:$F,'1.PL (VND) '!AT$4,'1.DC_Ra soat'!$I:$I,'1.PL (VND) '!$C14) -> 0 | AU14: =SUMIFS('1.DC_Ra soat'!$L:$L,'1.DC_Ra soat'!$F:$F,'1.PL (VND) '!AU$4,'1.DC_Ra soat'!$H:$H,'1.PL (VND) '!$C14)-SUMIFS('1.DC_Ra soat'!$L:$L,'1.DC_Ra soat'!$F:$F,'1.PL (VND) '!AU$4,'1.DC_Ra soat'!$I:$I,'1.PL (VND) '!$C14) -> 0 | AW14: =SUMIFS('1.DC_Ra soat'!$L:$L,'1.DC_Ra soat'!$F:$F,'1.PL (VND) '!AW$4,'1.DC_Ra soat'!$H:$H,'1.PL (VND) '!$C14)-SUMIFS('1.DC_Ra soat'!$L:$L,'1.DC_Ra soat'!$F:$F,'1.PL (VND) '!AW$4,'1.DC_Ra soat'!$I:$I,'1.PL (VND) '!$C14) -> 0 | AX14: =SUMIFS('1.DC_Ra soat'!$L:$L,'1.DC_Ra soat'!$F:$F,'1.PL (VND) '!AX$4,'1.DC_Ra soat'!$H:$H,'1.PL (VND) '!$C14)-SUMIFS('1.DC_Ra soat'!$L:$L,'1.DC_Ra soat'!$F:$F,'1.PL (VND) '!AX$4,'1.DC_Ra soat'!$I:$I,'1.PL (VND) '!$C14) -> 0 | AY14: =SUMIFS('1.DC_Ra soat'!$L:$L,'1.DC_Ra soat'!$F:$F,'1.PL (VND) '!AY$4,'1.DC_Ra soat'!$H:$H,'1.PL (VND) '!$C14)-SUMIFS('1.DC_Ra soat'!$L:$L,'1.DC_Ra soat'!$F:$F,'1.PL (VND) '!AY$4,'1.DC_Ra soat'!$I:$I,'1.PL (VND) '!$C14) -> 1262355349 | AZ14: =SUMIFS('1.DC_Ra soat'!$L:$L,'1.DC_Ra soat'!$F:$F,'1.PL (VND) '!AZ$4,'1.DC_Ra soat'!$H:$H,'1.PL (VND) '!$C14)-SUMIFS('1.DC_Ra soat'!$L:$L,'1.DC_Ra soat'!$F:$F,'1.PL (VND) '!AZ$4,'1.DC_Ra soat'!$I:$I,'1.PL (VND) '!$C14) -> 0 | BB14: =SUMIFS('1.DC_Ra soat'!$L:$L,'1.DC_Ra soat'!$F:$F,'1.PL (VND) '!BB$4,'1.DC_Ra soat'!$H:$H,'1.PL (VND) '!$C14)-SUMIFS('1.DC_Ra soat'!$L:$L,'1.DC_Ra soat'!$F:$F,'1.PL (VND) '!BB$4,'1.DC_Ra soat'!$I:$I,'1.PL (VND) '!$C14) -> 0 | BC14: =SUMIFS('1.DC_Ra soat'!$L:$L,'1.DC_Ra soat'!$F:$F,'1.PL (VND) '!BC$4,'1.DC_Ra soat'!$H:$H,'1.PL (VND) '!$C14)-SUMIFS('1.DC_Ra soat'!$L:$L,'1.DC_Ra soat'!$F:$F,'1.PL (VND) '!BC$4,'1.DC_Ra soat'!$I:$I,'1.PL (VND) '!$C14) -> 0 | BD14: =SUMIFS('1.DC_Ra soat'!$L:$L,'1.DC_Ra soat'!$F:$F,'1.PL (VND) '!BD$4,'1.DC_Ra soat'!$H:$H,'1.PL (VND) '!$C14)-SUMIFS('1.DC_Ra soat'!$L:$L,'1.DC_Ra soat'!$F:$F,'1.PL (VND) '!BD$4,'1.DC_Ra soat'!$I:$I,'1.PL (VND) '!$C14) -> 0 | BE14: =SUMIFS('1.DC_Ra soat'!$L:$L,'1.DC_Ra soat'!$F:$F,'1.PL (VND) '!BE$4,'1.DC_Ra soat'!$H:$H,'1.PL (VND) '!$C14)-SUMIFS('1.DC_Ra soat'!$L:$L,'1.DC_Ra soat'!$F:$F,'1.PL (VND) '!BE$4,'1.DC_Ra soat'!$I:$I,'1.PL (VND) '!$C14) -> 0 | BG14: =SUMIFS('1.DC_Ra soat'!$L:$L,'1.DC_Ra soat'!$F:$F,'1.PL (VND) '!BG$4,'1.DC_Ra soat'!$H:$H,'1.PL (VND) '!$C14)-SUMIFS('1.DC_Ra soat'!$L:$L,'1.DC_Ra soat'!$F:$F,'1.PL (VND) '!BG$4,'1.DC_Ra soat'!$I:$I,'1.PL (VND) '!$C14) -> 0 | BH14: =SUMIFS('1.DC_Ra soat'!$L:$L,'1.DC_Ra soat'!$F:$F,'1.PL (VND) '!BH$4,'1.DC_Ra soat'!$H:$H,'1.PL (VND) '!$C14)-SUMIFS('1.DC_Ra soat'!$L:$L,'1.DC_Ra soat'!$F:$F,'1.PL (VND) '!BH$4,'1.DC_Ra soat'!$I:$I,'1.PL (VND) '!$C14) -> 0 | BI14: =SUMIFS('1.DC_Ra soat'!$L:$L,'1.DC_Ra soat'!$F:$F,'1.PL (VND) '!BI$4,'1.DC_Ra soat'!$H:$H,'1.PL (VND) '!$C14)-SUMIFS('1.DC_Ra soat'!$L:$L,'1.DC_Ra soat'!$F:$F,'1.PL (VND) '!BI$4,'1.DC_Ra soat'!$I:$I,'1.PL (VND) '!$C14) -> 0 | BJ14: =SUMIFS('1.DC_Ra soat'!$L:$L,'1.DC_Ra soat'!$F:$F,'1.PL (VND) '!BJ$4,'1.DC_Ra soat'!$H:$H,'1.PL (VND) '!$C14)-SUMIFS('1.DC_Ra soat'!$L:$L,'1.DC_Ra soat'!$F:$F,'1.PL (VND) '!BJ$4,'1.DC_Ra soat'!$I:$I,'1.PL (VND) '!$C14) -> 0 | BL14: =D14+AH14 -> 8171598143 | BM14: =E14+AI14 -> 4496061333 | BN14: =F14+AJ14 -> 13833321122 | BO14: =G14+AK14 -> 12548808701 | BQ14: =I14+AM14 -> 0 | BR14: =J14+AN14 -> 725227638 | BS14: =K14+AO14 -> 3328009721 | BT14: =L14+AP14 -> 1890560444 | BV14: =N14+AR14 -> 1336298435 | BW14: =O14+AS14 -> 1675370773 | BX14: =P14+AT14 -> 2178070579 | BY14: =Q14+AU14 -> 2214890036 | CA14: =S14+AW14 -> 296662990 | CB14: =T14+AX14 -> 832438007 | CC14: =U14+AY14 -> 2355114495 | CD14: =V14+AZ14 -> 1540066497 | CF14: =X14+BB14 -> 0 | CG14: =Y14+BC14 -> 0 | CH14: =Z14+BD14 -> 0 | CI14: =AA14+BE14 -> 0 | CK14: =AC14+BG14 -> 0 | CL14: =AD14+BH14 -> 0 | CM14: =AE14+BI14 -> 0 | CN14: =AF14+BJ14 -> 0 | CP14: =SUMIF($BL$6:$CD$6,CP$6,$BL14:$CD14) -> 9804559568 | CQ14: =SUMIF($BL$6:$CD$6,CQ$6,$BL14:$CD14) -> 7729097751 | CR14: =SUMIF($BL$6:$CD$6,CR$6,$BL14:$CD14) -> 21694515917 | CS14: =SUMIF($BL$6:$CD$6,CS$6,$BL14:$CD14) -> 18194325678 | CU14: =-SUMIFS('1.DC_Ra soat'!$L:$L,'1.DC_Ra soat'!$F:$F,'1.PL (VND) '!CU$4,'1.DC_Ra soat'!$H:$H,'1.PL (VND) '!$C14)+SUMIFS('1.DC_Ra soat'!$L:$L,'1.DC_Ra soat'!$F:$F,'1.PL (VND) '!CU$4,'1.DC_Ra soat'!$I:$I,'1.PL (VND) '!$C14) -> 0 | CV14: =-SUMIFS('1.DC_Ra soat'!$L:$L,'1.DC_Ra soat'!$F:$F,'1.PL (VND) '!CV$4,'1.DC_Ra soat'!$H:$H,'1.PL (VND) '!$C14)+SUMIFS('1.DC_Ra soat'!$L:$L,'1.DC_Ra soat'!$F:$F,'1.PL (VND) '!CV$4,'1.DC_Ra soat'!$I:$I,'1.PL (VND) '!$C14) -> 0 | CW14: =-SUMIFS('1.DC_Ra soat'!$L:$L,'1.DC_Ra soat'!$F:$F,'1.PL (VND) '!CW$4,'1.DC_Ra soat'!$H:$H,'1.PL (VND) '!$C14)+SUMIFS('1.DC_Ra soat'!$L:$L,'1.DC_Ra soat'!$F:$F,'1.PL (VND) '!CW$4,'1.DC_Ra soat'!$I:$I,'1.PL (VND) '!$C14) -> 0 | CX14: =-SUMIFS('1.DC_Ra soat'!$L:$L,'1.DC_Ra soat'!$F:$F,'1.PL (VND) '!CX$4,'1.DC_Ra soat'!$H:$H,'1.PL (VND) '!$C14)+SUMIFS('1.DC_Ra soat'!$L:$L,'1.DC_Ra soat'!$F:$F,'1.PL (VND) '!CX$4,'1.DC_Ra soat'!$I:$I,'1.PL (VND) '!$C14) -> 0 | CZ14: =CP14+CU14 -> 9804559568 | DA14: =CQ14+CV14 -> 7729097751 | DB14: =CR14+CW14 -> 21694515917 | DC14: =CS14+CX14 -> 18194325678
B15: Trong đó: chi phí lãi vay | C15: 23 | D15: =D14 -> 8171598143 | E15: =E14 -> 4496061333 | F15: =F14 -> 8332900199 | G15: =G14 -> 12548808701 | I15: =I14 -> 0 | J15: =J14 -> 725227638 | K15: =K14 -> 2586469172 | L15: =L14 -> 1890560444 | N15: =N14 -> 1336298435 | O15: =O14 -> 1675370773 | P15: =P14 -> 2178070579 | Q15: =Q14 -> 2214890036 | S15: =S14 -> 296662990 | T15: =T14 -> 832438007 | U15: =U14 -> 1092759146 | V15: =V14 -> 1540066497 | AC15: =AC14 -> 0 | AD15: =AD14 -> 0 | AE15: =AE14 -> 0 | AF15: 0 | AH15: =SUMIFS('1.DC_Ra soat'!$L:$L,'1.DC_Ra soat'!$F:$F,'1.PL (VND) '!AH$4,'1.DC_Ra soat'!$H:$H,'1.PL (VND) '!$C15)-SUMIFS('1.DC_Ra soat'!$L:$L,'1.DC_Ra soat'!$F:$F,'1.PL (VND) '!AH$4,'1.DC_Ra soat'!$I:$I,'1.PL (VND) '!$C15) -> 0 | AI15: =SUMIFS('1.DC_Ra soat'!$L:$L,'1.DC_Ra soat'!$F:$F,'1.PL (VND) '!AI$4,'1.DC_Ra soat'!$H:$H,'1.PL (VND) '!$C15)-SUMIFS('1.DC_Ra soat'!$L:$L,'1.DC_Ra soat'!$F:$F,'1.PL (VND) '!AI$4,'1.DC_Ra soat'!$I:$I,'1.PL (VND) '!$C15) -> 0 | AJ15: =SUMIFS('1.DC_Ra soat'!$L:$L,'1.DC_Ra soat'!$F:$F,'1.PL (VND) '!AJ$4,'1.DC_Ra soat'!$H:$H,'1.PL (VND) '!$C15)-SUMIFS('1.DC_Ra soat'!$L:$L,'1.DC_Ra soat'!$F:$F,'1.PL (VND) '!AJ$4,'1.DC_Ra soat'!$I:$I,'1.PL (VND) '!$C15) -> 0 | AK15: =SUMIFS('1.DC_Ra soat'!$L:$L,'1.DC_Ra soat'!$F:$F,'1.PL (VND) '!AK$4,'1.DC_Ra soat'!$H:$H,'1.PL (VND) '!$C15)-SUMIFS('1.DC_Ra soat'!$L:$L,'1.DC_Ra soat'!$F:$F,'1.PL (VND) '!AK$4,'1.DC_Ra soat'!$I:$I,'1.PL (VND) '!$C15) -> 0 | AM15: =SUMIFS('1.DC_Ra soat'!$L:$L,'1.DC_Ra soat'!$F:$F,'1.PL (VND) '!AM$4,'1.DC_Ra soat'!$H:$H,'1.PL (VND) '!$C15)-SUMIFS('1.DC_Ra soat'!$L:$L,'1.DC_Ra soat'!$F:$F,'1.PL (VND) '!AM$4,'1.DC_Ra soat'!$I:$I,'1.PL (VND) '!$C15) -> 0 | AN15: =SUMIFS('1.DC_Ra soat'!$L:$L,'1.DC_Ra soat'!$F:$F,'1.PL (VND) '!AN$4,'1.DC_Ra soat'!$H:$H,'1.PL (VND) '!$C15)-SUMIFS('1.DC_Ra soat'!$L:$L,'1.DC_Ra soat'!$F:$F,'1.PL (VND) '!AN$4,'1.DC_Ra soat'!$I:$I,'1.PL (VND) '!$C15) -> 0 | AO15: =SUMIFS('1.DC_Ra soat'!$L:$L,'1.DC_Ra soat'!$F:$F,'1.PL (VND) '!AO$4,'1.DC_Ra soat'!$H:$H,'1.PL (VND) '!$C15)-SUMIFS('1.DC_Ra soat'!$L:$L,'1.DC_Ra soat'!$F:$F,'1.PL (VND) '!AO$4,'1.DC_Ra soat'!$I:$I,'1.PL (VND) '!$C15) -> 0 | AP15: =SUMIFS('1.DC_Ra soat'!$L:$L,'1.DC_Ra soat'!$F:$F,'1.PL (VND) '!AP$4,'1.DC_Ra soat'!$H:$H,'1.PL (VND) '!$C15)-SUMIFS('1.DC_Ra soat'!$L:$L,'1.DC_Ra soat'!$F:$F,'1.PL (VND) '!AP$4,'1.DC_Ra soat'!$I:$I,'1.PL (VND) '!$C15) -> 0 | AR15: =SUMIFS('1.DC_Ra soat'!$L:$L,'1.DC_Ra soat'!$F:$F,'1.PL (VND) '!AR$4,'1.DC_Ra soat'!$H:$H,'1.PL (VND) '!$C15)-SUMIFS('1.DC_Ra soat'!$L:$L,'1.DC_Ra soat'!$F:$F,'1.PL (VND) '!AR$4,'1.DC_Ra soat'!$I:$I,'1.PL (VND) '!$C15) -> 0 | AS15: =SUMIFS('1.DC_Ra soat'!$L:$L,'1.DC_Ra soat'!$F:$F,'1.PL (VND) '!AS$4,'1.DC_Ra soat'!$H:$H,'1.PL (VND) '!$C15)-SUMIFS('1.DC_Ra soat'!$L:$L,'1.DC_Ra soat'!$F:$F,'1.PL (VND) '!AS$4,'1.DC_Ra soat'!$I:$I,'1.PL (VND) '!$C15) -> 0 | AT15: =AT14 -> 0 | AU15: =SUMIFS('1.DC_Ra soat'!$L:$L,'1.DC_Ra soat'!$F:$F,'1.PL (VND) '!AU$4,'1.DC_Ra soat'!$H:$H,'1.PL (VND) '!$C15)-SUMIFS('1.DC_Ra soat'!$L:$L,'1.DC_Ra soat'!$F:$F,'1.PL (VND) '!AU$4,'1.DC_Ra soat'!$I:$I,'1.PL (VND) '!$C15) -> 0 | AW15: =SUMIFS('1.DC_Ra soat'!$L:$L,'1.DC_Ra soat'!$F:$F,'1.PL (VND) '!AW$4,'1.DC_Ra soat'!$H:$H,'1.PL (VND) '!$C15)-SUMIFS('1.DC_Ra soat'!$L:$L,'1.DC_Ra soat'!$F:$F,'1.PL (VND) '!AW$4,'1.DC_Ra soat'!$I:$I,'1.PL (VND) '!$C15) -> 0 | AX15: =SUMIFS('1.DC_Ra soat'!$L:$L,'1.DC_Ra soat'!$F:$F,'1.PL (VND) '!AX$4,'1.DC_Ra soat'!$H:$H,'1.PL (VND) '!$C15)-SUMIFS('1.DC_Ra soat'!$L:$L,'1.DC_Ra soat'!$F:$F,'1.PL (VND) '!AX$4,'1.DC_Ra soat'!$I:$I,'1.PL (VND) '!$C15) -> 0 | AY15: =SUMIFS('1.DC_Ra soat'!$L:$L,'1.DC_Ra soat'!$F:$F,'1.PL (VND) '!AY$4,'1.DC_Ra soat'!$H:$H,'1.PL (VND) '!$C15)-SUMIFS('1.DC_Ra soat'!$L:$L,'1.DC_Ra soat'!$F:$F,'1.PL (VND) '!AY$4,'1.DC_Ra soat'!$I:$I,'1.PL (VND) '!$C15) -> 0 | AZ15: =SUMIFS('1.DC_Ra soat'!$L:$L,'1.DC_Ra soat'!$F:$F,'1.PL (VND) '!AZ$4,'1.DC_Ra soat'!$H:$H,'1.PL (VND) '!$C15)-SUMIFS('1.DC_Ra soat'!$L:$L,'1.DC_Ra soat'!$F:$F,'1.PL (VND) '!AZ$4,'1.DC_Ra soat'!$I:$I,'1.PL (VND) '!$C15) -> 0 | BB15: =SUMIFS('1.DC_Ra soat'!$L:$L,'1.DC_Ra soat'!$F:$F,'1.PL (VND) '!BB$4,'1.DC_Ra soat'!$H:$H,'1.PL (VND) '!$C15)-SUMIFS('1.DC_Ra soat'!$L:$L,'1.DC_Ra soat'!$F:$F,'1.PL (VND) '!BB$4,'1.DC_Ra soat'!$I:$I,'1.PL (VND) '!$C15) -> 0 | BC15: =SUMIFS('1.DC_Ra soat'!$L:$L,'1.DC_Ra soat'!$F:$F,'1.PL (VND) '!BC$4,'1.DC_Ra soat'!$H:$H,'1.PL (VND) '!$C15)-SUMIFS('1.DC_Ra soat'!$L:$L,'1.DC_Ra soat'!$F:$F,'1.PL (VND) '!BC$4,'1.DC_Ra soat'!$I:$I,'1.PL (VND) '!$C15) -> 0 | BD15: =SUMIFS('1.DC_Ra soat'!$L:$L,'1.DC_Ra soat'!$F:$F,'1.PL (VND) '!BD$4,'1.DC_Ra soat'!$H:$H,'1.PL (VND) '!$C15)-SUMIFS('1.DC_Ra soat'!$L:$L,'1.DC_Ra soat'!$F:$F,'1.PL (VND) '!BD$4,'1.DC_Ra soat'!$I:$I,'1.PL (VND) '!$C15) -> 0 | BE15: =SUMIFS('1.DC_Ra soat'!$L:$L,'1.DC_Ra soat'!$F:$F,'1.PL (VND) '!BE$4,'1.DC_Ra soat'!$H:$H,'1.PL (VND) '!$C15)-SUMIFS('1.DC_Ra soat'!$L:$L,'1.DC_Ra soat'!$F:$F,'1.PL (VND) '!BE$4,'1.DC_Ra soat'!$I:$I,'1.PL (VND) '!$C15) -> 0 | BG15: =SUMIFS('1.DC_Ra soat'!$L:$L,'1.DC_Ra soat'!$F:$F,'1.PL (VND) '!BG$4,'1.DC_Ra soat'!$H:$H,'1.PL (VND) '!$C15)-SUMIFS('1.DC_Ra soat'!$L:$L,'1.DC_Ra soat'!$F:$F,'1.PL (VND) '!BG$4,'1.DC_Ra soat'!$I:$I,'1.PL (VND) '!$C15) -> 0 | BH15: =SUMIFS('1.DC_Ra soat'!$L:$L,'1.DC_Ra soat'!$F:$F,'1.PL (VND) '!BH$4,'1.DC_Ra soat'!$H:$H,'1.PL (VND) '!$C15)-SUMIFS('1.DC_Ra soat'!$L:$L,'1.DC_Ra soat'!$F:$F,'1.PL (VND) '!BH$4,'1.DC_Ra soat'!$I:$I,'1.PL (VND) '!$C15) -> 0 | BI15: =SUMIFS('1.DC_Ra soat'!$L:$L,'1.DC_Ra soat'!$F:$F,'1.PL (VND) '!BI$4,'1.DC_Ra soat'!$H:$H,'1.PL (VND) '!$C15)-SUMIFS('1.DC_Ra soat'!$L:$L,'1.DC_Ra soat'!$F:$F,'1.PL (VND) '!BI$4,'1.DC_Ra soat'!$I:$I,'1.PL (VND) '!$C15) -> 0 | BJ15: =SUMIFS('1.DC_Ra soat'!$L:$L,'1.DC_Ra soat'!$F:$F,'1.PL (VND) '!BJ$4,'1.DC_Ra soat'!$H:$H,'1.PL (VND) '!$C15)-SUMIFS('1.DC_Ra soat'!$L:$L,'1.DC_Ra soat'!$F:$F,'1.PL (VND) '!BJ$4,'1.DC_Ra soat'!$I:$I,'1.PL (VND) '!$C15) -> 0 | BL15: =D15+AH15 -> 8171598143 | BM15: =E15+AI15 -> 4496061333 | BN15: =F15+AJ15 -> 8332900199 | BO15: =G15+AK15 -> 12548808701 | BQ15: =I15+AM15 -> 0 | BR15: =J15+AN15 -> 725227638 | BS15: =K15+AO15 -> 2586469172 | BT15: =L15+AP15 -> 1890560444 | BV15: =N15+AR15 -> 1336298435 | BW15: =O15+AS15 -> 1675370773 | BX15: =P15+AT15 -> 2178070579 | BY15: =Q15+AU15 -> 2214890036 | CA15: =S15+AW15 -> 296662990 | CB15: =T15+AX15 -> 832438007 | CC15: =U15+AY15 -> 1092759146 | CD15: =V15+AZ15 -> 1540066497 | CF15: =X15+BB15 -> 0 | CG15: =Y15+BC15 -> 0 | CH15: =Z15+BD15 -> 0 | CI15: =AA15+BE15 -> 0 | CK15: =AC15+BG15 -> 0 | CL15: =AD15+BH15 -> 0 | CM15: =AE15+BI15 -> 0 | CN15: =AF15+BJ15 -> 0 | CP15: =SUMIF($BL$6:$CD$6,CP$6,$BL15:$CD15) -> 9804559568 | CQ15: =SUMIF($BL$6:$CD$6,CQ$6,$BL15:$CD15) -> 7729097751 | CR15: =SUMIF($BL$6:$CD$6,CR$6,$BL15:$CD15) -> 14190199096 | CS15: =SUMIF($BL$6:$CD$6,CS$6,$BL15:$CD15) -> 18194325678 | CU15: =CU14 -> 0 | CV15: =CV14 -> 0 | CW15: =CW14 -> 0 | CX15: =CX14 -> 0 | CZ15: =CP15+CU15 -> 9804559568 | DA15: =CQ15+CV15 -> 7729097751 | DB15: =CR15+CW15 -> 14190199096 | DC15: =CS15+CX15 -> 18194325678
