Workbook

Sheet Cover
B9: JOB
B11: SOFTWARE BUSINESS ANALYST
F15: Code | I15: 13e-CV/HR/HDCV/CM
F16: Version | I16: 1.0
F17: Effect Date | I17: MAR.31.2023

Sheet Table of Content
A1: TABLE OF CONTENT
A3: 1 | B3: Guidelines | G3: Click here
A4: 2 | B4: Models | G4: Click here
A5: 3 | B5: Career Paths | G5: Click here
A6: 4 | B6: Job Descriptions | G6: Click here
A7: 5 | B7: Job Rankings | G7: Click here
A8: 6 | B8: Assessment Summary | G8: Click here
A9: 7 | B9: Roles & Responsibilities | G9: Click here
A10: 8 | B10: Definitions | G10: Click here
A11: 9 | B11: Records of Change | G11: Click here

Sheet 01. Guidelines
A1: Guidelines
B2: Business Analyst Capabilities Assessment & Development
B3: 1. Purpose
B4: - This document use to assess current Software Business Analyst (BA) capabilities base on Job Description of FSOFT and specific requirement of BU.
B5: - This template will help BA find out the SKILL GAP to fulfill the required/desired ranking then define action to improve to achieve specific ranking.
B6: 2. Users:
B7: BA can use this template whenever they need to determine their competency or new onboarding BA in FSOFT.
B8: BUL/Project manager can use this template to verify BA ranking at CHE or Ad-hoc event.
B9: 3. Assessment criteria
C10: Career Path Development => Refer to sheet 03. Career Paths
C11: Competency Framework => Refer to sheet 04. Job Descriptions
C12: Job Assessment => Refer to sheet 05. Job Rankings
C13: Definitions and Parameters => Refer to sheet 08. Definitions
B14: 4. Steps to do the Assessment
C15: STEP 1: | D15: Go to sheet [05. Job Rankings],
D16: Enter your account + name in cell B3
D17: Input any description in cell C3
D18: Choose your current or ranking that you need to achieve in cell H3
C19: STEP 2: | D19: Continue with sheet [05. Job Rankings],
D20: Choose the correct value of each criteria at the Listbox in cells E7:E35
D21: Provide evidence or description in cells F7:F35 for corresponding criteria if any
C22: STEP 3: | D22: Filter "Yes" value in column J-[Need to improve?] and fill in the improvement to column K -[Action to improve] and appropriate deadline in column L.
D23: * Refer the required skill for each item in column H-[Ranking Requirement] to define what action need to be taken.
C24: STEP 4: | D24: Go to sheet [06. Assessment Summary] to view the Overall capabilities & actions needed to achieve your expected Ranking.
C25: STEP 5: | D25: Add the Action to improve to your Personal Development Plan and follow up for closure before the next Ranking Review.

Sheet 02. Models
A1: Models
B2: Software Business Analyst Role | D2: BUILD-UP | E2: BUY-IN
B3: Assessment Items | C3: Code | D3: Weight % | E3: Weight %
D4: =D5+D8+D25+D15+D30 -> 1 | E4: =E5+E8+E25+E15+E30 -> 1
B5: Roles & Responsibilities | D5: =SUM(D6:D7) -> 0.15 | E5: =SUM(E6:E7) -> 0
B6: Roles and Responsibilities | C6: SBA01 | D6: 0.12 | E6: 0
B7: Team Size To Lead for BA Leader | C7: SBA02 | D7: 0.03 | E7: 0
B8: Experiences & Contributions | D8: =SUM(D9:D14) -> 0.25 | E8: =SUM(E9:E14) -> 0.3
B9: Business Analysis Experiences (*) | C9: SBA03 | D9: 0.05 | E9: 0.15
B10: Subordinate Development | C10: SBA04 | D10: 0.03 | E10: 0
B11: Number of Projects/Phases | C11: SBA05 | D11: 0.03 | E11: 0.05
B12: Community Contributions | C12: SBA06 | D12: 0.02 | E12: 0
B13: Industry Experiences (IT and Non-IT fields) | C13: SBA07 | D13: 0.1 | E13: 0.1
B14: Consulting for Sales/Biding Teams | C14: SBA08 | D14: 0.02 | E14: 0
B15: Professional Business Analysis Skills | D15: =SUM(D16:D24) -> 0.4 | E15: =SUM(E16:E24) -> 0.5
B16: Business Analysis Planning & Monitoring (*) | C16: SBA09 | D16: 0.08 | E16: 0.08
B17: Requirement Elicitation & Collaboration (*) | C17: SBA10 | D17: 0.07 | E17: 0.07
B18: Business Requirement Analysis (*) | C18: SBA11 | D18: 0.1 | E18: 0.2
B19: Business Solution Evaluation | C19: SBA12 | D19: 0.05 | E19: 0.05
B20: Business Requirement Life-Cycle | C20: SBA13 | D20: 0.02 | E20: 0.02
B21: Business Strategy Design | C21: SBA14 | D21: 0.02 | E21: 0.02
B22: Business Acumen and Mindsets | C22: SBA15 | D22: 0.03 | E22: 0.03
B23: Software Design and Technology Stack | C23: SBA16 | D23: 0.01 | E23: 0.01
B24: Business Analysis Tools | C24: SBA17 | D24: 0.02 | E24: 0.02
B25: Foreign Language & Certificates | D25: =SUM(D26:D29) -> 0.1 | E25: =SUM(E26:E29) -> 0.1
B26: Foreign Language | C26: SBA18 | D26: 0.05 | E26: 0.05
B27: Education Background | C27: SBA19 | D27: 0.02 | E27: 0.02
B28: Business Analysis Certifications | C28: SBA20 | D28: 0.02 | E28: 0.02
B29: Individual Learning in Year | C29: SBA21 | D29: 0.01 | E29: 0.01
B30: Non-Engineering and Softskills | D30: =SUM(D31:D35) -> 0.1 | E30: =SUM(E31:E35) -> 0.1
B31: Communication and Problem Solving | C31: SBA22 | D31: 0.03 | E31: 0.03
B32: Organization and Industry Knowledge | C32: SBA23 | D32: 0.02 | E32: 0.02
B33: Analytical and Critical Thinking | C33: SBA24 | D33: 0.02 | E33: 0.02
B34: Project Risk Management | C34: SBA25 | D34: 0.02 | E34: 0.02
B35: Project Human Resource Management | C35: SBA26 | D35: 0.01 | E35: 0.01

Sheet 03. Career Paths
A1: Career Paths | V1: CURRENT VERSION:
V15: NEW VERSION:
V16: The Competency-Based JD Components and Weight | X16: =SUM(X17:X21) -> 1
V17: I | W17: ='02. Models'!B5 -> Roles & Responsibilities | X17: ='02. Models'!D5 -> 0.15
V18: II | W18: ='02. Models'!B8 -> Experiences & Contributions | X18: ='02. Models'!D8 -> 0.25
V19: III | W19: ='02. Models'!B15 -> Professional Business Analysis Skills | X19: ='02. Models'!D15 -> 0.4
V20: IV | W20: ='02. Models'!B25 -> Foreign Language & Certificates | X20: ='02. Models'!D25 -> 0.1
V21: V | W21: ='02. Models'!B30 -> Non-Engineering and Softskills | X21: ='02. Models'!D30 -> 0.1
V24: JOB INTERVIEW:
V25: The Competency-Based JD Components and Weight | X25: =SUM(X26:X29) -> 1
V26: I | W26: ='02. Models'!B13 -> Industry Experiences (IT and Non-IT fields) | X26: ='02. Models'!E8 -> 0.3
V27: II | W27: ='02. Models'!B17 -> Requirement Elicitation & Collaboration (*) | X27: ='02. Models'!E15 -> 0.5
V28: III | W28: ='02. Models'!B24 -> Business Analysis Tools | X28: ='02. Models'!E25 -> 0.1
V29: IV | W29: ='02. Models'!B34 -> Project Risk Management | X29: ='02. Models'!E30 -> 0.1

Sheet 04. Job Descriptions
A1: Job Descriptions | D1: Software Business Analyst Role - Job Description | M1: RANKING INDEX
B2: (*) Mandatory assessment items. If there is any unqualified item, you will not qualified this rank. | M2: =E3 -> Associate Business Analyst | N2: =F3 -> Business Analyst | O2: =G3 -> Senior Business Analyst | P2: =H3 -> Business Analysis Leader | Q2: =I3 -> Senior Business Analysis Consultant / Leader | R2: =J3 -> Principal Business Analysis Consultant / Leader
B3: Assessment Items | C3: Weight % | D3: Explanation of Assessment Items | E3: ='08. Definitions'!$D14 -> Associate Business Analyst | F3: ='08. Definitions'!$D15 -> Business Analyst | G3: ='08. Definitions'!$D16 -> Senior Business Analyst | H3: ='08. Definitions'!$D17 -> Business Analysis Leader | I3: ='08. Definitions'!$D19 -> Senior Business Analysis Consultant / Leader | J3: ='08. Definitions'!$D20 -> Principal Business Analysis Consultant / Leader | M3: =E4 -> BANE01 | N3: =F4 -> BANE02 | O3: =G4 -> BANE03 | P3: =H4 -> BANE04 | Q3: =I4 -> BANE05 | R3: =J4 -> BANE06
C4: =C5+C8+C25+C15+C30 -> 1 | E4: ='08. Definitions'!C14 -> BANE01 | F4: ='08. Definitions'!C15 -> BANE02 | G4: ='08. Definitions'!C16 -> BANE03 | H4: ='08. Definitions'!C17 -> BANE04 | I4: ='08. Definitions'!C19 -> BANE05 | J4: ='08. Definitions'!C20 -> BANE06 | M4: =M5+M8+M15+M25+M30 -> 25.733333 | N4: =N5+N8+N15+N25+N30 -> 34.233333 | O4: =O5+O8+O15+O25+O30 -> 49.916667 | P4: =P5+P8+P15+P25+P30 -> 67.816667 | Q4: =Q5+Q8+Q15+Q25+Q30 -> 81 | R4: =R5+R8+R15+R25+R30 -> 100
B5: ='02. Models'!B5 -> Roles & Responsibilities | C5: =SUM(C6:C7) -> 0.15 | D5: FSOFTER is required to have the role and responsibility to perform one or more of the following tasks | E5: Level 1 | F5: Level 2 | G5: Level 3 | H5: Level 4 | I5: Level 5 | J5: Level 6 | M5: =SUM(M6:M7) -> 2.4 | N5: =SUM(N6:N7) -> 4.8 | O5: =SUM(O6:O7) -> 7.2 | P5: =SUM(P6:P7) -> 10.35 | Q5: =SUM(Q6:Q7) -> 11.85 | R5: =SUM(R6:R7) -> 15
B6: ='02. Models'!B6 -> Roles and Responsibilities | C6: ='02. Models'!D6 -> 0.12 | D6: Implementing all the processes and activities related to business analysis which can be analyzing and designing functional and non-functional requirements to the development, client or production environment, including but not limited to following responsibilities: BANE01: - Has responsibility for documenting requirement, supporting communicate requirement to stakeholders (under guidance) as role BA member. - Project Diversity and Complexity - Low: >=5 items in Elementary Complexity Criteria BANE02: - Has responsibility for gathering requirement, elaborating and validating gathered requirement as role BA member. - Project Diversity and Complexity - Normal: All items of Elementary Complexity Criteria & >= 1 item in General Advanced Complexity Criteria BANE03: - Has responsibility for designing, analyzing and evaluating business solution to ensure that it aligns with the project's goal as role BA member. - Project Diversity and Complexity - Medium: >= 4 items of General Advanced Complexity Criteria & >= 2 items of Management Complexity Criteria OR >= 4 items of General Advanced Complexity Criteria & >=1 item in Consultant Complexity Criteria BANE04: - Has responsibility for defining requirement approach & process, planning and monitoring business analysis activities as role BA consultant. - Project Diversity and Complexity - Complex: >= 4 items in General Advanced Complexity Criteria & All items in Management Complexity Criteria OR >= 5 items in General Advanced Complexity Criteria & >= 2 item of Consultant Complexity Criteria BANE05: - Has responsibility for performing system evaluation & enterprise solution consultation as role BA consultant. - Project Diversity and Complexity - Complex: >= 4 items in General Advanced Complexity Criteria & All items in Management Complexity Criteria OR >= 5 items in General Advanced Complexity Criteria & >= 2 item of Consultant Complexity Criteria BANE06: - Has responsibility for performing system evaluation & enterprise solution consultation as role BA consultant. - Project Diversity and Complexity - Very Complex: >= 4 items of Advanced Complexity Criteria & All items of Management Complexity Criteria OR All items in General Advanced & All Consultant Complexity Criteria | E6: 1: Follow (BANE01) | F6: 2: Assist (BANE02) | G6: 3: Apply (BANE03) | H6: 4: Create (BANE04) | I6: 4: Create (BANE04) | J6: 5: Design (BANE05/BANE06) | K6: =MAX(LEFT(E6,1),LEFT(F6,1), LEFT(G6,1), LEFT(H6,1), LEFT(I6,1), LEFT(J6,1)) -> 5 | M6: =(LEFT(E6,1)*$C6/$K$6)*100 -> 2.4 | N6: =(LEFT(F6,1)*$C6/$K$6)*100 -> 4.8 | O6: =(LEFT(G6,1)*$C6/$K$6)*100 -> 7.2 | P6: =(LEFT(H6,1)*$C6/$K$6)*100 -> 9.6 | Q6: =(LEFT(I6,1)*$C6/$K$6)*100 -> 9.6 | R6: =(LEFT(J6,1)*$C6/$K$6)*100 -> 12
B7: ='02. Models'!B7 -> Team Size To Lead for BA Leader | C7: ='02. Models'!D7 -> 0.03 | D7: 4: Global Level - Have at least 70% BA2, 10% BA3, 3% BA4, 0.75%BA5 3: FSOFT Level - Have at least 50% BA2, 10% BA3, 3% BA4, 0.75%BA5 2: FSU Level - Have at least 50% BA2, 12% BA3, 3% BA4 1: BU Level - Have at least 50% BA2, 12% BA3 0: Not Required | E7: 0: Not Requried | F7: 0: Not Requried | G7: 0: Not Requried | H7: 1: BU Level | I7: 3: FSOFT Level | J7: 4: Global Level | K7: =MAX(LEFT(E7,1),LEFT(F7,1), LEFT(G7,1), LEFT(H7,1), LEFT(I7,1), LEFT(J7,1)) -> 4 | M7: =(LEFT(E7,1)*$C7/$K$7)*100 -> 0 | N7: =(LEFT(F7,1)*$C7/$K$7)*100 -> 0 | O7: =(LEFT(G7,1)*$C7/$K$7)*100 -> 0 | P7: =(LEFT(H7,1)*$C7/$K$7)*100 -> 0.75 | Q7: =(LEFT(I7,1)*$C7/$K$7)*100 -> 2.25 | R7: =(LEFT(J7,1)*$C7/$K$7)*100 -> 3
B8: ='02. Models'!B8 -> Experiences & Contributions | C8: =SUM(C9:C14) -> 0.25 | D8: FSOFTER is required to have one or more of the following professional experiences and project contributions | M8: =SUM(M9:M14) -> 0 | N8: =SUM(N9:N14) -> 1.6 | O8: =SUM(O9:O14) -> 7.45 | P8: =SUM(P9:P14) -> 13.3 | Q8: =SUM(Q9:Q14) -> 19.15 | R8: =SUM(R9:R14) -> 25
B9: ='02. Models'!B9 -> Business Analysis Experiences (*) | C9: ='02. Models'!D9 -> 0.05 | D9: Number of years working as Business Analyst, Software Business Analyst, Software Development Life Cycle, Team Work, Agile Mindset | E9: 0: Fundamental awareness | F9: 1: ~1 year experience | G9: 2: 2-3 years experience | H9: 3: 3-5 years experience | I9: 4: 5-7 years experience | J9: 5: 8-10 years experience | K9: =MAX(LEFT(E9,1),LEFT(F9,1), LEFT(G9,1), LEFT(H9,1), LEFT(I9,1), LEFT(J9,1)) -> 5 | M9: =(LEFT(E9,1)*$C9/$K$9)*100 -> 0 | N9: =(LEFT(F9,1)*$C9/$K$9)*100 -> 1 | O9: =(LEFT(G9,1)*$C9/$K$9)*100 -> 2 | P9: =(LEFT(H9,1)*$C9/$K$9)*100 -> 3 | Q9: =(LEFT(I9,1)*$C9/$K$9)*100 -> 4 | R9: =(LEFT(J9,1)*$C9/$K$9)*100 -> 5
B10: ='02. Models'!B10 -> Subordinate Development | C10: ='02. Models'!D10 -> 0.03 | D10: Number of team members or number of people trained/coached | E10: 0: Not Required | F10: 0: Not Required | G10: 1: 1-5 Members or Coaching 1-2 Junior BA | H10: 2: 5-10 Members or Coaching 3-4 Junior BA | I10: 3: 10-20 Members or Coaching 1-2 Senior BA | J10: 4: >20 Members or Coaching 3-4 Senior BA | K10: =MAX(LEFT(E10,1),LEFT(F10,1), LEFT(G10,1), LEFT(H10,1), LEFT(I10,1), LEFT(J10,1)) -> 4 | M10: =(LEFT(E10,1)*$C10/$K$10)*100 -> 0 | N10: =(LEFT(F10,1)*$C10/$K$10)*100 -> 0 | O10: =(LEFT(G10,1)*$C10/$K$10)*100 -> 0.75 | P10: =(LEFT(H10,1)*$C10/$K$10)*100 -> 1.5 | Q10: =(LEFT(I10,1)*$C10/$K$10)*100 -> 2.25 | R10: =(LEFT(J10,1)*$C10/$K$10)*100 -> 3
B11: ='02. Models'!B11 -> Number of Projects/Phases | C11: ='02. Models'!D11 -> 0.03 | D11: The successful projects in business requirements that you have done at least one of the following tasks: analyze, design, develop, support, migrate, deploy, manage software projects or phases (FSOFTER can provide joined project is project rank of Project Rank A, Project Rank B, Project Rank C in Evidence section) | E11: 0: Not Required | F11: 1: ~01-03 Projects / Phases | G11: 2: ~04-05 Projects / Phases | H11: 3: ~06-10 Projects / Phases | I11: 4: ~11-15 Projects / Phases | J11: 5: ~16-20 Projects / Phases | K11: =MAX(LEFT(E11,1),LEFT(F11,1), LEFT(G11,1), LEFT(H11,1), LEFT(I11,1), LEFT(J11,1)) -> 5 | M11: =(LEFT(E11,1)*$C11/$K$11)*100 -> 0 | N11: =(LEFT(F11,1)*$C11/$K$11)*100 -> 0.6 | O11: =(LEFT(G11,1)*$C11/$K$11)*100 -> 1.2 | P11: =(LEFT(H11,1)*$C11/$K$11)*100 -> 1.8 | Q11: =(LEFT(I11,1)*$C11/$K$11)*100 -> 2.4 | R11: =(LEFT(J11,1)*$C11/$K$11)*100 -> 3
B12: ='02. Models'!B12 -> Community Contributions | C12: ='02. Models'!D12 -> 0.02 | D12: Business Analyst Activities to support/training other projects/team, presenter of workshop, contribute IP/solution… | E12: 0: Not Required | F12: 0: Not Required | G12: 1: Training, support other projects | H12: 2: Contribute >= 1 IP/Solution at project level | I12: 3: Contribute >= 1 IP/Solution at BU/FSU level | J12: 4: Contribute >= 1 IP/Solution at FSOFT level | K12: =MAX(LEFT(E12,1),LEFT(F12,1), LEFT(G12,1), LEFT(H12,1), LEFT(I12,1), LEFT(J12,1)) -> 4 | M12: =(LEFT(E12,1)*$C12/$K$12)*100 -> 0 | N12: =(LEFT(F12,1)*$C12/$K$12)*100 -> 0 | O12: =(LEFT(G12,1)*$C12/$K$12)*100 -> 0.5 | P12: =(LEFT(H12,1)*$C12/$K$12)*100 -> 1 | Q12: =(LEFT(I12,1)*$C12/$K$12)*100 -> 1.5 | R12: =(LEFT(J12,1)*$C12/$K$12)*100 -> 2
B13: ='02. Models'!B13 -> Industry Experiences (IT and Non-IT fields) | C13: ='02. Models'!D13 -> 0.1 | D13: Banking, Finance, Insurance, Aviation, Automotive, Oil and Gas, Health Care, ERP, Data Warehouse, Logistic, Real estate, Telecom, … | E13: 0: Fundamental awareness | F13: 0: Fundamental awareness | G13: 1: ~1 year experience | H13: 2: 2-3 years experience | I13: 3: 3-5 years experience | J13: 4: 5-7 years experience | K13: =MAX(LEFT(E13,1),LEFT(F13,1), LEFT(G13,1), LEFT(H13,1), LEFT(I13,1), LEFT(J13,1)) -> 4 | M13: =(LEFT(E13,1)*$C13/$K$13)*100 -> 0 | N13: =(LEFT(F13,1)*$C13/$K$13)*100 -> 0 | O13: =(LEFT(G13,1)*$C13/$K$13)*100 -> 2.5 | P13: =(LEFT(H13,1)*$C13/$K$13)*100 -> 5 | Q13: =(LEFT(I13,1)*$C13/$K$13)*100 -> 7.5 | R13: =(LEFT(J13,1)*$C13/$K$13)*100 -> 10
B14: ='02. Models'!B14 -> Consulting for Sales/Biding Teams | C14: ='02. Models'!D14 -> 0.02 | D14: Business Requirements, Technology Stack, Customer Experience, Vision Development, Processes and Activities, Pricing and Positioning Strategies, Drive Product Launch, … | E14: 0: Not Required | F14: 0: Not Required | G14: 1: ~1 year experience | H14: 2: 2-3 years experience | I14: 3: 3-5 years experience | J14: 4: 5-7 years experience | K14: =MAX(LEFT(E14,1),LEFT(F14,1), LEFT(G14,1), LEFT(H14,1), LEFT(I14,1), LEFT(J14,1)) -> 4 | M14: =(LEFT(E14,1)*$C14/$K$14)*100 -> 0 | N14: =(LEFT(F14,1)*$C14/$K$14)*100 -> 0 | O14: =(LEFT(G14,1)*$C14/$K$14)*100 -> 0.5 | P14: =(LEFT(H14,1)*$C14/$K$14)*100 -> 1 | Q14: =(LEFT(I14,1)*$C14/$K$14)*100 -> 1.5 | R14: =(LEFT(J14,1)*$C14/$K$14)*100 -> 2
B15: ='02. Models'!B15 -> Professional Business Analysis Skills | C15: =SUM(C16:C24) -> 0.4 | D15: FSOFTER is required to have one or more of the following specialized skills to perform assigned tasks | M15: =SUM(M16:M24) -> 16 | N15: =SUM(N16:N24) -> 19 | O15: =SUM(O16:O24) -> 22.6 | P15: =SUM(P16:P24) -> 29 | Q15: =SUM(Q16:Q24) -> 32 | R15: =SUM(R16:R24) -> 40
B16: ='02. Models'!B16 -> Business Analysis Planning & Monitoring (*) | C16: ='02. Models'!D16 -> 0.08 | D16: - Plan Business Analysis Approach - Plan Stakeholders Engagement - Plan Business Analysis Governance - Plan Business Analysis Information Management - Identify Business Analysis Performance Improvement | E16: 2: Limited Experience | F16: 2: Limited Experience | G16: 3: Intermediate | H16: 3: Intermediate | I16: 4: Advanced | J16: 5: Expert | K16: =MAX(LEFT(E16,1),LEFT(F16,1), LEFT(G16,1), LEFT(H16,1), LEFT(I16,1), LEFT(J16,1)) -> 5 | M16: =(LEFT(E16,1)*$C16/$K$16)*100 -> 3.2 | N16: =(LEFT(F16,1)*$C16/$K$16)*100 -> 3.2 | O16: =(LEFT(G16,1)*$C16/$K$16)*100 -> 4.8 | P16: =(LEFT(H16,1)*$C16/$K$16)*100 -> 4.8 | Q16: =(LEFT(I16,1)*$C16/$K$16)*100 -> 6.4 | R16: =(LEFT(J16,1)*$C16/$K$16)*100 -> 8
B17: ='02. Models'!B17 -> Requirement Elicitation & Collaboration (*) | C17: ='02. Models'!D17 -> 0.07 | D17: - Elicitation Preparation - Requirement Workshop / Conduct Elicitation - Requirement Transfer & Confirmation - Requirement Management & Communication - Stakeholders Management | E17: 2: Limited Experience | F17: 2: Limited Experience | G17: 2: Limited Experience | H17: 3: Intermediate | I17: 4: Advanced | J17: 5: Expert | K17: =MAX(LEFT(E17,1),LEFT(F17,1), LEFT(G17,1), LEFT(H17,1), LEFT(I17,1), LEFT(J17,1)) -> 5 | M17: =(LEFT(E17,1)*$C17/$K$17)*100 -> 2.8 | N17: =(LEFT(F17,1)*$C17/$K$17)*100 -> 2.8 | O17: =(LEFT(G17,1)*$C17/$K$17)*100 -> 2.8 | P17: =(LEFT(H17,1)*$C17/$K$17)*100 -> 4.2 | Q17: =(LEFT(I17,1)*$C17/$K$17)*100 -> 5.6 | R17: =(LEFT(J17,1)*$C17/$K$17)*100 -> 7
B18: ='02. Models'!B18 -> Business Requirement Analysis (*) | C18: ='02. Models'!D18 -> 0.1 | D18: - Requirement Specification - Requirement Verification - Requirement Validation - Requirement UI/UX Behavior Design & Principles - Requirement CX (Customer Experience / Customer Journey) - Solution Definition & Assessment | E18: 2: Limited Experience | F18: 3: Intermediate | G18: 3: Intermediate | H18: 4: Advanced | I18: 4: Advanced | J18: 5: Expert | K18: =MAX(LEFT(E18,1),LEFT(F18,1), LEFT(G18,1), LEFT(H18,1), LEFT(I18,1), LEFT(J18,1)) -> 5 | M18: =(LEFT(E18,1)*$C18/$K$18)*100 -> 4 | N18: =(LEFT(F18,1)*$C18/$K$18)*100 -> 6 | O18: =(LEFT(G18,1)*$C18/$K$18)*100 -> 6 | P18: =(LEFT(H18,1)*$C18/$K$18)*100 -> 8 | Q18: =(LEFT(I18,1)*$C18/$K$18)*100 -> 8 | R18: =(LEFT(J18,1)*$C18/$K$18)*100 -> 10
B19: ='02. Models'!B19 -> Business Solution Evaluation | C19: ='02. Models'!D19 -> 0.05 | D19: - Measure Solution Performance - Analyze Performance Measured - Assess Solution Limitations - Assess Enterprise Limitations - Recommend Actions to Increase Solution's Value | E19: 2: Limited Experience | F19: 2: Limited Experience | G19: 3: Intermediate | H19: 4: Advanced | I19: 4: Advanced | J19: 5: Expert | K19: =MAX(LEFT(E19,1),LEFT(F19,1), LEFT(G19,1), LEFT(H19,1), LEFT(I19,1), LEFT(J19,1)) -> 5 | M19: =(LEFT(E19,1)*$C19/$K$19)*100 -> 2 | N19: =(LEFT(F19,1)*$C19/$K$19)*100 -> 2 | O19: =(LEFT(G19,1)*$C19/$K$19)*100 -> 3 | P19: =(LEFT(H19,1)*$C19/$K$19)*100 -> 4 | Q19: =(LEFT(I19,1)*$C19/$K$19)*100 -> 4 | R19: =(LEFT(J19,1)*$C19/$K$19)*100 -> 5
B20: ='02. Models'!B20 -> Business Requirement Life-Cycle | C20: ='02. Models'!D20 -> 0.02 | D20: - Requirement Tracing - Requirement Maintenance - Requirement Prioritization - Requirement Change Management - Requirement Approval | E20: 2: Limited Experience | F20: 2: Limited Experience | G20: 3: Intermediate | H20: 4: Advanced | I20: 4: Advanced | J20: 5: Expert | K20: =MAX(LEFT(E20,1),LEFT(F20,1), LEFT(G20,1), LEFT(H20,1), LEFT(I20,1), LEFT(J20,1)) -> 5 | M20: =(LEFT(E20,1)*$C20/$K$20)*100 -> 0.8 | N20: =(LEFT(F20,1)*$C20/$K$20)*100 -> 0.8 | O20: =(LEFT(G20,1)*$C20/$K$20)*100 -> 1.2 | P20: =(LEFT(H20,1)*$C20/$K$20)*100 -> 1.6 | Q20: =(LEFT(I20,1)*$C20/$K$20)*100 -> 1.6 | R20: =(LEFT(J20,1)*$C20/$K$20)*100 -> 2
B21: ='02. Models'!B21 -> Business Strategy Design | C21: ='02. Models'!D21 -> 0.02 | D21: - Current State Analysis - Future State Analysis - Risk Analysis - Define Change Strategy | E21: 2: Limited Experience | F21: 2: Limited Experience | G21: 3: Intermediate | H21: 4: Advanced | I21: 4: Advanced | J21: 5: Expert | K21: =MAX(LEFT(E21,1),LEFT(F21,1), LEFT(G21,1), LEFT(H21,1), LEFT(I21,1), LEFT(J21,1)) -> 5 | M21: =(LEFT(E21,1)*$C21/$K$21)*100 -> 0.8 | N21: =(LEFT(F21,1)*$C21/$K$21)*100 -> 0.8 | O21: =(LEFT(G21,1)*$C21/$K$21)*100 -> 1.2 | P21: =(LEFT(H21,1)*$C21/$K$21)*100 -> 1.6 | Q21: =(LEFT(I21,1)*$C21/$K$21)*100 -> 1.6 | R21: =(LEFT(J21,1)*$C21/$K$21)*100 -> 2
B22: ='02. Models'!B22 -> Business Acumen and Mindsets | C22: ='02. Models'!D22 -> 0.03 | D22: - Understanding of fundamental business principles and best practices. - Analysis mindsets | E22: 2: Limited Experience | F22: 3: Intermediate | G22: 3: Intermediate | H22: 4: Advanced | I22: 4: Advanced | J22: 5: Expert | K22: =MAX(LEFT(E22,1),LEFT(F22,1), LEFT(G22,1), LEFT(H22,1), LEFT(I22,1), LEFT(J22,1)) -> 5 | M22: =(LEFT(E22,1)*$C22/$K$22)*100 -> 1.2 | N22: =(LEFT(F22,1)*$C22/$K$22)*100 -> 1.8 | O22: =(LEFT(G22,1)*$C22/$K$22)*100 -> 1.8 | P22: =(LEFT(H22,1)*$C22/$K$22)*100 -> 2.4 | Q22: =(LEFT(I22,1)*$C22/$K$22)*100 -> 2.4 | R22: =(LEFT(J22,1)*$C22/$K$22)*100 -> 3
B23: ='02. Models'!B23 -> Software Design and Technology Stack | C23: ='02. Models'!D23 -> 0.01 | D23: - Software Architecture Design - Object Oriented Design - Relational and Non-Relational Database Platforms | E23: 2: Limited Experience | F23: 2: Limited Experience | G23: 3: Intermediate | H23: 4: Advanced | I23: 4: Advanced | J23: 5: Expert | K23: =MAX(LEFT(E23,1),LEFT(F23,1), LEFT(G23,1), LEFT(H23,1), LEFT(I23,1), LEFT(J23,1)) -> 5 | M23: =(LEFT(E23,1)*$C23/$K$23)*100 -> 0.4 | N23: =(LEFT(F23,1)*$C23/$K$23)*100 -> 0.4 | O23: =(LEFT(G23,1)*$C23/$K$23)*100 -> 0.6 | P23: =(LEFT(H23,1)*$C23/$K$23)*100 -> 0.8 | Q23: =(LEFT(I23,1)*$C23/$K$23)*100 -> 0.8 | R23: =(LEFT(J23,1)*$C23/$K$23)*100 -> 1
B24: ='02. Models'!B24 -> Business Analysis Tools | C24: ='02. Models'!D24 -> 0.02 | D24: - Business Analysis Tools - UI/UX Design Tools - Architecture Design Tools - Communication Tools | E24: 2: Limited Experience | F24: 3: Intermediate | G24: 3: Intermediate | H24: 4: Advanced | I24: 4: Advanced | J24: 5: Expert | K24: =MAX(LEFT(E24,1),LEFT(F24,1), LEFT(G24,1), LEFT(H24,1), LEFT(I24,1), LEFT(J24,1)) -> 5 | M24: =(LEFT(E24,1)*$C24/$K$24)*100 -> 0.8 | N24: =(LEFT(F24,1)*$C24/$K$24)*100 -> 1.2 | O24: =(LEFT(G24,1)*$C24/$K$24)*100 -> 1.2 | P24: =(LEFT(H24,1)*$C24/$K$24)*100 -> 1.6 | Q24: =(LEFT(I24,1)*$C24/$K$24)*100 -> 1.6 | R24: =(LEFT(J24,1)*$C24/$K$24)*100 -> 2
B25: ='02. Models'!B25 -> Foreign Language & Certificates | C25: =SUM(C26:C29) -> 0.1 | D25: FSOFTER may have one or more of the following Foreign Language/Technical qualifications to perform assigned tasks | M25: =SUM(M26:M29) -> 4.8333333 | N25: =SUM(N26:N29) -> 5.8333333 | O25: =SUM(O26:O29) -> 7.6666667 | P25: =SUM(P26:P29) -> 8.6666667 | Q25: =SUM(Q26:Q29) -> 9.5 | R25: =SUM(R26:R29) -> 10
B26: ='02. Models'!B26 -> Foreign Language | C26: ='02. Models'!D26 -> 0.05 | D26: - Language Proficiency: English, Japanese, Korean, Chinese, Germany, French, Thailand | E26: 2: TOEIC 451-500, TOELF iBT 42-50, IELTS 4.0-4.5, CEFR B1, JP N4 or equivalent | F26: 3: TOEIC 501-600, TOELF iBT 51-60, IELTS 4.6-5.5, CEFR B1+, JP N4+ or equivalent | G26: 4: TOEIC 601-700, TOELF iBT 61-70, IELTS 5.6-6.5, CEFR B2, JP N3 or equivalent | H26: 5: TOEIC 701-800, TOELF iBT 71-80, IELTS 6.6-7.5, CEFR B2+, JP N3+ or equivalent | I26: 5: TOEIC 701-800, TOELF iBT 71-80, IELTS 6.6-7.5, CEFR B2+, JP N3+ or equivalent | J26: 5: TOEIC 701-800, TOELF iBT 71-80, IELTS 6.6-7.5, CEFR B2+, JP N3+ or equivalent | K26: =MAX(LEFT(E26,1),LEFT(F26,1), LEFT(G26,1), LEFT(H26,1), LEFT(I26,1), LEFT(J26,1)) -> 5 | M26: =(LEFT(E26,1)*$C26/$K$26)*100 -> 2 | N26: =(LEFT(F26,1)*$C26/$K$26)*100 -> 3 | O26: =(LEFT(G26,1)*$C26/$K$26)*100 -> 4 | P26: =(LEFT(H26,1)*$C26/$K$26)*100 -> 5 | Q26: =(LEFT(I26,1)*$C26/$K$26)*100 -> 5 | R26: =(LEFT(J26,1)*$C26/$K$26)*100 -> 5
B27: ='02. Models'!B27 -> Education Background | C27: ='02. Models'!D27 -> 0.02 | D27: Required one of degree in Engineering and Non-Engineering: - Engineering: Computer Science | Information Technology | Computer Engineering | Software Engineering, ... - Non-Engineering: Economics, Finances, Administrations, Social Science, Supply Chain, Logistics, ... | E27: 3-Bachelor Degree / Post-Baccalaureate Certificate | F27: 3-Bachelor Degree / Post-Baccalaureate Certificate | G27: 3-Bachelor Degree / Post-Baccalaureate Certificate | H27: 3-Bachelor Degree / Post-Baccalaureate Certificate | I27: 3-Bachelor Degree / Post-Baccalaureate Certificate | J27: 3-Bachelor Degree / Post-Baccalaureate Certificate | K27: =MAX(LEFT(E27,1),LEFT(F27,1), LEFT(G27,1), LEFT(H27,1), LEFT(I27,1), LEFT(J27,1)) -> 3 | M27: =(LEFT(E27,1)*$C27/$K$27)*100 -> 2 | N27: =(LEFT(F27,1)*$C27/$K$27)*100 -> 2 | O27: =(LEFT(G27,1)*$C27/$K$27)*100 -> 2 | P27: =(LEFT(H27,1)*$C27/$K$27)*100 -> 2 | Q27: =(LEFT(I27,1)*$C27/$K$27)*100 -> 2 | R27: =(LEFT(J27,1)*$C27/$K$27)*100 -> 2
B28: ='02. Models'!B28 -> Business Analysis Certifications | C28: ='02. Models'!D28 -> 0.02 | D28: - Required certificates in Business Analysis: Business Analyst, Software Business Analyst | E28: 1: At least 1 Certified Business Analyst Foundation or Equivalent | F28: 1: At least 1 Certified Business Analyst Foundation or Equivalent | G28: 2: Certified Business Analyst Advance or Equivalent | H28: 2: Certified Business Analyst Advance or Equivalent | I28: 3: >=2 Certificates of Business Analyst Advance or Equivalent | J28: 4: >=3 Certificates of Business Analyst Advance or Equivalent | K28: =MAX(LEFT(E28,1),LEFT(F28,1), LEFT(G28,1), LEFT(H28,1), LEFT(I28,1), LEFT(J28,1)) -> 4 | M28: =(LEFT(E28,1)*$C28/$K$28)*100 -> 0.5 | N28: =(LEFT(F28,1)*$C28/$K$28)*100 -> 0.5 | O28: =(LEFT(G28,1)*$C28/$K$28)*100 -> 1 | P28: =(LEFT(H28,1)*$C28/$K$28)*100 -> 1 | Q28: =(LEFT(I28,1)*$C28/$K$28)*100 -> 1.5 | R28: =(LEFT(J28,1)*$C28/$K$28)*100 -> 2
B29: ='02. Models'!B29 -> Individual Learning in Year | C29: ='02. Models'!D29 -> 0.01 | D29: - Joined the training courses of any FSOFT program (upskilling, reskilling, fasttrack, internal training) related to Business Analysis in year (ranking year) | E29: 1: Join <=2 training or workshop | F29: 1: Join <=2 training or workshop | G29: 2: Join >=3 training or workshop | H29: 2: Join >=3 training or workshop | I29: 3: Join >=5 training or workshop | J29: 3: Join >=5 training or workshop | K29: =MAX(LEFT(E29,1),LEFT(F29,1), LEFT(G29,1), LEFT(H29,1), LEFT(I29,1), LEFT(J29,1)) -> 3 | M29: =(LEFT(E29,1)*$C29/$K$29)*100 -> 0.33333333 | N29: =(LEFT(F29,1)*$C29/$K$29)*100 -> 0.33333333 | O29: =(LEFT(G29,1)*$C29/$K$29)*100 -> 0.66666667 | P29: =(LEFT(H29,1)*$C29/$K$29)*100 -> 0.66666667 | Q29: =(LEFT(I29,1)*$C29/$K$29)*100 -> 1 | R29: =(LEFT(J29,1)*$C29/$K$29)*100 -> 1
B30: ='02. Models'!B30 -> Non-Engineering and Softskills | C30: =SUM(C31:C35) -> 0.1 | D30: FSOFTER is required to have one or more of the following soft skills and other skills to perform assigned tasks | M30: =SUM(M31:M35) -> 2.5 | N30: =SUM(N31:N35) -> 3 | O30: =SUM(O31:O35) -> 5 | P30: =SUM(P31:P35) -> 6.5 | Q30: =SUM(Q31:Q35) -> 8.5 | R30: =SUM(R31:R35) -> 10
B31: ='02. Models'!B31 -> Communication and Problem Solving | C31: ='02. Models'!D31 -> 0.03 | D31: - Team Work - Leadership & Motivation - Communication - Problem Solving - Change Management - Networking/ Relationship building | E31: 1: Fundamental Awareness | F31: 1: Fundamental Awareness | G31: 2: Limited Experience | H31: 2: Limited Experience | I31: 3: Intermediate | J31: 4: Advanced | K31: =MAX(LEFT(E31,1),LEFT(F31,1), LEFT(G31,1), LEFT(H31,1), LEFT(I31,1), LEFT(J31,1)) -> 4 | M31: =(LEFT(E31,1)*$C31/$K$31)*100 -> 0.75 | N31: =(LEFT(F31,1)*$C31/$K$31)*100 -> 0.75 | O31: =(LEFT(G31,1)*$C31/$K$31)*100 -> 1.5 | P31: =(LEFT(H31,1)*$C31/$K$31)*100 -> 1.5 | Q31: =(LEFT(I31,1)*$C31/$K$31)*100 -> 2.25 | R31: =(LEFT(J31,1)*$C31/$K$31)*100 -> 3
B32: ='02. Models'!B33 -> Analytical and Critical Thinking | C32: ='02. Models'!D33 -> 0.02 | D32: - Research - Forecasting - Data mining - Data and metrics interpreting - Reporting - Organization | E32: 1: Fundamental Awareness | F32: 2: Limited Experience | G32: 2: Limited Experience | H32: 3: Intermediate | I32: 4: Advanced | J32: 4: Advanced | K32: =MAX(LEFT(E32,1),LEFT(F32,1), LEFT(G32,1), LEFT(H32,1), LEFT(I32,1), LEFT(J32,1)) -> 4 | M32: =(LEFT(E32,1)*$C32/$K$32)*100 -> 0.5 | N32: =(LEFT(F32,1)*$C32/$K$32)*100 -> 1 | O32: =(LEFT(G32,1)*$C32/$K$32)*100 -> 1 | P32: =(LEFT(H32,1)*$C32/$K$32)*100 -> 1.5 | Q32: =(LEFT(I32,1)*$C32/$K$32)*100 -> 2 | R32: =(LEFT(J32,1)*$C32/$K$32)*100 -> 2
B33: ='02. Models'!B32 -> Organization and Industry Knowledge | C33: ='02. Models'!D32 -> 0.02 | D33: - Agile Mindset - Process Understanding - Product Understanding - Market trends & Challenges - Market drivers - Customer Segmentation Understanding - Organization Knowledge | E33: 1: Fundamental Awareness | F33: 1: Fundamental Awareness | G33: 2: Limited Experience | H33: 3: Intermediate | I33: 3: Intermediate | J33: 4: Advanced | K33: =MAX(LEFT(E33,1),LEFT(F33,1), LEFT(G33,1), LEFT(H33,1), LEFT(I33,1), LEFT(J33,1)) -> 4 | M33: =(LEFT(E33,1)*$C33/$K$33)*100 -> 0.5 | N33: =(LEFT(F33,1)*$C33/$K$33)*100 -> 0.5 | O33: =(LEFT(G33,1)*$C33/$K$33)*100 -> 1 | P33: =(LEFT(H33,1)*$C33/$K$33)*100 -> 1.5 | Q33: =(LEFT(I33,1)*$C33/$K$33)*100 -> 1.5 | R33: =(LEFT(J33,1)*$C33/$K$33)*100 -> 2
B34: ='02. Models'!B34 -> Project Risk Management | C34: ='02. Models'!D34 -> 0.02 | D34: - Understand and utilize process of implementing risk response plans - Tracking identified risks, monitoring residual risks, identifying new risks - Evaluating risk process effectiveness throughout the project. - Forecast risk that may occur in range of project that the team is responsible for. - Analyze and perform preventitive actions to reduce risks raised by members. - In the case that risks cannot be closed, raise the risk to leader/mamager and discuss with leader/manger to find out preventitive actions then follow up. (the risk in Methodology is the risk of Business solution. the risk mentioned in this sheet derives from project activities, especially in oursourcing project.) | E34: 1: Fundamental Awareness | F34: 1: Fundamental Awareness | G34: 2: Limited Experience | H34: 3: Intermediate | I34: 4: Advanced | J34: 4: Advanced | K34: =MAX(LEFT(E34,1),LEFT(F34,1), LEFT(G34,1), LEFT(H34,1), LEFT(I34,1), LEFT(J34,1)) -> 4 | M34: =(LEFT(E34,1)*$C34/$K$34)*100 -> 0.5 | N34: =(LEFT(F34,1)*$C34/$K$34)*100 -> 0.5 | O34: =(LEFT(G34,1)*$C34/$K$34)*100 -> 1 | P34: =(LEFT(H34,1)*$C34/$K$34)*100 -> 1.5 | Q34: =(LEFT(I34,1)*$C34/$K$34)*100 -> 2 | R34: =(LEFT(J34,1)*$C34/$K$34)*100 -> 2
B35: ='02. Models'!B35 -> Project Human Resource Management | C35: ='02. Models'!D35 -> 0.01 | D35: - Understand the ability of each BA to assign appropriate projects/tasks. - Understand project request for BA service to determine proper resource plan. - Regularly control BA allocation to optimize resource. - Monitor and control progress and status of BA involvement in each and every project; detect, resolve and followup to close any issue arising. - Evaluate performance, identify strengths as well as improvement points and propose career path for each BA | E35: 1: Fundamental Awareness | F35: 1: Fundamental Awareness | G35: 2: Limited Experience | H35: 2: Limited Experience | I35: 3: Intermediate | J35: 4: Advanced | K35: =MAX(LEFT(E35,1),LEFT(F35,1), LEFT(G35,1), LEFT(H35,1), LEFT(I35,1), LEFT(J35,1)) -> 4 | M35: =(LEFT(E35,1)*$C35/$K$35)*100 -> 0.25 | N35: =(LEFT(F35,1)*$C35/$K$35)*100 -> 0.25 | O35: =(LEFT(G35,1)*$C35/$K$35)*100 -> 0.5 | P35: =(LEFT(H35,1)*$C35/$K$35)*100 -> 0.5 | Q35: =(LEFT(I35,1)*$C35/$K$35)*100 -> 0.75 | R35: =(LEFT(J35,1)*$C35/$K$35)*100 -> 1

Sheet 05. Job Rankings
A1: Job Rankings | E1: CANDIDATE'S SELF-RANKED RESULTS SCORED BY MANAGER / LEADER / HOD | H1: YOUR ASSESSMENT RANK TO COMPARE CORRESPONDING RANK | J1: ="Number of the required criteria not passed for RANK: " & H3 -> Number of the required criteria not passed for RANK: BANE04 | K1: CHOOSE EXPECTED RANK TO COMPARE | M1: ACTIONS TO IMPROVE YOUR RANKINGS
B2: Software Business Analyst Role - Job Assessment
B3: [Name] - [Account] | E3: =IF(J5=0,"YOUR ASSESSMENT RANK: "&IF(G3>='04. Job Descriptions'!R4,'04. Job Descriptions'!R2&"-"&'04. Job Descriptions'!R3,IF(G3>='04. Job Descriptions'!Q4,'04. Job Descriptions'!Q2&"-"&'04. Job Descriptions'!Q3,IF(G3>='04. Job Descriptions'!P4,'04. Job Descriptions'!P2&"-"&'04. Job Descriptions'!P3,IF(G3>='04. Job Descriptions'!O4,'04. Job Descriptions'!O2&"-"&'04. Job Descriptions'!O3,IF(G3>='04. Job Descriptions'!N4,'04. Job Descriptions'!N2&"-"&'04. Job Descriptions'!N3,IF(G3>='04. Job Descriptions'!M4,'04. Job Descriptions'!M2&"-"&'04. Job Descriptions'!M3,'06. Assessment Summary'!E5)))))),"YOU ACHIEVED RANK: "&VLOOKUP(LEFT(H3,5)&RIGHT(H3,1)-1,'08. Definitions'!$C$14:$D$20,2,FALSE)&"-"&LEFT(H3,5)&RIGHT(H3,1)-1) -> YOU ACHIEVED RANK: Senior Business Analyst-BANE03 | G3: =G5+G8+G15+G25+G30 -> 70.316667 | H3: =IF(G3>='04. Job Descriptions'!R4,'04. Job Descriptions'!R3,IF(G3>='04. Job Descriptions'!Q4,'04. Job Descriptions'!Q3,IF(G3>='04. Job Descriptions'!P4,'04. Job Descriptions'!P3,IF(G3>='04. Job Descriptions'!O4,'04. Job Descriptions'!O3,IF(G3>='04. Job Descriptions'!N4,'04. Job Descriptions'!N3,IF(G3>='04. Job Descriptions'!M4,'04. Job Descriptions'!M3,'06. Assessment Summary'!E5)))))) -> BANE04 | K3: BANE04 | L3: =L5+L8+L15+L25+L30 -> 67.816667
B4: Assessment Items | C4: Explanation of Assessment Items | D4: Weighted % | E4: Choose competency level for each evaluation criteria | F4: Add remarks or evidences for each evaluation if any | G4: Actual Score | H4: ="Competency Level for RANK: " & H3 -> Competency Level for RANK: BANE04 | I4: =H3 & " Score(s)" -> BANE04 Score(s) | K4: Required Competency Level for Your Expected RANK | L4: Required Score | M4: Need to improve? | N4: Action to improve | O4: Deadline
B5: ='04. Job Descriptions'!B5 -> Roles & Responsibilities | C5: ='04. Job Descriptions'!D5 -> FSOFTER is required to have the role and responsibility to perform one or more of the following tasks | D5: ='04. Job Descriptions'!C5 -> 0.15 | G5: =SUM(G6:G7) -> 10.35 | I5: =SUM(I6:I7) -> 10.35 | J5: =COUNTIF(J6:J35,"Yes") -> 1 | L5: =SUM(L6:L7) -> 10.35
B6: ='04. Job Descriptions'!B6 -> Roles and Responsibilities | C6: ='04. Job Descriptions'!D6 -> Implementing all the processes and activities related to business analysis which can be analyzing and designing functional and non-functional requirements to the development, client or production environment, including but not limited to following responsibilities: BANE01: - Has responsibility for documenting requirement, supporting communicate requirement to stakeholders (under guidance) as role BA member. - Project Diversity and Complexity - Low: >=5 items in Elementary Complexity Criteria BANE02: - Has responsibility for gathering requirement, elaborating and validating gathered requirement as role BA member. - Project Diversity and Complexity - Normal: All items of Elementary Complexity Criteria & >= 1 item in General Advanced Complexity Criteria BANE03: - Has responsibility for designing, analyzing and evaluating business solution to ensure that it aligns with the project's goal as role BA member. - Project Diversity and Complexity - Medium: >= 4 items of General Advanced Complexity Criteria & >= 2 items of Management Complexity Criteria OR >= 4 items of General Advanced Complexity Criteria & >=1 item in Consultant Complexity Criteria BANE04: - Has responsibility for defining requirement approach & process, planning and monitoring business analysis activities as role BA consultant. - Project Diversity and Complexity - Complex: >= 4 items in General Advanced Complexity Criteria & All items in Management Complexity Criteria OR >= 5 items in General Advanced Complexity Criteria & >= 2 item of Consultant Complexity Criteria BANE05: - Has responsibility for performing system evaluation & enterprise solution consultation as role BA consultant. - Project Diversity and Complexity - Complex: >= 4 items in General Advanced Complexity Criteria & All items in Management Complexity Criteria OR >= 5 items in General Advanced Complexity Criteria & >= 2 item of Consultant Complexity Criteria BANE06: - Has responsibility for performing system evaluation & enterprise solution consultation as role BA consultant. - Project Diversity and Complexity - Very Complex: >= 4 items of Advanced Complexity Criteria & All items of Management Complexity Criteria OR All items in General Advanced & All Consultant Complexity Criteria | D6: ='04. Job Descriptions'!C6 -> 0.12 | E6: 4: Create (BANE04) | G6: =IFERROR((LEFT(E6,1)*$D6/'04. Job Descriptions'!K6)*100,0) -> 9.6 | H6: =IFERROR(HLOOKUP(H3,'04. Job Descriptions'!$B$4:$J$35,3,0),"NA") -> 4: Create (BANE04) | I6: =IFERROR(HLOOKUP($H$3,'04. Job Descriptions'!$M$3:$R$35,4,0),"NA") -> 9.6 | J6: =IF(G6<I6,"Yes","No") -> No | K6: =IFERROR(HLOOKUP($K$3,'04. Job Descriptions'!$B$4:$J$35,3,0),"NA") -> 4: Create (BANE04) | L6: =IFERROR(HLOOKUP($K$3,'04. Job Descriptions'!$M$3:$R$35,4,0),"NA") -> 9.6 | M6: =IF(G6<L6,"Yes","No") -> No
B7: ='04. Job Descriptions'!B7 -> Team Size To Lead for BA Leader | C7: ='04. Job Descriptions'!D7 -> 4: Global Level - Have at least 70% BA2, 10% BA3, 3% BA4, 0.75%BA5 3: FSOFT Level - Have at least 50% BA2, 10% BA3, 3% BA4, 0.75%BA5 2: FSU Level - Have at least 50% BA2, 12% BA3, 3% BA4 1: BU Level - Have at least 50% BA2, 12% BA3 0: Not Required | D7: ='04. Job Descriptions'!C7 -> 0.03 | E7: 1: BU Level | G7: =IFERROR((LEFT(E7,1)*$D7/'04. Job Descriptions'!K7)*100,0) -> 0.75 | H7: =IFERROR(HLOOKUP(H3,'04. Job Descriptions'!$B$4:$J$35,4,0),"NA") -> 1: BU Level | I7: =IFERROR(HLOOKUP($H$3,'04. Job Descriptions'!$M$3:$R$35,5,0),"NA") -> 0.75 | J7: =IF(G7<I7,"Yes","No") -> No | K7: =IFERROR(HLOOKUP($K$3,'04. Job Descriptions'!$B$4:$J$35,4,0),"NA") -> 1: BU Level | L7: =IFERROR(HLOOKUP($K$3,'04. Job Descriptions'!$M$3:$R$35,5,0),"NA") -> 0.75 | M7: =IF(G7<L7,"Yes","No") -> No
B8: ='04. Job Descriptions'!B8 -> Experiences & Contributions | C8: ='04. Job Descriptions'!D8 -> FSOFTER is required to have one or more of the following professional experiences and project contributions | D8: ='04. Job Descriptions'!C8 -> 0.25 | G8: =SUM(G9:G14) -> 17.4 | I8: =SUM(I9:I14) -> 13.3 | L8: =SUM(L9:L14) -> 13.3
B9: ='04. Job Descriptions'!B9 -> Business Analysis Experiences (*) | C9: ='04. Job Descriptions'!D9 -> Number of years working as Business Analyst, Software Business Analyst, Software Development Life Cycle, Team Work, Agile Mindset | D9: ='04. Job Descriptions'!C9 -> 0.05 | E9: 3: 3-5 years experience | G9: =IFERROR((LEFT(E9,1)*D9/'04. Job Descriptions'!K9)*100,0) -> 3 | H9: =IFERROR(HLOOKUP($H$3,'04. Job Descriptions'!$B$4:$J$35,6,0),"NA") -> 3: 3-5 years experience | I9: =IFERROR(HLOOKUP($H$3,'04. Job Descriptions'!$M$3:$R$35,7,0),"NA") -> 3 | J9: =IF(G9<I9,"Yes","No") -> No | K9: =IFERROR(HLOOKUP($K$3,'04. Job Descriptions'!$B$4:$J$35,6,0),"NA") -> 3: 3-5 years experience | L9: =IFERROR(HLOOKUP($K$3,'04. Job Descriptions'!$M$3:$R$35,7,0),"NA") -> 3 | M9: =IF(G9<L9,"Yes","No") -> No
B10: ='04. Job Descriptions'!B10 -> Subordinate Development | C10: ='04. Job Descriptions'!D10 -> Number of team members or number of people trained/coached | D10: ='04. Job Descriptions'!C10 -> 0.03 | E10: 2: 5-10 Members or Coaching 3-4 Junior BA | G10: =IFERROR((LEFT(E10,1)*D10/'04. Job Descriptions'!K10)*100,0) -> 1.5 | H10: =IFERROR(HLOOKUP($H$3,'04. Job Descriptions'!$B$4:$J$35,7,0),"NA") -> 2: 5-10 Members or Coaching 3-4 Junior BA | I10: =IFERROR(HLOOKUP($H$3,'04. Job Descriptions'!$M$3:$R$35,8,0),"NA") -> 1.5 | K10: =IFERROR(HLOOKUP($K$3,'04. Job Descriptions'!$B$4:$J$35,7,0),"NA") -> 2: 5-10 Members or Coaching 3-4 Junior BA | L10: =IFERROR(HLOOKUP($K$3,'04. Job Descriptions'!$M$3:$R$35,8,0),"NA") -> 1.5 | M10: =IF(G10<L10,"Yes","No") -> No
B11: ='04. Job Descriptions'!B11 -> Number of Projects/Phases | C11: ='04. Job Descriptions'!D11 -> The successful projects in business requirements that you have done at least one of the following tasks: analyze, design, develop, support, migrate, deploy, manage software projects or phases (FSOFTER can provide joined project is project rank of Project Rank A, Project Rank B, Project Rank C in Evidence section) | D11: ='04. Job Descriptions'!C11 -> 0.03 | E11: 4: ~11-15 Projects / Phases | G11: =IFERROR((LEFT(E11,1)*D11/'04. Job Descriptions'!K11)*100,0) -> 2.4 | H11: =IFERROR(HLOOKUP($H$3,'04. Job Descriptions'!$B$4:$J$35,8,0),"NA") -> 3: ~06-10 Projects / Phases | I11: =IFERROR(HLOOKUP($H$3,'04. Job Descriptions'!$M$3:$R$35,9,0),"NA") -> 1.8 | K11: =IFERROR(HLOOKUP($K$3,'04. Job Descriptions'!$B$4:$J$35,8,0),"NA") -> 3: ~06-10 Projects / Phases | L11: =IFERROR(HLOOKUP($K$3,'04. Job Descriptions'!$M$3:$R$35,9,0),"NA") -> 1.8 | M11: =IF(G11<L11,"Yes","No") -> No
B12: ='04. Job Descriptions'!B12 -> Community Contributions | C12: ='04. Job Descriptions'!D12 -> Business Analyst Activities to support/training other projects/team, presenter of workshop, contribute IP/solution… | D12: ='04. Job Descriptions'!C12 -> 0.02 | E12: 3: Lecturer/Trainer of Technical workshop of FSU | G12: =IFERROR((LEFT(E12,1)*D12/'04. Job Descriptions'!K12)*100,0) -> 1.5 | H12: =IFERROR(HLOOKUP($H$3,'04. Job Descriptions'!$B$4:$J$35,9,0),"NA") -> 2: Contribute >= 1 IP/Solution at project level | I12: =IFERROR(HLOOKUP($H$3,'04. Job Descriptions'!$M$3:$R$35,10,0),"NA") -> 1 | K12: =IFERROR(HLOOKUP($K$3,'04. Job Descriptions'!$B$4:$J$35,9,0),"NA") -> 2: Contribute >= 1 IP/Solution at project level | L12: =IFERROR(HLOOKUP($K$3,'04. Job Descriptions'!$M$3:$R$35,10,0),"NA") -> 1 | M12: =IF(G12<L12,"Yes","No") -> No
B13: ='04. Job Descriptions'!B13 -> Industry Experiences (IT and Non-IT fields) | C13: ='04. Job Descriptions'!D13 -> Banking, Finance, Insurance, Aviation, Automotive, Oil and Gas, Health Care, ERP, Data Warehouse, Logistic, Real estate, Telecom, … | D13: ='04. Job Descriptions'!C13 -> 0.1 | E13: 3: 3-5 years experience | G13: =IFERROR((LEFT(E13,1)*D13/'04. Job Descriptions'!K13)*100,0) -> 7.5 | H13: =IFERROR(HLOOKUP($H$3,'04. Job Descriptions'!$B$4:$J$35,10,0),"NA") -> 2: 2-3 years experience | I13: =IFERROR(HLOOKUP($H$3,'04. Job Descriptions'!$M$3:$R$35,11,0),"NA") -> 5 | K13: =IFERROR(HLOOKUP($K$3,'04. Job Descriptions'!$B$4:$J$35,10,0),"NA") -> 2: 2-3 years experience | L13: =IFERROR(HLOOKUP($K$3,'04. Job Descriptions'!$M$3:$R$35,11,0),"NA") -> 5 | M13: =IF(G13<L13,"Yes","No") -> No
B14: ='04. Job Descriptions'!B14 -> Consulting for Sales/Biding Teams | C14: ='04. Job Descriptions'!D14 -> Business Requirements, Technology Stack, Customer Experience, Vision Development, Processes and Activities, Pricing and Positioning Strategies, Drive Product Launch, … | D14: ='04. Job Descriptions'!C14 -> 0.02 | E14: 3: 3-5 years experience | G14: =IFERROR((LEFT(E14,1)*D14/'04. Job Descriptions'!K14)*100,0) -> 1.5 | H14: =IFERROR(HLOOKUP($H$3,'04. Job Descriptions'!$B$4:$J$35,11,0),"NA") -> 2: 2-3 years experience | I14: =IFERROR(HLOOKUP($H$3,'04. Job Descriptions'!$M$3:$R$35,12,0),"NA") -> 1 | K14: =IFERROR(HLOOKUP($K$3,'04. Job Descriptions'!$B$4:$J$35,11,0),"NA") -> 2: 2-3 years experience | L14: =IFERROR(HLOOKUP($K$3,'04. Job Descriptions'!$M$3:$R$35,12,0),"NA") -> 1 | M14: =IF(G14<L14,"Yes","No") -> No
B15: ='04. Job Descriptions'!B15 -> Professional Business Analysis Skills | C15: ='04. Job Descriptions'!D15 -> FSOFTER is required to have one or more of the following specialized skills to perform assigned tasks | D15: ='04. Job Descriptions'!C15 -> 0.4 | G15: =SUM(G16:G24) -> 27.4 | I15: =SUM(I16:I24) -> 29 | L15: =SUM(L16:L24) -> 29
B16: ='04. Job Descriptions'!B16 -> Business Analysis Planning & Monitoring (*) | C16: ='04. Job Descriptions'!D16 -> - Plan Business Analysis Approach - Plan Stakeholders Engagement - Plan Business Analysis Governance - Plan Business Analysis Information Management - Identify Business Analysis Performance Improvement | D16: ='04. Job Descriptions'!C16 -> 0.08 | E16: 2: Limited Experience | G16: =IFERROR((LEFT(E16,1)*D16/'04. Job Descriptions'!K16)*100,0) -> 3.2 | H16: =IFERROR(HLOOKUP($H$3,'04. Job Descriptions'!$B$4:$J$35,13,0),"NA") -> 3: Intermediate | I16: =IFERROR(HLOOKUP($H$3,'04. Job Descriptions'!$M$3:$R$35,14,0),"NA") -> 4.8 | J16: =IF(G16<I16,"Yes","No") -> Yes | K16: =IFERROR(HLOOKUP($K$3,'04. Job Descriptions'!$B$4:$J$35,13,0),"NA") -> 3: Intermediate | L16: =IFERROR(HLOOKUP($K$3,'04. Job Descriptions'!$M$3:$R$35,14,0),"NA") -> 4.8 | M16: =IF(G16<L16,"Yes","No") -> Yes
B17: ='04. Job Descriptions'!B17 -> Requirement Elicitation & Collaboration (*) | C17: ='04. Job Descriptions'!D17 -> - Elicitation Preparation - Requirement Workshop / Conduct Elicitation - Requirement Transfer & Confirmation - Requirement Management & Communication - Stakeholders Management | D17: ='04. Job Descriptions'!C17 -> 0.07 | E17: 3: Intermediate | G17: =IFERROR((LEFT(E17,1)*D17/'04. Job Descriptions'!K17)*100,0) -> 4.2 | H17: =IFERROR(HLOOKUP($H$3,'04. Job Descriptions'!$B$4:$J$35,14,0),"NA") -> 3: Intermediate | I17: =IFERROR(HLOOKUP($H$3,'04. Job Descriptions'!$M$3:$R$35,15,0),"NA") -> 4.2 | J17: =IF(G17<I17,"Yes","No") -> No | K17: =IFERROR(HLOOKUP($K$3,'04. Job Descriptions'!$B$4:$J$35,14,0),"NA") -> 3: Intermediate | L17: =IFERROR(HLOOKUP($K$3,'04. Job Descriptions'!$M$3:$R$35,15,0),"NA") -> 4.2 | M17: =IF(G17<L17,"Yes","No") -> No
B18: ='04. Job Descriptions'!B18 -> Business Requirement Analysis (*) | C18: ='04. Job Descriptions'!D18 -> - Requirement Specification - Requirement Verification - Requirement Validation - Requirement UI/UX Behavior Design & Principles - Requirement CX (Customer Experience / Customer Journey) - Solution Definition & Assessment | D18: ='04. Job Descriptions'!C18 -> 0.1 | E18: 4: Advanced | G18: =IFERROR((LEFT(E18,1)*D18/'04. Job Descriptions'!K18)*100,0) -> 8 | H18: =IFERROR(HLOOKUP($H$3,'04. Job Descriptions'!$B$4:$J$35,15,0),"NA") -> 4: Advanced | I18: =IFERROR(HLOOKUP($H$3,'04. Job Descriptions'!$M$3:$R$35,16,0),"NA") -> 8 | J18: =IF(G18<I18,"Yes","No") -> No | K18: =IFERROR(HLOOKUP($K$3,'04. Job Descriptions'!$B$4:$J$35,15,0),"NA") -> 4: Advanced | L18: =IFERROR(HLOOKUP($K$3,'04. Job Descriptions'!$M$3:$R$35,16,0),"NA") -> 8 | M18: =IF(G18<L18,"Yes","No") -> No
B19: ='04. Job Descriptions'!B19 -> Business Solution Evaluation | C19: ='04. Job Descriptions'!D19 -> - Measure Solution Performance - Analyze Performance Measured - Assess Solution Limitations - Assess Enterprise Limitations - Recommend Actions to Increase Solution's Value | D19: ='04. Job Descriptions'!C19 -> 0.05 | E19: 4: Advanced | G19: =IFERROR((LEFT(E19,1)*D19/'04. Job Descriptions'!K19)*100,0) -> 4 | H19: =IFERROR(HLOOKUP($H$3,'04. Job Descriptions'!$B$4:$J$35,16,0),"NA") -> 4: Advanced | I19: =IFERROR(HLOOKUP($H$3,'04. Job Descriptions'!$M$3:$R$35,17,0),"NA") -> 4 | K19: =IFERROR(HLOOKUP($K$3,'04. Job Descriptions'!$B$4:$J$35,16,0),"NA") -> 4: Advanced | L19: =IFERROR(HLOOKUP($K$3,'04. Job Descriptions'!$M$3:$R$35,17,0),"NA") -> 4 | M19: =IF(G19<L19,"Yes","No") -> No
B20: ='04. Job Descriptions'!B20 -> Business Requirement Life-Cycle | C20: ='04. Job Descriptions'!D20 -> - Requirement Tracing - Requirement Maintenance - Requirement Prioritization - Requirement Change Management - Requirement Approval | D20: ='04. Job Descriptions'!C20 -> 0.02 | E20: 4: Advanced | G20: =IFERROR((LEFT(E20,1)*D20/'04. Job Descriptions'!K20)*100,0) -> 1.6 | H20: =IFERROR(HLOOKUP($H$3,'04. Job Descriptions'!$B$4:$J$35,17,0),"NA") -> 4: Advanced | I20: =IFERROR(HLOOKUP($H$3,'04. Job Descriptions'!$M$3:$R$35,18,0),"NA") -> 1.6 | K20: =IFERROR(HLOOKUP($K$3,'04. Job Descriptions'!$B$4:$J$35,17,0),"NA") -> 4: Advanced | L20: =IFERROR(HLOOKUP($K$3,'04. Job Descriptions'!$M$3:$R$35,18,0),"NA") -> 1.6 | M20: =IF(G20<L20,"Yes","No") -> No
B21: ='04. Job Descriptions'!B21 -> Business Strategy Design | C21: ='04. Job Descriptions'!D21 -> - Current State Analysis - Future State Analysis - Risk Analysis - Define Change Strategy | D21: ='04. Job Descriptions'!C21 -> 0.02 | E21: 4: Advanced | G21: =IFERROR((LEFT(E21,1)*D21/'04. Job Descriptions'!K21)*100,0) -> 1.6 | H21: =IFERROR(HLOOKUP($H$3,'04. Job Descriptions'!$B$4:$J$35,18,0),"NA") -> 4: Advanced | I21: =IFERROR(HLOOKUP($H$3,'04. Job Descriptions'!$M$3:$R$35,19,0),"NA") -> 1.6 | K21: =IFERROR(HLOOKUP($K$3,'04. Job Descriptions'!$B$4:$J$35,18,0),"NA") -> 4: Advanced | L21: =IFERROR(HLOOKUP($K$3,'04. Job Descriptions'!$M$3:$R$35,19,0),"NA") -> 1.6 | M21: =IF(G21<L21,"Yes","No") -> No
B22: ='04. Job Descriptions'!B22 -> Business Acumen and Mindsets | C22: ='04. Job Descriptions'!D22 -> - Understanding of fundamental business principles and best practices. - Analysis mindsets | D22: ='04. Job Descriptions'!C22 -> 0.03 | E22: 4: Advanced | G22: =IFERROR((LEFT(E22,1)*D22/'04. Job Descriptions'!K22)*100,0) -> 2.4 | H22: =IFERROR(HLOOKUP($H$3,'04. Job Descriptions'!$B$4:$J$35,19,0),"NA") -> 4: Advanced | I22: =IFERROR(HLOOKUP($H$3,'04. Job Descriptions'!$M$3:$R$35,20,0),"NA") -> 2.4 | K22: =IFERROR(HLOOKUP($K$3,'04. Job Descriptions'!$B$4:$J$35,19,0),"NA") -> 4: Advanced | L22: =IFERROR(HLOOKUP($K$3,'04. Job Descriptions'!$M$3:$R$35,20,0),"NA") -> 2.4 | M22: =IF(G22<L22,"Yes","No") -> No
B23: ='04. Job Descriptions'!B23 -> Software Design and Technology Stack | C23: ='04. Job Descriptions'!D23 -> - Software Architecture Design - Object Oriented Design - Relational and Non-Relational Database Platforms | D23: ='04. Job Descriptions'!C23 -> 0.01 | E23: 4: Advanced | G23: =IFERROR((LEFT(E23,1)*D23/'04. Job Descriptions'!K23)*100,0) -> 0.8 | H23: =IFERROR(HLOOKUP($H$3,'04. Job Descriptions'!$B$4:$J$35,20,0),"NA") -> 4: Advanced | I23: =IFERROR(HLOOKUP($H$3,'04. Job Descriptions'!$M$3:$R$35,21,0),"NA") -> 0.8 | K23: =IFERROR(HLOOKUP($K$3,'04. Job Descriptions'!$B$4:$J$35,20,0),"NA") -> 4: Advanced | L23: =IFERROR(HLOOKUP($K$3,'04. Job Descriptions'!$M$3:$R$35,21,0),"NA") -> 0.8 | M23: =IF(G23<L23,"Yes","No") -> No
B24: ='04. Job Descriptions'!B24 -> Business Analysis Tools | C24: ='04. Job Descriptions'!D24 -> - Business Analysis Tools - UI/UX Design Tools - Architecture Design Tools - Communication Tools | D24: ='04. Job Descriptions'!C24 -> 0.02 | E24: 4: Advanced | G24: =IFERROR((LEFT(E24,1)*D24/'04. Job Descriptions'!K24)*100,0) -> 1.6 | H24: =IFERROR(HLOOKUP($H$3,'04. Job Descriptions'!$B$4:$J$35,21,0),"NA") -> 4: Advanced | I24: =IFERROR(HLOOKUP($H$3,'04. Job Descriptions'!$M$3:$R$35,22,0),"NA") -> 1.6 | K24: =IFERROR(HLOOKUP($K$3,'04. Job Descriptions'!$B$4:$J$35,21,0),"NA") -> 4: Advanced | L24: =IFERROR(HLOOKUP($K$3,'04. Job Descriptions'!$M$3:$R$35,22,0),"NA") -> 1.6 | M24: =IF(G24<L24,"Yes","No") -> No
B25: ='04. Job Descriptions'!B25 -> Foreign Language & Certificates | C25: ='04. Job Descriptions'!D25 -> FSOFTER may have one or more of the following Foreign Language/Technical qualifications to perform assigned tasks | D25: ='04. Job Descriptions'!C25 -> 0.1 | G25: =SUM(G26:G29) -> 8.6666667 | I25: =SUM(I26:I29) -> 8.6666667 | L25: =SUM(L26:L29) -> 8.6666667
B26: ='04. Job Descriptions'!B26 -> Foreign Language | C26: ='04. Job Descriptions'!D26 -> - Language Proficiency: English, Japanese, Korean, Chinese, Germany, French, Thailand | D26: ='04. Job Descriptions'!C26 -> 0.05 | E26: 5: TOEIC 701-800, TOELF iBT 71-80, IELTS 6.6-7.5, CEFR B2+, JP N3+ or equivalent | G26: =IFERROR((LEFT(E26,1)*D26/'04. Job Descriptions'!K26)*100,0) -> 5 | H26: =IFERROR(HLOOKUP($H$3,'04. Job Descriptions'!$B$4:$J$35,23,0),"NA") -> 5: TOEIC 701-800, TOELF iBT 71-80, IELTS 6.6-7.5, CEFR B2+, JP N3+ or equivalent | I26: =IFERROR(HLOOKUP($H$3,'04. Job Descriptions'!$M$3:$R$35,24,0),"NA") -> 5 | K26: =IFERROR(HLOOKUP($K$3,'04. Job Descriptions'!$B$4:$J$35,23,0),"NA") -> 5: TOEIC 701-800, TOELF iBT 71-80, IELTS 6.6-7.5, CEFR B2+, JP N3+ or equivalent | L26: =IFERROR(HLOOKUP($K$3,'04. Job Descriptions'!$M$3:$R$35,24,0),"NA") -> 5 | M26: =IF(G26<L26,"Yes","No") -> No
B27: ='04. Job Descriptions'!B27 -> Education Background | C27: ='04. Job Descriptions'!D27 -> Required one of degree in Engineering and Non-Engineering: - Engineering: Computer Science | Information Technology | Computer Engineering | Software Engineering, ... - Non-Engineering: Economics, Finances, Administrations, Social Science, Supply Chain, Logistics, ... | D27: ='04. Job Descriptions'!C27 -> 0.02 | E27: 3-Bachelor Degree / Post-Baccalaureate Certificate | G27: =IFERROR((LEFT(E27,1)*D27/'04. Job Descriptions'!K27)*100,0) -> 2 | H27: =IFERROR(HLOOKUP($H$3,'04. Job Descriptions'!$B$4:$J$35,24,0),"NA") -> 3-Bachelor Degree / Post-Baccalaureate Certificate | I27: =IFERROR(HLOOKUP($H$3,'04. Job Descriptions'!$M$3:$R$35,25,0),"NA") -> 2 | K27: =IFERROR(HLOOKUP($K$3,'04. Job Descriptions'!$B$4:$J$35,24,0),"NA") -> 3-Bachelor Degree / Post-Baccalaureate Certificate | L27: =IFERROR(HLOOKUP($K$3,'04. Job Descriptions'!$M$3:$R$35,25,0),"NA") -> 2 | M27: =IF(G27<L27,"Yes","No") -> No
B28: ='04. Job Descriptions'!B28 -> Business Analysis Certifications | C28: ='04. Job Descriptions'!D28 -> - Required certificates in Business Analysis: Business Analyst, Software Business Analyst | D28: ='04. Job Descriptions'!C28 -> 0.02 | E28: 2: Certified Business Analyst Advance or Equivalent | G28: =IFERROR((LEFT(E28,1)*D28/'04. Job Descriptions'!K28)*100,0) -> 1 | H28: =IFERROR(HLOOKUP($H$3,'04. Job Descriptions'!$B$4:$J$35,25,0),"NA") -> 2: Certified Business Analyst Advance or Equivalent | I28: =IFERROR(HLOOKUP($H$3,'04. Job Descriptions'!$M$3:$R$35,26,0),"NA") -> 1 | K28: =IFERROR(HLOOKUP($K$3,'04. Job Descriptions'!$B$4:$J$35,25,0),"NA") -> 2: Certified Business Analyst Advance or Equivalent | L28: =IFERROR(HLOOKUP($K$3,'04. Job Descriptions'!$M$3:$R$35,26,0),"NA") -> 1 | M28: =IF(G28<L28,"Yes","No") -> No
B29: ='04. Job Descriptions'!B29 -> Individual Learning in Year | C29: ='04. Job Descriptions'!D29 -> - Joined the training courses of any FSOFT program (upskilling, reskilling, fasttrack, internal training) related to Business Analysis in year (ranking year) | D29: ='04. Job Descriptions'!C29 -> 0.01 | E29: 2: Join >=3 training or workshop | G29: =IFERROR((LEFT(E29,1)*D29/'04. Job Descriptions'!K29)*100,0) -> 0.66666667 | H29: =IFERROR(HLOOKUP($H$3,'04. Job Descriptions'!$B$4:$J$35,26,0),"NA") -> 2: Join >=3 training or workshop | I29: =IFERROR(HLOOKUP($H$3,'04. Job Descriptions'!$M$3:$R$35,27,0),"NA") -> 0.66666667 | K29: =IFERROR(HLOOKUP($K$3,'04. Job Descriptions'!$B$4:$J$35,26,0),"NA") -> 2: Join >=3 training or workshop | L29: =IFERROR(HLOOKUP($K$3,'04. Job Descriptions'!$M$3:$R$35,27,0),"NA") -> 0.66666667 | M29: =IF(G29<L29,"Yes","No") -> No
B30: ='04. Job Descriptions'!B30 -> Non-Engineering and Softskills | C30: ='04. Job Descriptions'!D30 -> FSOFTER is required to have one or more of the following soft skills and other skills to perform assigned tasks | D30: ='04. Job Descriptions'!C30 -> 0.1 | G30: =SUM(G31:G35) -> 6.5 | I30: =SUM(I31:I35) -> 6.5 | L30: =SUM(L31:L35) -> 6.5
B31: ='04. Job Descriptions'!B31 -> Communication and Problem Solving | C31: ='04. Job Descriptions'!D31 -> - Team Work - Leadership & Motivation - Communication - Problem Solving - Change Management - Networking/ Relationship building | D31: ='04. Job Descriptions'!C31 -> 0.03 | E31: 2: Limited Experience | G31: =IFERROR((LEFT(E31,1)*D31/'04. Job Descriptions'!K31)*100,0) -> 1.5 | H31: =IFERROR(HLOOKUP($H$3,'04. Job Descriptions'!$B$4:$J$35,28,0),"NA") -> 2: Limited Experience | I31: =IFERROR(HLOOKUP($H$3,'04. Job Descriptions'!$M$3:$R$35,29,0),"NA") -> 1.5 | K31: =IFERROR(HLOOKUP($K$3,'04. Job Descriptions'!$B$4:$J$35,28,0),"NA") -> 2: Limited Experience | L31: =IFERROR(HLOOKUP($K$3,'04. Job Descriptions'!$M$3:$R$35,29,0),"NA") -> 1.5 | M31: =IF(G31<L31,"Yes","No") -> No
B32: ='04. Job Descriptions'!B32 -> Analytical and Critical Thinking | C32: ='04. Job Descriptions'!D32 -> - Research - Forecasting - Data mining - Data and metrics interpreting - Reporting - Organization | D32: ='04. Job Descriptions'!C32 -> 0.02 | E32: 3: Intermediate | G32: =IFERROR((LEFT(E32,1)*D32/'04. Job Descriptions'!K32)*100,0) -> 1.5 | H32: =IFERROR(HLOOKUP($H$3,'04. Job Descriptions'!$B$4:$J$35,29,0),"NA") -> 3: Intermediate | I32: =IFERROR(HLOOKUP($H$3,'04. Job Descriptions'!$M$3:$R$35,30,0),"NA") -> 1.5 | K32: =IFERROR(HLOOKUP($K$3,'04. Job Descriptions'!$B$4:$J$35,29,0),"NA") -> 3: Intermediate | L32: =IFERROR(HLOOKUP($K$3,'04. Job Descriptions'!$M$3:$R$35,30,0),"NA") -> 1.5 | M32: =IF(G32<L32,"Yes","No") -> No
B33: ='04. Job Descriptions'!B33 -> Organization and Industry Knowledge | C33: ='04. Job Descriptions'!D33 -> - Agile Mindset - Process Understanding - Product Understanding - Market trends & Challenges - Market drivers - Customer Segmentation Understanding - Organization Knowledge | D33: ='04. Job Descriptions'!C33 -> 0.02 | E33: 3: Intermediate | G33: =IFERROR((LEFT(E33,1)*D33/'04. Job Descriptions'!K33)*100,0) -> 1.5 | H33: =IFERROR(HLOOKUP($H$3,'04. Job Descriptions'!$B$4:$J$35,30,0),"NA") -> 3: Intermediate | I33: =IFERROR(HLOOKUP($H$3,'04. Job Descriptions'!$M$3:$R$35,31,0),"NA") -> 1.5 | K33: =IFERROR(HLOOKUP($K$3,'04. Job Descriptions'!$B$4:$J$35,30,0),"NA") -> 3: Intermediate | L33: =IFERROR(HLOOKUP($K$3,'04. Job Descriptions'!$M$3:$R$35,31,0),"NA") -> 1.5 | M33: =IF(G33<L33,"Yes","No") -> No
