Workbook

Sheet Senior
A1: Anh, chị Interviewer vui lòng fill thông tin vào các ô màu xanh lá cây | E1: =25/2 -> 12.5
A2: INTERVIEW CHECK LIST
A3: Candidate name
A4: Interviewer name
A5: # | B5: Category | C5: Standard for 10 scores | D5: Description | E5: Score (1~10) | F5: Rate
A6: 1 | B6: Japanese | C6: Listening | D6: N3+ | E6: =IF(D6="N1",10,IF(D6="N1-",9.5,IF(D6="N2+",9,IF(D6="N2",8,IF(D6="N2-",7.5,IF(D6="N3+",7,IF(D6="N3",6,IF(D6="N3-",5,IF(D6="N4",4,IF(D6="N5",3,0)))))))))) -> 7 | F6: 0.125 | G6: =E6*F6 -> 0.875
C7: Speaking | D7: N3+ | E7: =IF(D7="N1",10,IF(D7="N1-",9.5,IF(D7="N2+",9,IF(D7="N2",8,IF(D7="N2-",7.5,IF(D7="N3+",7,IF(D7="N3",6,IF(D7="N3-",5,IF(D7="N4",4,IF(D7="N5",3,0)))))))))) -> 7 | F7: 0.125
C8: Writing | D8: N3+ | E8: =IF(D8="N1",10,IF(D8="N1-",9.5,IF(D8="N2+",9,IF(D8="N2",8,IF(D8="N2-",7.5,IF(D8="N3+",7,IF(D8="N3",6,IF(D8="N3-",5,IF(D8="N4",4,IF(D8="N5",3,0)))))))))) -> 7 | F8: 0.05
C9: Reading | D9: N3+ | E9: =IF(D9="N1",10,IF(D9="N1-",9.5,IF(D9="N2+",9,IF(D9="N2",8,IF(D9="N2-",7.5,IF(D9="N3+",7,IF(D9="N3",6,IF(D9="N3-",5,IF(D9="N4",4,IF(D9="N5",3,0)))))))))) -> 7 | F9: 0.05
A10: 2 | B10: English | C10: Intermediate | E10: =IF(C10="Elementary",2.5,IF(C10="Intermediate",5,IF(C10="Advanced",8,IF(C10="Proficiency",10,0)))) -> 5 | F10: 0.05 | G10: =E10*F10 -> 0.25
A11: 3 | B11: Education | C11: ĐH | D11: Ghi rõ tên tất cả các trường đã TN và năm TN | E11: =IF(C12=Reference!#REF!,Reference!#REF!,IF(C12=Reference!#REF!,Reference!#REF!,IF(Senior!C12=Reference!#REF!,Reference!#REF!,IF(Senior!C12=Reference!#REF!,Reference!#REF!,IF(C12=Reference!#REF!,Reference!#REF!,IF(C12=Reference!#REF!,Reference!#REF!,IF(C12=Reference!#REF!,Reference!#REF!,0))))))) -> #REF! | F11: 0.05 | G11: =E11*F11 -> #REF!
A12: 4 | B12: IT Experience | C12: 5~8yrs | D12: Ghi chính xác số năm kinh nghiệm trong lĩnh vực IT | G12: =E11*F12 -> #REF!
A13: 5 | B13: Working experience in Japan | C13: <1y | D13: Ghi chính xác số năm kinh nghiệm làm việc ở Nhật | E13: =IF(C13=Reference!#REF!,Reference!#REF!,IF(C13=Reference!#REF!,Reference!#REF!,IF(Senior!C13=Reference!#REF!,Reference!#REF!,IF(Senior!C13=Reference!#REF!,Reference!#REF!,IF(C13=Reference!#REF!,Reference!#REF!,IF(C13=Reference!#REF!,Reference!#REF!,IF(C13=Reference!#REF!,Reference!#REF!,0))))))) -> #REF! | F13: 0.05 | G13: =E13*F13 -> #REF!
A14: 6 | B14: Technical skill (Hardskill/ Professionals/ Experience/Techical Skills/ Process) | C14: Position | D14: Ghi rõ position đã làm, số năm kinh nghiệm. VD 3 năm code, 2 năm test UT, IT,ST, test design, 1 năm PM size 5 members, 1 năm Basic Design bằng tiếng Nhật, 1 năm Detail Design bằng tiếng Anh, 1 năm BA… Các nhận xét khác của interviewer | E14: =E16*10%+E17*50%+E18*20%+E19*20%+E20+E21 -> #REF! | F14: 0.35 | G14: =E14*F14 -> #REF!
C15: Programing Language | D15: Ghi rõ ngôn ngữ đã làm thật trong dự án và số năm kinh nghiệm. VD - Java: Dev3, 2 năm Java front end Springs, - dotNET: Dev2, 2 năm web - Python: Dev1 - Oracle làm nhiều, MySQL ít. Ghi rõ kinh nghiệm ở các domain, VD 3 năm Cobol dự án chứng khoán, 2 năm Qt dự án Car Navigation... Ghi rõ khả năng làm được BD, DD, bằng tiếng Nhật hay tiếng Anh, kinh nghiệm bao lâu Các nhận xét khác của interviewer
A16: 7 | B16: Job rank assessed by Interviewer | C16: Management - Job rank | D16: PM1 | E16: =VLOOKUP(D16,Reference!#REF!,2,0) -> #REF!
C17: BrSE- Job rank | D17: BrSE0 | E17: =VLOOKUP(D17,Reference!#REF!,2,0) -> #REF!
C18: SE/Dev/Test -Job rank | D18: Dev3 | E18: =VLOOKUP(D18,Reference!#REF!,2,0) -> #REF!
C19: BA/Comtor - Job rank | D19: BA1 | E19: =VLOOKUP(D19,Reference!#REF!,2,0) -> #REF!
C20: Writing Basic Design by Japanese | D20: 0 year | E20: =VLOOKUP(D20,Reference!#REF!,2,FALSE) -> #REF!
C21: Writing Detail Design by Japanese | D21: 0 year | E21: =VLOOKUP(D21,Reference!#REF!,2,FALSE) -> #REF!
A22: 8 | B22: Soft Skill | C22: Presentation/Communication Skills | D22: Ghi rõ nhận xét của interviewer. Thang điểm 10 | E22: 5 | F22: 0.03 | G22: =E22*F22 -> 0.15
C23: Learning Ability/Adaptable Ability | D23: Ghi rõ nhận xét của interviewer. Thang điểm 10 | E23: 5 | F23: 0.02 | G23: =E23*F23 -> 0.1
C24: Ability to handle pressure at work | D24: Ghi rõ nhận xét của interviewer. Thang điểm 10 | E24: 5 | F24: 0.02 | G24: =E24*F24 -> 0.1
A25: 9 | B25: Plus point | C25: Working location | D25: Làm việc ở vùng nào cũng được 10 điểm. Ghi rõ địa điểm có thể làm việc được | E25: 5 | F25: 0.03 | G25: =E25*F25 -> 0.15
C26: Experience of working in FSOFT | D26: Ghi rõ số năm và chi tiết kinh nghiệm làm việc tại FSOFT | E26: 5 | F26: 0.03 | G26: =E26*F26 -> 0.15
C27: Valuable skill | D27: Ghi rõ skil hiếm hoặc khó hoặc có mặt bằng lương cao mà ứng viên sở hữu. VD Python, Ruby, Machine Learning… | E27: 5 | F27: 0.02 | G27: =E27*F27 -> 0.1
A28: Total score | E28: =E6*F6+E7*F7+E8*F8+E9*F9+E10*F10+E11*F11+E13*F13+E14*F14+E22*F22+E23*F23+E24*F24+E25*F25+E26*F26+E27*F27 -> #REF! | F28: =SUM(F6:F27) -> 1
A29: Conclusion | E29: =IF(E28<5,"FAIL",IF(E28>6,"PASS","CONSIDER")) -> #REF!
A30: Reference Information
A31: 10 | B31: Current resident address | C31: Ghi rõ nơi ở hiện tại của ứng viên, vd Đà Nẵng, Nagoya…
A32: 11 | B32: Visa status | C32: Chú ý nếu UV không có bằng ĐH thì phải hỏi có chứng chỉ FE hoặc 10 năm kinh nghiệm IT không?
A33: 12 | B33: Start date | C33: Ngày ứng vien có thể bắt đầu làm việc nếu pass
A34: 13 | B34: Family status | C34: Tình trạng gia đình, vd vợ đang đi làm ở Hàn, 2 con ở VN với ông bà
A35: 14 | B35: Japanese moving expectation | C35: Mong muốn sang Nhật bao lâu, vd muốn sang Nhật 3 năm, vợ con vẫn ở VN hoặc muốn định cư cả gia đình tại Nhật…
A36: 15 | B36: Position exepectation | C36: Vị trí mong muốn, vd BrSE theo hướng có offshore hoặc SE focus vào kỹ thuật mới hoặc chỉ muốn làm trong lĩnh vực tài chính…
A37: 16 | B37: Mức lương mong muốn

Sheet Guideline
A1: Interview checklist template
A2: Overview | B2: Links
A3: Interview checklist template ,là phiếu đánh ghi lại toàn bộ quá trình phỏng vấn giữa ứng viên và interviewer, đánh giá năng lực ứng viên thông qua các thông tin đã được phỏng vấn, xếp năng lực ứng viên phù hợp với Job rank của Fsoft
A4: 1. Interview check list | B4: Click here
A5: Interview check list là các mục bắt buộc phải hỏi và đánh giá khi interviewer thực hiện cuộc phỏng vấn với ứng viên Information : Các thông tin cơ bản về ứng viên ( tên, trường,... job ứng tuyển, Rank...) - Applied Position : Vị trí ứng tuyển( DEV, Test, BA...) interviewer lựachọn trong Box bên cạnh - Job level : Rank 1, Rank 2, Rank 3… tương đương phân loại rank ứng viền ( Ví dụ : ứng viên ứng tuyển rank DEV, Rank 1 => DEV1 Interview Evaluation: Đánh giá cho điểm theo trọng số và xếp job rank cho ứng, kết quả chốt Pass/ fail/ consider - Rate : Trọng số theo quy định công ty - Score : Thang điểm 1 - 10 , interview cho điểm ứng viên theo thang điểm này - Language : Chọn trong Box hiển thị ngôn ngữ cần đánh giá - Please select certification : liệt kê các chứng chỉ và các giải thưởng nếu có - Techical skill : phỏng vấn theo cấu trúc từ dễ đến khó ( must have , Nice Have ) theo từng domain - Job rank assesed : xếp loại ứng viên tương ứng phù hợp với RAnk của Fsoft (( ví dụ DEV1, DEv2...) - Total score : điểm sẽ tự động và xếp loại pass/fail/consider - Interviewer cần bổ sung mô tả cho từng mục để giải thích kết quả đánh giá.
A6: Reference information
A7: - Salary expectation : Câu hỏi dành riêng cho FWA - Các Câu hỏi còn lại Interviewer phỏng vấn
A8: 2. Techinterview Interviewer ghi lại câu hỏi và trả lời của ứng viên trong quá trình phỏng vấn (không áp dụng cho BA) | B8: Click here
A9: 3.InterviewBank Ngân hàng câu hỏi cho interviewer tham khảo | B9: Click here

Sheet InterviewCheckList
A1: Anh, chị Interviewer vui lòng fill thông tin vào các ô màu xanh lá cây theo Thang điểm 10
A2: INTERVIEW CHECK LIST
A3: Information
A4: Applied Position | H4: BA | Q4: Interview Unit | AA4: FHM | AE4: AKAT
A5: Job level | H5: senior | Q5: Interviewer | AA5: REC to help fill in in advance.
A6: Candidate | H6: REC to help fill in in advance. | Q6: Interview Date | AA6: 0.625
AA7: 45078
A8: Education | H8: REC to help fill in in advance. | Q8: Major: REC to help fill in in advance. | AA8: Graduated scores | AG8: Please select graduated rank
H9: REC to help fill in in advance. | Q9: Major: REC to help fill in in advance. | AA9: Graduated scores | AG9: REC to help fill in in advance.
A10: Interview Evaluation
A11: # | B11: Category | H11: Sub-category | Q11: Description | AI11: Rate | AM11: Proficiency
A12: 1 | B12: Previous companies | H12: REC to help fill in in advance. | Q12: REC to help fill in in advance.
H13: REC to help fill in in advance. | Q13: REC to help fill in in advance. | AQ13: Question
A14: 2 | B14: Experiences | H14: Applied Position Experience | Q14: Ghi chính xác số năm kinh nghiệm với applied position | Z14: 5 năm kinh nghiệm làm BA trong ngân hàng, với hệ thống core, thanh toán, thẻ | AI14: 0.02 | AM14: Advanced | AP14: =AI14*VLOOKUP(InterviewCheckList!AM14,Reference!$B$2:$C$7,2,0) -> 0.08 | AQ14: Please introduce yourself
A15: 3 | B15: BA Knowledge | H15: BA Planning & Monitoring | Q15: Basic Skill: Break down task of BA and plan by excel/mpp. Monitor daily progress, know how to handle risk/issue. Advanced Skill: Define appropriate approach for different types of projects & proper deliverables. | Z15: Nắm được full lifecycle software development. Có kinh nghiệm thực tế với SDLC. Tuy nhiên output của BA ở eliciate chưa rõ ràng. Chưa nêu được giai đoạn project definition | AI15: 0.08 | AM15: Advanced | AP15: =AI15*VLOOKUP(InterviewCheckList!AM15,Reference!$B$2:$C$7,2,0) -> 0.32 | AQ15: Can you list down all the phases for a Software Development Lifecyle? And what is the goal or output of BA for each phase?
H16: Elicitation & Collaboration | Q16: Basic Skill: Elicitate requirement via document/existing system analysis, simple interview Intermediate: Requirement Workshop. Advanced: Research, Experiment, Feasibility Study. | Z16: Bạn biết cách elicit yêu cầu từ stakeholder bằng các phương pháp: Interview, workshop, document và survey. Phần lớn kinh nghiệm là interview với khách hàng, scope vừa và nhỏ Chưa có kinh nghiệm về quan sát và benchmark các hệ thống. Có kinh nghiệm tham gia workshop chứ chưa đứng ra tổ chức workshop | AI16: 0.1 | AM16: Advanced | AP16: =AI16*VLOOKUP(InterviewCheckList!AM16,Reference!$B$2:$C$7,2,0) -> 0.4 | AQ16: I see you got CBAP certificate, how many kinds of requirements that you know? Business requirement Can you show me some skills or method applied in eliciation phase? How would you organize a workshop? - Interview - Workshop - Benchmark - Observation - Survey - Document analysis
H17: Requirement Analysis & Design Definition | Q17: Basic: Know different ways to define and document requirement at detailed level: use case or user story. Advanced: Know to define requirement architect suitable for each types of project and review the requirement to make sure it aligns with project's goal. | Z17: Cách giải quyết vấn đề khi gặp người không chịu chia sẻ: Tốt. Tìm hiểu trực tiếp hệ thống, tìm hiểu từ databse, hỏi người kinh nghiệm | AI17: 0.1 | AM17: Advanced | AP17: =AI17*VLOOKUP(InterviewCheckList!AM17,Reference!$B$2:$C$7,2,0) -> 0.4 | AQ17: You show that you understand needs and elicit the requirements from PO. Can you give me an example? Did you face any diffuculty at that moment and how do you overcome it? | AR17: Human abundant opporrtunity and don’t want to share => investigate Ask other expirence people
H18: Requirement Life Cycle Management | Q18: Understand requirement life cycle (traceability, prioritization, approval, maintenance, reuseability) (profieciency level depends on how much knowledge and experience they have in above items). | Z18: Interviewer to fill in details of assessment…. | AI18: 0.1 | AM18: Intermediate | AP18: =AI18*VLOOKUP(InterviewCheckList!AM18,Reference!$B$2:$C$7,2,0) -> 0.3
H19: Solution Evaluation | Q19: Basic: know how to conduct User Acceptance Test. Advanced: know how to perform different testing/evaluation to improve product value and define the improvement for the system. | Z19: Interviewer to fill in details of assessment…. | AI19: 0.08 | AM19: Advanced | AP19: =AI19*VLOOKUP(InterviewCheckList!AM19,Reference!$B$2:$C$7,2,0) -> 0.32
H20: Strategy Analysis | Q20: Have knowledge and experience in current & future state analysis, gap analysis, risk assessment and overall change strategy. (should be at enterprise level, not project level) | Z20: Interviewer to fill in details of assessment…. | AI20: 0.08 | AM20: Intermediate | AP20: =AI20*VLOOKUP(InterviewCheckList!AM20,Reference!$B$2:$C$7,2,0) -> 0.24
A21: 4 | B21: Domain Knowledge | H21: Domain Knowledge Understanding | Q21: Assessment based on: - Number of experience in the corresponding domain. - Certificate. - Direct discussion. | Z21: Có kinh nghiệm thực tế, hiểu về các hoạt động của bank | AI21: 0.1 | AM21: Advanced | AP21: =AI21*VLOOKUP(InterviewCheckList!AM21,Reference!$B$2:$C$7,2,0) -> 0.4 | AQ21: Can you list down some operations that a customer do with the bank?
A22: 5 | B22: Technical Understanding | H22: General Technical Understanding | Q22: Have fundamental IT knowledge: database structure, one programming language, application structure, API. | Z22: Câu hỏi về các hệ thống nội bộ: có nêu được nhưng chưa khái quát được Câu hỏi về thanh toán thẻ: trả lời tốt, đúng mong đợi Câu hỏi nâng cao về API: chưa tốt, chưa từng làm tài liệu về API | AI22: 0.03 | AM22: Advanced | AP22: =AI22*VLOOKUP(InterviewCheckList!AM22,Reference!$B$2:$C$7,2,0) -> 0.12 | AQ22: Can you name some internal system of a digital banking? - Operation - Management system - Sales and marketing - Customer service? | AR22: 1. Please describe a transaction by debit or credit card at a POS. How many stakeholders are involved in that transaction? 2. In case of the bank want to deploy a POS on a Supermarket - How many method of payment can be applied? - How many kinds of document you should provide to stakeholders? Can you give me the structure of one kind of them? | AS22: If the bank want to integrate with a third party payment service, how do you describe the API specification?
H23: Platform Understanding | Q23: Have knowledge on 1 platform on business analyst perspective (understand functionality supported, know how to configure, know limitation), for example: SharePoint, Microsoft Dynamic, a main module of ERP. | Z23: Có kinh nghiệm về BPN - business management process Có kinh nghiệm về hệ thống thẻ Có kinh nghiệm về hệ thống core banking | AI23: 0.03 | AM23: Advanced | AP23: =AI23*VLOOKUP(InterviewCheckList!AM23,Reference!$B$2:$C$7,2,0) -> 0.12
A24: 6 | B24: Management Skill | H24: Team Management | Q24: Have experience in building a team (recruitment, managing career path, training…) | Z24: Interviewer to fill in details of assessment…. | AI24: 0.08 | AM24: Fundamental awareness | AP24: =AI24*VLOOKUP(InterviewCheckList!AM24,Reference!$B$2:$C$7,2,0) -> 0.08
A25: 7 | B25: Soft skill | H25: Analytical Thinking | Q25: Depending on how interviewees respond to questions of interviewer in simulation/exploring past experience. (whether they understand the issue properly and give a related solution) | Z25: Một vài câu hỏi cần gợi ý (interview mong muốn ứng viên chủ động làm rõ câu hỏi bằng cách đặt câu hỏi ngược lại hơn là để interviewer giải thích) | AI25: 0.04 | AM25: 3 | AP25: =AM25*AI25 -> 0.12
H26: Communication Skill | Q26: Depending on how interviewees communicate. | Z26: Interviewer to fill in details of assessment…. | AI26: 0.04 | AM26: 3 | AP26: =AM26*AI26 -> 0.12
H27: Other Skill | Q27: This can be changed based on specific position or bonus point for strong skill of candidate. | Z27: Interviewer to fill in details of assessment…. | AI27: 0.03 | AM27: 4 | AP27: =AM27*AI27 -> 0.12
A28: 8 | B28: Language | H28: English/Japanese | Q28: Listening | Z28: Interviewer to fill in details of assessment…. | AI28: 0.02 | AM28: Intermediate/N3 | AP28: =AI28*VLOOKUP(InterviewCheckList!AM28,Reference!$D$2:$E$7,2,0) -> 0.06
Q29: Writing: | Z29: Interviewer to fill in details of assessment…. | AI29: 0.02 | AM29: Intermediate/N3 | AP29: =AI29*VLOOKUP(InterviewCheckList!AM29,Reference!$D$2:$E$7,2,0) -> 0.06
Q30: Reading: | Z30: Interviewer to fill in details of assessment…. | AI30: 0.02 | AM30: Intermediate/N3 | AP30: =AI30*VLOOKUP(InterviewCheckList!AM30,Reference!$D$2:$E$7,2,0) -> 0.06
Q31: Speaking | Z31: Interviewer to fill in details of assessment…. | AI31: 0.02 | AM31: Intermediate/N3 | AP31: =AI31*VLOOKUP(InterviewCheckList!AM31,Reference!$D$2:$E$7,2,0) -> 0.06
A32: 9 | B32: Certifications | H32: Please select certification | Q32: Liệt kê thành tích và chứng chỉ nếu có: | Z32: CBAP - chứng chỉ chuyên ngành của BA | AI32: 0.01 | AM32: Yes | AP32: =IF( AM32="Yes",1,0)*AI32 -> 0.01
A33: Total score | AI33: =SUM(AP15:AP32) -> 3.31
A34: Conclusion | AI34: =IF(AI33>4.4,"BA06",IF(AI33>4,"BA05",IF(AI33>3.4,"BA04",IF(AI33>2.5,"BA03",IF(AI33>1.6,"BA02","BA01"))))) -> BA03 | AJ34: =IF(AJ33>5.4,"DEV06",IF(AJ33>5.1,"DEV05",IF(AJ33>4,"DEV04",IF(AJ33>3,"DEV03",IF(AJ33>2.5,"DEV02","F"))))) -> F | AK34: =IF(AK33>5.4,"DEV06",IF(AK33>5.1,"DEV05",IF(AK33>4,"DEV04",IF(AK33>3,"DEV03",IF(AK33>2.5,"DEV02","F"))))) -> F | AL34: =IF(AL33>5.4,"DEV06",IF(AL33>5.1,"DEV05",IF(AL33>4,"DEV04",IF(AL33>3,"DEV03",IF(AL33>2.5,"DEV02","F"))))) -> F | AM34: =IF(AM33>5.4,"DEV06",IF(AM33>5.1,"DEV05",IF(AM33>4,"DEV04",IF(AM33>3,"DEV03",IF(AM33>2.5,"DEV02","F"))))) -> F | AN34: =IF(AN33>5.4,"DEV06",IF(AN33>5.1,"DEV05",IF(AN33>4,"DEV04",IF(AN33>3,"DEV03",IF(AN33>2.5,"DEV02","F"))))) -> F | AO34: =IF(AO33>5.4,"DEV06",IF(AO33>5.1,"DEV05",IF(AO33>4,"DEV04",IF(AO33>3,"DEV03",IF(AO33>2.5,"DEV02","F"))))) -> F
A35: Reference information
A36: 10 | B36: Start date | H36: REC/Interviewer to fill in.
A37: 11 | B37: Position expectation | H37: REC fill in in advance
A38: 12 | B38: Candidate concern | H38: REC/Interviewer to fill in.
A39: 13 | B39: Current resident address | H39: REC fill in in advance
A40: 14 | B40: Family status | H40: REC fill in in advance
...

Sheet Sheet2
A1: Question set for BA skill.
A2: Soft skill can be subjective.

Sheet Interview Bank
A1: No | B1: Job Rank | C1: General Question | D1: Answer | E1: Hint/Answer
A2: 1 | B2: All | C2: General Question | D2: What's your marriage status?
A3: 2 | B3: All | C3: General Question | D3: Why do you leave your previous/current company?
A4: 3 | B4: All | C4: General Question | D4: Điều gì có thể motivate được team member tốt nhất?
A5: 4 | B5: All | C5: General Question | D5: Điều gì có thể giúp member làm việc với performance tốt nhất?
A6: 5 | B6: All | C6: General Question | D6: How much do you know about BA job?
A7: 6 | B7: All | C7: General Question | D7: Please share with me/us about your BA experience.
A8: 7 | B8: All | C8: Presentation | D8: Please describe a system that you have joined in the requirement phase as a BA.
A9: 8 | B9: All | C9: General Question | D9: What's your opinion about working overtime?
A10: 9 | B10: All | C10: General Question | D10: What do you think about working under high pressure? How much of work is high pressure with you?
A11: 10 | B11: All | C11: General Question | D11: As a BA, we might need to travel to get the requirement, is it a problem with you?
A12: 11 | B12: All | C12: General Question | D12: Could you share with us/me about your hobby?
A13: 12 | B13: All | C13: General Question | D13: If you want to be a BA, what have you done to achieve your target?
... A16: 15 | B16: All | C16: General Question | D16: With your current skills, what do you think you should improve in order to work better as a BA?
A17: 16 | B17: BA 1 | C17: BA Skill Basic | D17: How many BA product that you know? | E17: SRS/BD/Function Spec, AVF, UM
A18: 17 | B18: BA 3 | C18: Requirement Gathering | D18: Which information do you have in the SRS document? / Which information do you need to describe a system? | E18: asking about SRS outline
A19: 18 | B19: BA 1 | C19: BA Skill Basic | D19: Do you know about UML? | E19: Unified Modeling Language
A20: 19 | B20: BA 1 | C20: BA Skill Basic | D20: What's UC/User story? Please give me an example of UC/US. | E20: definition/purpose, information that need to have
A21: 20 | B21: BA 1 | C21: BA Skill Basic | D21: What's the meaning of actor?
A22: 21 | B22: BA 1 | C22: BA Skill Basic | D22: How many type of actor do you know?
A23: 22 | B23: BA 1 | C23: BA Skill Basic | D23: How many scenario path of an use case? | E23: happy/alternative/exception path
A24: 23 | B24: BA 1 | C24: BA Skill Basic | D24: What's the application workflow?
A25: 24 | B25: BA 1 | C25: BA Skill Basic | D25: Do you know about UC diagram? Which object do we need to have in an UC diagram? | E25: actor, uc
A26: 25 | B26: BA 1 | C26: BA Skill Basic | D26: What's the rule we should follow to have a good UC diagram?
A27: 26 | B27: BA 1 | C27: BA Skill Basic | D27: How do you describe a screen? Please provide an example?
A28: 27 | B28: BA 1 | C28: BA Skill Basic | D28: Please give me some example of common validation rule in a screen.
A29: 28 | B29: BA 1 | C29: BA Skill Basic | D29: What's the functional and non-functional requirement?
A30: 29 | B30: All | C30: Technical | D30: Please share with me/us about your technical background
A31: 30 | B31: All | C31: Technical | D31: Do you know anything about database management system such as SQL/Oracle?
A32: 31 | B32: BA 2 | C32: Requirement Workshop | D32: Please share with us the way to setup a requirement workshop
A33: 32 | B33: BA 2 | C33: Requirement Workshop | D33: How often do you think is the best to setup a meeting with customer?
A34: 33 | B34: BA 2 | C34: Stakeholder Interview | D34: Please share with us the way to do customer interview.
A35: 34 | B35: BA 2 | C35: Simulation | D35: Please ask me to get the requirement for archive functions.
A36: 35 | B36: BA 2 | C36: Requirement Planning | D36: Please explain the way you make the requirement plan.
A37: 36 | B37: BA 2 | C37: Requirement Planning | D37: What's the purpose of requirement plan?
... A48: 47 | B48: BA 3 | C48: Requirement Planning | D48: How to priority requirement? Which criteria will be used?
A49: 48 | B49: BA 3 | C49: Requirement Planning and Monitoring | D49: When you making a requirement plan for your BA team, how will you assign task for your member? | E49: assign depend of member skill
A50: 49 | B50: BA 3 | C50: Requirement Planning | D50: After making a plan and you feel that with the current number of resources you cannot achieve the deadline, how will you do?
A51: 50 | B51: BA 3 | C51: Requirement Management | D51: What's the requirement information?
A52: 51 | B52: BA 3 | C52: Requirement Management | D52: Which information do you use for managing requirement information?
...

Sheet Reference
A1: Technical | D1: English/Japanese | F1: Tính điểm
B2: No knowledge/experience | C2: 0 | D2: No knowledge | E2: 0
B3: Fundamental awareness | C3: 1 | D3: Fundamental/N5 | E3: 1
B4: Limited Experience | C4: 2 | D4: Limited/N4 | E4: 2
B5: Intermediate | C5: 3 | D5: Intermediate/N3 | E5: 3
B6: Advanced | C6: 4 | D6: Advanced/N2 | E6: 4
B7: Expert | C7: 5 | D7: Fluently/N1 | E7: 5
