Workbook

Sheet PHƯƠNG
A1: 2024
A2: SUM của Số tiền | B2: Tháng
A3: Báo cáo dòng tiền | B3: =$A$1&"."&"01" -> 2024.01 | C3: =$A$1&"."&"02" -> 2024.02 | D3: =$A$1&"."&"03" -> 2024.03 | F3: =$A$1&"."&"04" -> 2024.04 | G3: =$A$1&"."&"05" -> 2024.05 | H3: =$A$1&"."&"06" -> 2024.06 | I3: =$A$1&"."&"07" -> 2024.07 | J3: =$A$1&"."&"08" -> 2024.08 | K3: =$A$1&"."&"09" -> 2024.09 | L3: =$A$1&"."&"10" -> 2024.10 | M3: =$A$1&"."&"11" -> 2024.11 | N3: =$A$1&"."&"12" -> 2024.12 | O3: Tổng
A4: Biến phí | B4: =vlookup(B3,#REF!,2,0) -> #REF! | C4: =vlookup(C3,#REF!,2,0) -> #REF! | D4: =vlookup(D3,#REF!,2,0) -> #REF! | F4: =vlookup(F3,#REF!,2,0) -> #REF! | G4: =vlookup(G3,#REF!,2,0) -> #REF! | H4: =vlookup(H3,#REF!,2,0) -> #REF! | I4: =vlookup(I3,#REF!,2,0) -> #REF! | J4: =vlookup(J3,#REF!,2,0) -> #REF! | K4: =vlookup(K3,#REF!,2,0) -> #REF! | L4: =vlookup(L3,#REF!,2,0) -> #REF! | M4: =vlookup(M3,#REF!,2,0) -> #REF! | N4: =vlookup(N3,#REF!,2,0) -> #REF! | O4: 950042901
A5: Chi phí khác | B5: =vlookup(B3,#REF!,3,0) -> #REF! | C5: =vlookup(C3,#REF!,3,0) -> #REF! | D5: =vlookup(D3,#REF!,3,0) -> #REF! | F5: =vlookup(F3,#REF!,3,0) -> #REF! | G5: =vlookup(G3,#REF!,3,0) -> #REF! | H5: =vlookup(H3,#REF!,3,0) -> #REF! | I5: =vlookup(I3,#REF!,3,0) -> #REF! | J5: =vlookup(J3,#REF!,3,0) -> #REF! | K5: =vlookup(K3,#REF!,3,0) -> #REF! | L5: =vlookup(L3,#REF!,3,0) -> #REF! | M5: =vlookup(M3,#REF!,3,0) -> #REF! | N5: =vlookup(N3,#REF!,3,0) -> #REF! | O5: 119364240
A6: Định phí | B6: =vlookup(B3,#REF!,4,0) -> #REF! | C6: =vlookup(C3,#REF!,4,0) -> #REF! | D6: =vlookup(D3,#REF!,4,0) -> #REF! | F6: =vlookup(F3,#REF!,4,0) -> #REF! | G6: =vlookup(G3,#REF!,4,0) -> #REF! | H6: =vlookup(H3,#REF!,4,0) -> #REF! | I6: =vlookup(I3,#REF!,4,0) -> #REF! | J6: =vlookup(J3,#REF!,4,0) -> #REF! | K6: =vlookup(K3,#REF!,4,0) -> #REF! | L6: =vlookup(L3,#REF!,4,0) -> #REF! | M6: =vlookup(M3,#REF!,4,0) -> #REF! | N6: =vlookup(N3,#REF!,4,0) -> #REF! | O6: 1223293543
A7: Giá vốn | B7: =vlookup(B3,#REF!,5,0) -> #REF! | C7: =vlookup(C3,#REF!,5,0) -> #REF! | D7: =vlookup(D3,#REF!,5,0) -> #REF! | F7: =vlookup(F3,#REF!,5,0) -> #REF! | G7: =vlookup(G3,#REF!,5,0) -> #REF! | H7: =vlookup(H3,#REF!,5,0) -> #REF! | I7: =vlookup(I3,#REF!,5,0) -> #REF! | J7: =vlookup(J3,#REF!,5,0) -> #REF! | K7: =vlookup(K3,#REF!,5,0) -> #REF! | L7: =vlookup(L3,#REF!,5,0) -> #REF! | M7: =vlookup(M3,#REF!,5,0) -> #REF! | N7: =vlookup(N3,#REF!,5,0) -> #REF! | O7: 1855790333
A8: Hành chính | B8: =vlookup(B3,#REF!,6,0) -> #REF! | C8: =vlookup(C3,#REF!,6,0) -> #REF! | D8: =vlookup(D3,#REF!,6,0) -> #REF! | F8: =vlookup(F3,#REF!,6,0) -> #REF! | G8: =vlookup(G3,#REF!,6,0) -> #REF! | H8: =vlookup(H3,#REF!,6,0) -> #REF! | I8: =vlookup(I3,#REF!,6,0) -> #REF! | J8: =vlookup(J3,#REF!,6,0) -> #REF! | K8: =vlookup(K3,#REF!,6,0) -> #REF! | L8: =vlookup(L3,#REF!,6,0) -> #REF! | M8: =vlookup(M3,#REF!,6,0) -> #REF! | N8: =vlookup(N3,#REF!,6,0) -> #REF! | O8: 252733853
A9: Marketing | B9: =vlookup(B3,#REF!,7,0) -> #REF! | C9: =vlookup(C3,#REF!,7,0) -> #REF! | D9: =vlookup(D3,#REF!,7,0) -> #REF! | F9: =vlookup(F3,#REF!,7,0) -> #REF! | G9: =vlookup(G3,#REF!,7,0) -> #REF! | H9: =vlookup(H3,#REF!,7,0) -> #REF! | I9: =vlookup(I3,#REF!,7,0) -> #REF! | J9: =vlookup(J3,#REF!,7,0) -> #REF! | K9: =vlookup(K3,#REF!,7,0) -> #REF! | L9: =vlookup(L3,#REF!,7,0) -> #REF! | M9: =vlookup(M3,#REF!,7,0) -> #REF! | N9: =vlookup(N3,#REF!,7,0) -> #REF! | O9: 1855109996
A10: Tài sản | B10: =vlookup(B3,#REF!,8,0) -> #REF! | C10: =vlookup(C3,#REF!,8,0) -> #REF! | D10: =vlookup(D3,#REF!,8,0) -> #REF! | F10: =vlookup(F3,#REF!,8,0) -> #REF! | G10: =vlookup(G3,#REF!,8,0) -> #REF! | H10: =vlookup(H3,#REF!,8,0) -> #REF! | I10: =vlookup(I3,#REF!,8,0) -> #REF! | J10: =vlookup(J3,#REF!,8,0) -> #REF! | K10: =vlookup(K3,#REF!,8,0) -> #REF! | L10: =vlookup(L3,#REF!,8,0) -> #REF! | M10: =vlookup(M3,#REF!,8,0) -> #REF! | N10: =vlookup(N3,#REF!,8,0) -> #REF! | O10: 141458334
A11: Tổng cộng | B11: 2826933299 | C11: 1704981149 | D11: 1865878752 | F11: 0 | G11: 0 | H11: 0 | I11: 0 | J11: 0 | K11: 0 | L11: 0 | M11: 0 | N11: 0 | O11: 6397793200
A13: Định phí | B13: =$A$1&"."&"01" -> 2024.01 | C13: =$A$1&"."&"02" -> 2024.02 | D13: =$A$1&"."&"03" -> 2024.03 | F13: =$A$1&"."&"04" -> 2024.04 | G13: =$A$1&"."&"05" -> 2024.05 | H13: =$A$1&"."&"06" -> 2024.06 | I13: =$A$1&"."&"07" -> 2024.07 | J13: =$A$1&"."&"08" -> 2024.08 | K13: =$A$1&"."&"09" -> 2024.09 | L13: =$A$1&"."&"10" -> 2024.10 | M13: =$A$1&"."&"11" -> 2024.11 | N13: =$A$1&"."&"12" -> 2024.12 | O13: Tổng
A14: [Định phí]. Lương cứng | B14: =vlookup(B13,'Report_Chi phi'!$A$3:$P$51,4,0) -> #N/A | C14: =vlookup(C13,'Report_Chi phi'!$A$3:$P$51,4,0) -> #N/A | D14: =vlookup(D13,'Report_Chi phi'!$A$3:$P$51,4,0) -> #N/A | F14: =vlookup(F13,'Report_Chi phi'!$A$3:$P$51,4,0) -> #N/A | G14: =vlookup(G13,'Report_Chi phi'!$A$3:$P$51,4,0) -> #N/A | H14: =vlookup(H13,'Report_Chi phi'!$A$3:$P$51,4,0) -> #N/A | I14: =vlookup(I13,'Report_Chi phi'!$A$3:$P$51,4,0) -> #N/A | J14: =vlookup(J13,'Report_Chi phi'!$A$3:$P$51,4,0) -> #N/A | K14: =vlookup(K13,'Report_Chi phi'!$A$3:$P$51,4,0) -> #N/A | L14: =vlookup(L13,'Report_Chi phi'!$A$3:$P$51,4,0) -> #N/A | M14: =vlookup(M13,'Report_Chi phi'!$A$3:$P$51,4,0) -> #N/A | N14: =vlookup(N13,'Report_Chi phi'!$A$3:$P$51,4,0) -> #N/A | O14: =sum(B14:N14) -> #N/A
A15: [Định phí]. Mặt bằng | B15: =vlookup(B13,'Report_Chi phi'!$A$3:$P$51,5,0) -> #N/A | C15: =vlookup(C13,'Report_Chi phi'!$A$3:$P$51,5,0) -> #N/A | D15: =vlookup(D13,'Report_Chi phi'!$A$3:$P$51,5,0) -> #N/A | F15: =vlookup(F13,'Report_Chi phi'!$A$3:$P$51,5,0) -> #N/A | G15: =vlookup(G13,'Report_Chi phi'!$A$3:$P$51,5,0) -> #N/A | H15: =vlookup(H13,'Report_Chi phi'!$A$3:$P$51,5,0) -> #N/A | I15: =vlookup(I13,'Report_Chi phi'!$A$3:$P$51,5,0) -> #N/A | J15: =vlookup(J13,'Report_Chi phi'!$A$3:$P$51,5,0) -> #N/A | K15: =vlookup(K13,'Report_Chi phi'!$A$3:$P$51,5,0) -> #N/A | L15: =vlookup(L13,'Report_Chi phi'!$A$3:$P$51,5,0) -> #N/A | M15: =vlookup(M13,'Report_Chi phi'!$A$3:$P$51,5,0) -> #N/A | N15: =vlookup(N13,'Report_Chi phi'!$A$3:$P$51,5,0) -> #N/A | O15: =sum(B15:N15) -> #N/A
A16: [Định phí]. Thuê bằng | B16: =vlookup(B13,'Report_Chi phi'!$A$3:$P$51,6,0) -> #N/A | C16: =vlookup(C13,'Report_Chi phi'!$A$3:$P$51,6,0) -> #N/A | D16: =vlookup(D13,'Report_Chi phi'!$A$3:$P$51,6,0) -> #N/A | F16: =vlookup(F13,'Report_Chi phi'!$A$3:$P$51,6,0) -> #N/A | G16: =vlookup(G13,'Report_Chi phi'!$A$3:$P$51,6,0) -> #N/A | H16: =vlookup(H13,'Report_Chi phi'!$A$3:$P$51,6,0) -> #N/A | I16: =vlookup(I13,'Report_Chi phi'!$A$3:$P$51,6,0) -> #N/A | J16: =vlookup(J13,'Report_Chi phi'!$A$3:$P$51,6,0) -> #N/A | K16: =vlookup(K13,'Report_Chi phi'!$A$3:$P$51,6,0) -> #N/A | L16: =vlookup(L13,'Report_Chi phi'!$A$3:$P$51,6,0) -> #N/A | M16: =vlookup(M13,'Report_Chi phi'!$A$3:$P$51,6,0) -> #N/A | N16: =vlookup(N13,'Report_Chi phi'!$A$3:$P$51,6,0) -> #N/A | O16: =sum(B16:N16) -> #N/A
A17: [Định phí]. Bảo hiểm | B17: =vlookup(B13,'Report_Chi phi'!$A$3:$P$51,3,0) -> #N/A | C17: =vlookup(C13,'Report_Chi phi'!$A$3:$P$51,3,0) -> #N/A | D17: =vlookup(D13,'Report_Chi phi'!$A$3:$P$51,3,0) -> #N/A | F17: =vlookup(F13,'Report_Chi phi'!$A$3:$P$51,3,0) -> #N/A | G17: =vlookup(G13,'Report_Chi phi'!$A$3:$P$51,3,0) -> #N/A | H17: =vlookup(H13,'Report_Chi phi'!$A$3:$P$51,3,0) -> #N/A | I17: =vlookup(I13,'Report_Chi phi'!$A$3:$P$51,3,0) -> #N/A | J17: =vlookup(J13,'Report_Chi phi'!$A$3:$P$51,3,0) -> #N/A | K17: =vlookup(K13,'Report_Chi phi'!$A$3:$P$51,3,0) -> #N/A | L17: =vlookup(L13,'Report_Chi phi'!$A$3:$P$51,3,0) -> #N/A | M17: =vlookup(M13,'Report_Chi phi'!$A$3:$P$51,3,0) -> #N/A | N17: =vlookup(N13,'Report_Chi phi'!$A$3:$P$51,3,0) -> #N/A | O17: =sum(B17:N17) -> #N/A
O18: =sum(B18:N18) -> 0
A19: Biến phí | B19: =$A$1&"."&"01" -> 2024.01 | C19: =$A$1&"."&"02" -> 2024.02 | D19: =$A$1&"."&"03" -> 2024.03 | F19: =$A$1&"."&"04" -> 2024.04 | G19: =$A$1&"."&"05" -> 2024.05 | H19: =$A$1&"."&"06" -> 2024.06 | I19: =$A$1&"."&"07" -> 2024.07 | J19: =$A$1&"."&"08" -> 2024.08 | K19: =$A$1&"."&"09" -> 2024.09 | L19: =$A$1&"."&"10" -> 2024.10 | M19: =$A$1&"."&"11" -> 2024.11 | N19: =$A$1&"."&"12" -> 2024.12 | O19: Tổng
A20: [Bán hàng]. Marketing | B20: =vlookup(B19,'Report_Chi phi'!$A$3:$P$51,2,0) -> #N/A | C20: =vlookup(C19,'Report_Chi phi'!$A$3:$P$51,2,0) -> #N/A | D20: =vlookup(D19,'Report_Chi phi'!$A$3:$P$51,2,0) -> #N/A | F20: =vlookup(F19,'Report_Chi phi'!$A$3:$P$51,2,0) -> #N/A | G20: =vlookup(G19,'Report_Chi phi'!$A$3:$P$51,2,0) -> #N/A | H20: =vlookup(H19,'Report_Chi phi'!$A$3:$P$51,2,0) -> #N/A | I20: =vlookup(I19,'Report_Chi phi'!$A$3:$P$51,2,0) -> #N/A | J20: =vlookup(J19,'Report_Chi phi'!$A$3:$P$51,2,0) -> #N/A | K20: =vlookup(K19,'Report_Chi phi'!$A$3:$P$51,2,0) -> #N/A | L20: =vlookup(L19,'Report_Chi phi'!$A$3:$P$51,2,0) -> #N/A | M20: =vlookup(M19,'Report_Chi phi'!$A$3:$P$51,2,0) -> #N/A | N20: =vlookup(N19,'Report_Chi phi'!$A$3:$P$51,2,0) -> #N/A | O20: =sum(B20:N20) -> #N/A
A21: KPI | B21: =vlookup(B19,'Report_Chi phi'!$A$3:$P$51,15,0) -> #N/A | C21: =vlookup(C19,'Report_Chi phi'!$A$3:$P$51,15,0) -> #N/A | D21: =vlookup(D19,'Report_Chi phi'!$A$3:$P$51,15,0) -> #N/A | F21: =vlookup(F19,'Report_Chi phi'!$A$3:$P$51,15,0) -> #N/A | G21: =vlookup(G19,'Report_Chi phi'!$A$3:$P$51,15,0) -> #N/A | H21: =vlookup(H19,'Report_Chi phi'!$A$3:$P$51,15,0) -> #N/A | I21: =vlookup(I19,'Report_Chi phi'!$A$3:$P$51,15,0) -> #N/A | J21: =vlookup(J19,'Report_Chi phi'!$A$3:$P$51,15,0) -> #N/A | K21: =vlookup(K19,'Report_Chi phi'!$A$3:$P$51,15,0) -> #N/A | L21: =vlookup(L19,'Report_Chi phi'!$A$3:$P$51,15,0) -> #N/A | M21: =vlookup(M19,'Report_Chi phi'!$A$3:$P$51,15,0) -> #N/A | N21: =vlookup(N19,'Report_Chi phi'!$A$3:$P$51,15,0) -> #N/A | O21: =sum(B21:N21) -> #N/A
A22: Giá vốn | B22: =$A$1&"."&"01" -> 2024.01 | C22: =$A$1&"."&"02" -> 2024.02 | D22: =$A$1&"."&"03" -> 2024.03 | F22: =$A$1&"."&"04" -> 2024.04 | G22: =$A$1&"."&"05" -> 2024.05 | H22: =$A$1&"."&"06" -> 2024.06 | I22: =$A$1&"."&"07" -> 2024.07 | J22: =$A$1&"."&"08" -> 2024.08 | K22: =$A$1&"."&"09" -> 2024.09 | L22: =$A$1&"."&"10" -> 2024.10 | M22: =$A$1&"."&"11" -> 2024.11 | N22: =$A$1&"."&"12" -> 2024.12 | O22: Tổng
A23: [Giá vốn]. Vật liệu | B23: =vlookup(B22,'Report_Chi phi'!$A$3:$P$51,8,0) -> #N/A | C23: =vlookup(C22,'Report_Chi phi'!$A$3:$P$51,8,0) -> #N/A | D23: =vlookup(D22,'Report_Chi phi'!$A$3:$P$51,8,0) -> #N/A | F23: =vlookup(F22,'Report_Chi phi'!$A$3:$P$51,8,0) -> #N/A | G23: =vlookup(G22,'Report_Chi phi'!$A$3:$P$51,8,0) -> #N/A | H23: =vlookup(H22,'Report_Chi phi'!$A$3:$P$51,8,0) -> #N/A | I23: =vlookup(I22,'Report_Chi phi'!$A$3:$P$51,8,0) -> #N/A | J23: =vlookup(J22,'Report_Chi phi'!$A$3:$P$51,8,0) -> #N/A | K23: =vlookup(K22,'Report_Chi phi'!$A$3:$P$51,8,0) -> #N/A | L23: =vlookup(L22,'Report_Chi phi'!$A$3:$P$51,8,0) -> #N/A | M23: =vlookup(M22,'Report_Chi phi'!$A$3:$P$51,8,0) -> #N/A | N23: =vlookup(N22,'Report_Chi phi'!$A$3:$P$51,8,0) -> #N/A | O23: =sum(B23:N23) -> #N/A
A24: [Giá vốn]. Labo | B24: =vlookup(B22,'Report_Chi phi'!$A$3:$P$51,7,0) -> #N/A | C24: =vlookup(C22,'Report_Chi phi'!$A$3:$P$51,7,0) -> #N/A | D24: =vlookup(D22,'Report_Chi phi'!$A$3:$P$51,7,0) -> #N/A | F24: =vlookup(F22,'Report_Chi phi'!$A$3:$P$51,7,0) -> #N/A | G24: =vlookup(G22,'Report_Chi phi'!$A$3:$P$51,7,0) -> #N/A | H24: =vlookup(H22,'Report_Chi phi'!$A$3:$P$51,7,0) -> #N/A | I24: =vlookup(I22,'Report_Chi phi'!$A$3:$P$51,7,0) -> #N/A | J24: =vlookup(J22,'Report_Chi phi'!$A$3:$P$51,7,0) -> #N/A | K24: =vlookup(K22,'Report_Chi phi'!$A$3:$P$51,7,0) -> #N/A | L24: =vlookup(L22,'Report_Chi phi'!$A$3:$P$51,7,0) -> #N/A | M24: =vlookup(M22,'Report_Chi phi'!$A$3:$P$51,7,0) -> #N/A | N24: =vlookup(N22,'Report_Chi phi'!$A$3:$P$51,7,0) -> #N/A | O24: =sum(B24:N24) -> #N/A
B25: =sum(B23:B24) -> #N/A | C25: =sum(C23:C24) -> #N/A | D25: =sum(D23:D24) -> #N/A | F25: =sum(F23:F24) -> #N/A | G25: =sum(G23:G24) -> #N/A | H25: =sum(H23:H24) -> #N/A | I25: =sum(I23:I24) -> #N/A | J25: =sum(J23:J24) -> #N/A | K25: =sum(K23:K24) -> #N/A | L25: =sum(L23:L24) -> #N/A | M25: =sum(M23:M24) -> #N/A | N25: =sum(N23:N24) -> #N/A
A26: Hành chính | B26: =$A$1&"."&"01" -> 2024.01 | C26: =$A$1&"."&"02" -> 2024.02 | D26: =$A$1&"."&"03" -> 2024.03 | F26: =$A$1&"."&"04" -> 2024.04 | G26: =$A$1&"."&"05" -> 2024.05 | H26: =$A$1&"."&"06" -> 2024.06 | I26: =$A$1&"."&"07" -> 2024.07 | J26: =$A$1&"."&"08" -> 2024.08 | K26: =$A$1&"."&"09" -> 2024.09 | L26: =$A$1&"."&"10" -> 2024.10 | M26: =$A$1&"."&"11" -> 2024.11 | N26: =$A$1&"."&"12" -> 2024.12 | O26: Tổng
A27: [Hành chính].Điện | B27: =vlookup(B26,'Report_Chi phi'!$A$3:$P$51,10,0) -> #N/A | C27: =vlookup(C26,'Report_Chi phi'!$A$3:$P$51,10,0) -> #N/A | D27: =vlookup(D26,'Report_Chi phi'!$A$3:$P$51,10,0) -> #N/A | F27: =vlookup(F26,'Report_Chi phi'!$A$3:$P$51,10,0) -> #N/A | G27: =vlookup(G26,'Report_Chi phi'!$A$3:$P$51,10,0) -> #N/A | H27: =vlookup(H26,'Report_Chi phi'!$A$3:$P$51,10,0) -> #N/A | I27: =vlookup(I26,'Report_Chi phi'!$A$3:$P$51,10,0) -> #N/A | J27: =vlookup(J26,'Report_Chi phi'!$A$3:$P$51,10,0) -> #N/A | K27: =vlookup(K26,'Report_Chi phi'!$A$3:$P$51,10,0) -> #N/A | L27: =vlookup(L26,'Report_Chi phi'!$A$3:$P$51,10,0) -> #N/A | M27: =vlookup(M26,'Report_Chi phi'!$A$3:$P$51,10,0) -> #N/A | N27: =vlookup(N26,'Report_Chi phi'!$A$3:$P$51,10,0) -> #N/A | O27: =sum(B27:N27) -> #N/A
A28: [Hành chính].Nước | B28: =vlookup(B26,'Report_Chi phi'!$A$3:$P$51,11,0) -> #N/A | C28: =vlookup(C26,'Report_Chi phi'!$A$3:$P$51,11,0) -> #N/A | D28: =vlookup(D26,'Report_Chi phi'!$A$3:$P$51,11,0) -> #N/A | F28: =vlookup(F26,'Report_Chi phi'!$A$3:$P$51,11,0) -> #N/A | G28: =vlookup(G26,'Report_Chi phi'!$A$3:$P$51,11,0) -> #N/A | H28: =vlookup(H26,'Report_Chi phi'!$A$3:$P$51,11,0) -> #N/A | I28: =vlookup(I26,'Report_Chi phi'!$A$3:$P$51,11,0) -> #N/A | J28: =vlookup(J26,'Report_Chi phi'!$A$3:$P$51,11,0) -> #N/A | K28: =vlookup(K26,'Report_Chi phi'!$A$3:$P$51,11,0) -> #N/A | L28: =vlookup(L26,'Report_Chi phi'!$A$3:$P$51,11,0) -> #N/A | M28: =vlookup(M26,'Report_Chi phi'!$A$3:$P$51,11,0) -> #N/A | N28: =vlookup(N26,'Report_Chi phi'!$A$3:$P$51,11,0) -> #N/A | O28: =sum(B28:N28) -> #N/A
A29: [Hành chính].Chung | B29: =vlookup(B26,'Report_Chi phi'!$A$3:$P$51,9,0) -> #N/A | C29: =vlookup(C26,'Report_Chi phi'!$A$3:$P$51,9,0) -> #N/A | D29: =vlookup(D26,'Report_Chi phi'!$A$3:$P$51,9,0) -> #N/A | F29: =vlookup(F26,'Report_Chi phi'!$A$3:$P$51,9,0) -> #N/A | G29: =vlookup(G26,'Report_Chi phi'!$A$3:$P$51,9,0) -> #N/A | H29: =vlookup(H26,'Report_Chi phi'!$A$3:$P$51,9,0) -> #N/A | I29: =vlookup(I26,'Report_Chi phi'!$A$3:$P$51,9,0) -> #N/A | J29: =vlookup(J26,'Report_Chi phi'!$A$3:$P$51,9,0) -> #N/A | K29: =vlookup(K26,'Report_Chi phi'!$A$3:$P$51,9,0) -> #N/A | L29: =vlookup(L26,'Report_Chi phi'!$A$3:$P$51,9,0) -> #N/A | M29: =vlookup(M26,'Report_Chi phi'!$A$3:$P$51,9,0) -> #N/A | N29: =vlookup(N26,'Report_Chi phi'!$A$3:$P$51,9,0) -> #N/A | O29: =sum(B29:N29) -> #N/A
B30: =sum(B27:B29) -> #N/A | C30: =sum(C27:C29) -> #N/A | D30: =sum(D27:D29) -> #N/A | F30: =sum(F27:F29) -> #N/A | G30: =sum(G27:G29) -> #N/A | H30: =sum(H27:H29) -> #N/A | I30: =sum(I27:I29) -> #N/A | J30: =sum(J27:J29) -> #N/A | K30: =sum(K27:K29) -> #N/A | L30: =sum(L27:L29) -> #N/A | M30: =sum(M27:M29) -> #N/A | N30: =sum(N27:N29) -> #N/A
A31: Cấu hình tính giá vốn | B31: =$A$1&"."&"01" -> 2024.01 | C31: =$A$1&"."&"02" -> 2024.02 | D31: =$A$1&"."&"03" -> 2024.03 | F31: =$A$1&"."&"04" -> 2024.04 | G31: =$A$1&"."&"05" -> 2024.05 | H31: =$A$1&"."&"06" -> 2024.06 | I31: =$A$1&"."&"07" -> 2024.07 | J31: =$A$1&"."&"08" -> 2024.08 | K31: =$A$1&"."&"09" -> 2024.09 | L31: =$A$1&"."&"10" -> 2024.10 | M31: =$A$1&"."&"11" -> 2024.11 | N31: =$A$1&"."&"12" -> 2024.12 | O31: Tổng
A32: Giá vốn 1 răng | B32: 1000000 | C32: 1000000 | D32: 1000000 | F32: 2000000 | G32: 1000000 | H32: 1000000 | I32: 1000000 | J32: 1000000 | K32: 1000000 | L32: 1000000 | M32: 1000000 | N32: 1000000
A33: Đơn giá răng sứ | B33: 3000000 | C33: 2500000 | D33: 2500000 | F33: 2500000 | G33: 2500000 | H33: 2200000 | I33: 2500000 | J33: 2500000 | K33: 2500000 | L33: 2500000 | M33: 2500000 | N33: 2500000
A34: Biến phí | B34: =sum(B20:B21) -> #N/A | C34: =sum(C20:C21) -> #N/A | D34: =sum(D20:D21) -> #N/A | F34: =sum(F20:F21) -> #N/A | G34: =sum(G20:G21) -> #N/A | H34: =sum(H20:H21) -> #N/A | I34: =sum(I20:I21) -> #N/A | J34: =sum(J20:J21) -> #N/A | K34: =sum(K20:K21) -> #N/A | L34: =sum(L20:L21) -> #N/A | M34: =sum(M20:M21) -> #N/A | N34: =sum(N20:N21) -> #N/A
A35: Số răng sứ | B35: =round(B7/B32,1) -> #REF! | C35: =round(C7/C32,1) -> #REF! | D35: =round(D7/D32,1) -> #REF! | F35: =round(F7/F32,1) -> #REF! | G35: =round(G7/G32,1) -> #REF! | H35: =round(H7/H32,1) -> #REF! | I35: =round(I7/I32,1) -> #REF! | J35: =round(J7/J32,1) -> #REF! | K35: =round(K7/K32,1) -> #REF! | L35: =round(L7/L32,1) -> #REF! | M35: =round(M7/M32,1) -> #REF! | N35: =round(N7/N32,1) -> #REF!
A36: Doanh thu tính theo răng sứ | B36: =B33*B35 -> #REF! | C36: =C33*C35 -> #REF! | D36: =D33*D35 -> #REF! | F36: =F33*F35 -> #REF! | G36: =G33*G35 -> #REF! | H36: =H33*H35 -> #REF! | I36: =I33*I35 -> #REF! | J36: =J33*J35 -> #REF! | K36: =K33*K35 -> #REF! | L36: =L33*L35 -> #REF! | M36: =M33*M35 -> #REF! | N36: =N33*N35 -> #REF!
A37: Doanh thu thực tế | B37: =vlookup(B31,'Report_Doanh thu'!$A$2:$H$50,7,0) -> 3517022000 | C37: =vlookup(C31,'Report_Doanh thu'!$A$2:$H$50,7,0) -> 1700101000 | D37: =vlookup(D31,'Report_Doanh thu'!$A$2:$H$50,7,0) -> 2020806000 | F37: =vlookup(F31,'Report_Doanh thu'!$A$2:$H$50,7,0) -> 1711707000 | G37: =vlookup(G31,'Report_Doanh thu'!$A$2:$H$50,7,0) -> 1562947800 | H37: =vlookup(H31,'Report_Doanh thu'!$A$2:$H$50,7,0) -> 2122290000 | I37: =vlookup(I31,'Report_Doanh thu'!$A$2:$H$50,7,0) -> 3300551002 | J37: =vlookup(J31,'Report_Doanh thu'!$A$2:$H$50,7,0) -> 2090704801 | K37: =vlookup(K31,'Report_Doanh thu'!$A$2:$H$50,7,0) -> 2082261500 | L37: =vlookup(L31,'Report_Doanh thu'!$A$2:$H$50,7,0) -> 0 | M37: =vlookup(M31,'Report_Doanh thu'!$A$2:$H$50,7,0) -> 0 | N37: =vlookup(N31,'Report_Doanh thu'!$A$2:$H$50,7,0) -> 0
A38: KPI_BS(30%) | B38: =B36*0.3 -> #REF! | C38: =C36*0.3 -> #REF! | D38: =D36*0.3 -> #REF! | F38: =F36*0.3 -> #REF! | G38: =G36*0.3 -> #REF! | H38: =H36*0.3 -> #REF! | I38: =I36*0.3 -> #REF! | J38: =J36*0.3 -> #REF! | K38: =K36*0.3 -> #REF! | L38: =L36*0.3 -> #REF! | M38: =M36*0.3 -> #REF! | N38: =N36*0.3 -> #REF!
A39: Giá vốn (21%) | B39: 803070000 | C39: 526283000 | D39: 526437333 | F39: 325571166 | G39: 258758000
A40: Marketing (tuỳ ý phân bổ) | B40: 734000000 | C40: 454705933 | D40: 477778721 | F40: 305919900 | G40: 337589083
A41: chi phí marketing trên mỗi chiếc răng | B41: =B40/B35 -> #REF! | C41: =C40/C35 -> #REF! | D41: =D40/D35 -> #REF! | F41: =F40/F35 -> #REF! | G41: =G40/G35 -> #REF! | H41: =H40/H35 -> #REF! | I41: =I40/I35 -> #REF! | J41: =J40/J35 -> #REF! | K41: =K40/K35 -> #REF! | L41: =L40/L35 -> #REF! | M41: =M40/M35 -> #REF! | N41: =N40/N35 -> #REF!
...

Sheet Master data
A1: Phân loại | B1: Tài chính | C1: Dòng tiền | D1: Ngân sách | E1: Tỷ lệ | F1: Tháng cần so sánh | G1: 2024.08 | H1: 2000000000 | I1: Số tương đối | J1: Số tuyệt đối
A2: Marketing chạy Quảng cáo | B2: Chi phí bán hàng | C2: Biến phí | D2: 300000000 | E2: =D2/$D$30 -> 0.1540832 | F2: =vlookup($G$1,'Report_Chi phi'!$A$3:$AD$89,12,0) -> #N/A | G2: =F2/$F$30 -> #N/A | H2: =$H$1*E2 -> 3.0816641e+08 | I2: =F2-D2 -> #N/A | J2: =(E2-G2) -> #N/A
A3: KPI | B3: Chi phí bán hàng | C3: Biến phí | D3: 260000000 | E3: =D3/$D$30 -> 0.13353878 | F3: =vlookup($G$1,'Report_Chi phi'!$A$3:$AD$89,10,0) -> #N/A | G3: =F3/$F$30 -> #N/A | H3: =$H$1*E3 -> 2.6707756e+08 | I3: =F3-D3 -> #N/A | J3: =(E3-G3) -> #N/A
A4: Cộng tác viên | B4: Chi phí bán hàng | C4: Biến phí | D4: 40000000 | E4: =D4/$D$30 -> 0.020544427 | F4: =vlookup($G$1,'Report_Chi phi'!$A$3:$AD$89,4,0) -> #N/A | G4: =F4/$F$30 -> #N/A | H4: =$H$1*E4 -> 41088855 | I4: =F4-D4 -> #N/A | J4: =(E4-G4) -> #N/A
A5: Quỹ thưởng gián tiếp | B5: Chi phí bán hàng | C5: Biến phí | D5: 10000000 | E5: =D5/$D$30 -> 0.0051361068 | F5: =vlookup($G$1,'Report_Chi phi'!$A$3:$AD$89,16,0) -> #N/A | G5: =F5/$F$30 -> #N/A | H5: =$H$1*E5 -> 10272214 | I5: =F5-D5 -> #N/A | J5: =(E5-G5) -> #N/A
A6: Tiền vật liệu | B6: Chi phí giá vốn | C6: Biến phí | D6: 70000000 | E6: =D6/$D$30 -> 0.035952748 | F6: =vlookup($G$1,'Report_Chi phi'!$A$3:$AD$89,26,0) -> #N/A | G6: =F6/$F$30 -> #N/A | H6: =$H$1*E6 -> 71905496 | I6: =F6-D6 -> #N/A | J6: =(E6-G6) -> #N/A
A7: Hành chính MKT | B7: Chi phí bán hàng | C7: Biến phí | D7: 15000000 | E7: =D7/$D$30 -> 0.0077041602 | F7: =vlookup($G$1,'Report_Chi phi'!$A$3:$AD$89,8,0) -> #N/A | G7: =F7/$F$30 -> #N/A | H7: =$H$1*E7 -> 15408320 | I7: =F7-D7 -> #N/A | J7: =(E7-G7) -> #N/A
A8: Tiền Lab | B8: Chi phí giá vốn | C8: Biến phí | D8: 344000000 | E8: =D8/$D$30 -> 0.17668207 | F8: =vlookup($G$1,'Report_Chi phi'!$A$3:$AD$89,23,0) -> #N/A | G8: =F8/$F$30 -> #N/A | H8: =$H$1*E8 -> 353364150 | I8: =F8-D8 -> #N/A | J8: =(E8-G8) -> #N/A
A9: Hoa hồng giới thiệu | B9: Chi phí bán hàng | C9: Biến phí | D9: 40000000 | E9: =D9/$D$30 -> 0.020544427 | F9: =vlookup($G$1,'Report_Chi phi'!$A$3:$AD$89,9,0) -> #N/A | G9: =F9/$F$30 -> #N/A | H9: =$H$1*E9 -> 41088855 | I9: =F9-D9 -> #N/A | J9: =(E9-G9) -> #N/A
A10: Tiktok | B10: Chi phí bán hàng | C10: Biến phí | D10: 40000000 | E10: =D10/$D$30 -> 0.020544427 | F10: =vlookup($G$1,'Report_Chi phi'!$A$3:$AD$89,29,0) -> #N/A | G10: =F10/$F$30 -> #N/A | H10: =$H$1*E10 -> 41088855 | I10: =F10-D10 -> #N/A | J10: =(E10-G10) -> #N/A
A11: SEO | B11: Chi phí bán hàng | C11: Biến phí | D11: 15000000 | E11: =D11/$D$30 -> 0.0077041602 | F11: =vlookup($G$1,'Report_Chi phi'!$A$3:$AD$89,18,0) -> #N/A | G11: =F11/$F$30 -> #N/A | H11: =$H$1*E11 -> 15408320 | I11: =F11-D11 -> #N/A | J11: =(E11-G11) -> #N/A
A12: Phí cà thẻ | B12: Chi phí bán hàng | C12: Biến phí | D12: 5000000 | E12: =D12/$D$30 -> 0.0025680534 | F12: =vlookup($G$1,'Report_Chi phi'!$A$3:$AD$89,15,0) -> #N/A | G12: =F12/$F$30 -> #N/A | H12: =$H$1*E12 -> 5136106.8 | I12: =F12-D12 -> #N/A | J12: =(E12-G12) -> #N/A
A13: Tặng phẩm khách | B13: Chi phí bán hàng | C13: Biến phí | D13: 20000000 | E13: =D13/$D$30 -> 0.010272214 | F13: =vlookup($G$1,'Report_Chi phi'!$A$3:$AD$89,20,0) -> #N/A | G13: =F13/$F$30 -> #N/A | H13: =$H$1*E13 -> 20544427 | I13: =F13-D13 -> #N/A | J13: =(E13-G13) -> #N/A
A14: Tiếp khách phòng khám | B14: Chi phí bán hàng | C14: Biến phí | D14: 20000000 | E14: =D14/$D$30 -> 0.010272214 | F14: =vlookup($G$1,'Report_Chi phi'!$A$3:$AD$89,27,0) -> #N/A | G14: =F14/$F$30 -> #N/A | H14: =$H$1*E14 -> 20544427 | I14: =F14-D14 -> #N/A | J14: =(E14-G14) -> #N/A
A15: Lương | B15: Chi phí QLDN | C15: Định phí | D15: 320000000 | E15: =D15/$D$30 -> 0.16435542 | F15: =vlookup($G$1,'Report_Chi phi'!$A$3:$AD$89,11,0) -> #N/A | G15: =F15/$F$30 -> #N/A | H15: =$H$1*E15 -> 3.2871084e+08 | I15: =F15-D15 -> #N/A | J15: =(E15-G15) -> #N/A
A16: Quỹ thưởng tổng cuối năm | B16: Chi phí khác | C16: Định phí | D16: 30000000 | E16: =D16/$D$30 -> 0.01540832 | F16: =vlookup($G$1,'Report_Chi phi'!$A$3:$AD$89,17,0) -> #N/A | G16: =F16/$F$30 -> #N/A | H16: =$H$1*E16 -> 30816641 | I16: =F16-D16 -> #N/A | J16: =(E16-G16) -> #N/A
A17: Mua đồ hành chính | B17: Chi phí hành chính | C17: Biến phí | D17: 30000000 | E17: =D17/$D$30 -> 0.01540832 | F17: =vlookup($G$1,'Report_Chi phi'!$A$3:$AD$89,13,0) -> #N/A | G17: =F17/$F$30 -> #N/A | H17: =$H$1*E17 -> 30816641 | I17: =F17-D17 -> #N/A | J17: =(E17-G17) -> #N/A
A18: Sửa chữa | B18: Chi phí hành chính | C18: Định phí | D18: 12000000 | E18: =D18/$D$30 -> 0.0061633282 | F18: =vlookup($G$1,'Report_Chi phi'!$A$3:$AD$89,19,0) -> #N/A | G18: =F18/$F$30 -> #N/A | H18: =$H$1*E18 -> 12326656 | I18: =F18-D18 -> #N/A | J18: =(E18-G18) -> #N/A
A19: Tiền thuê xe | B19: Chi phí hành chính | C19: Định phí | D19: 23000000 | E19: =D19/$D$30 -> 0.011813046 | F19: =vlookup($G$1,'Report_Chi phi'!$A$3:$AD$89,24,0) -> #N/A | G19: =F19/$F$30 -> #N/A | H19: =$H$1*E19 -> 23626091 | I19: =F19-D19 -> #N/A | J19: =(E19-G19) -> #N/A
A20: Điện + Nước | B20: Chi phí hành chính | C20: Định phí | D20: 20000000 | E20: =D20/$D$30 -> 0.010272214 | F20: =vlookup($G$1,'Report_Chi phi'!$A$3:$AD$89,7,0) -> #N/A | G20: =F20/$F$30 -> #N/A | H20: =$H$1*E20 -> 20544427 | I20: =F20-D20 -> #N/A | J20: =(E20-G20) -> #N/A
A21: Đi trường | B21: Chi phí bán hàng | C21: Định phí | D21: 20000000 | E21: =D21/$D$30 -> 0.010272214 | F21: =vlookup($G$1,'Report_Chi phi'!$A$3:$AD$89,6,0) -> #N/A | G21: =F21/$F$30 -> #N/A | H21: =$H$1*E21 -> 20544427 | I21: =F21-D21 -> #N/A | J21: =(E21-G21) -> #N/A
A22: Tiếp khách | B22: Chi phí hành chính | C22: Định phí | D22: 20000000 | E22: =D22/$D$30 -> 0.010272214 | F22: =vlookup($G$1,'Report_Chi phi'!$A$3:$AD$89,27,0) -> #N/A | G22: =F22/$F$30 -> #N/A | H22: =$H$1*E22 -> 20544427 | I22: =F22-D22 -> #N/A | J22: =(E22-G22) -> #N/A
A23: Tiền dự trù phát sinh | B23: Chi phí khác | C23: Định phí | D23: 50000000 | E23: =D23/$D$30 -> 0.025680534 | F23: =vlookup($G$1,'Report_Chi phi'!$A$3:$AD$89,22,0) -> #N/A | G23: =F23/$F$30 -> #N/A | H23: =$H$1*E23 -> 51361068 | I23: =F23-D23 -> #N/A | J23: =(E23-G23) -> #N/A
A24: Chi phí Mặt bằng | B24: Chi phí QLDN | C24: Định phí | D24: 110000000 | E24: =D24/$D$30 -> 0.056497175 | F24: =vlookup($G$1,'Report_Chi phi'!$A$3:$AD$89,3,0) -> #N/A | G24: =F24/$F$30 -> #N/A | H24: =$H$1*E24 -> 1.1299435e+08 | I24: =F24-D24 -> #N/A | J24: =(E24-G24) -> #N/A
A25: Bảo hiểm | B25: Chi phí QLDN | C25: Định phí | D25: 20000000 | E25: =D25/$D$30 -> 0.010272214 | F25: =vlookup($G$1,'Report_Chi phi'!$A$3:$AD$89,2,0) -> #N/A | G25: =F25/$F$30 -> #N/A | H25: =$H$1*E25 -> 20544427 | I25: =F25-D25 -> #N/A | J25: =(E25-G25) -> #N/A
A26: Tiền thưởng nóng + liên hoan | B26: Chi phí khác | C26: Định phí | D26: 20000000 | E26: =D26/$D$30 -> 0.010272214 | F26: =vlookup($G$1,'Report_Chi phi'!$A$3:$AD$89,25,0) -> #N/A | G26: =F26/$F$30 -> #N/A | H26: =$H$1*E26 -> 20544427 | I26: =F26-D26 -> #N/A | J26: =(E26-G26) -> #N/A
A27: Thuê bằng | B27: Chi phí QLDN | C27: Định phí | D27: 18000000 | E27: =D27/$D$30 -> 0.0092449923 | F27: =vlookup($G$1,'Report_Chi phi'!$A$3:$AD$89,21,0) -> #N/A | G27: =F27/$F$30 -> #N/A | H27: =$H$1*E27 -> 18489985 | I27: =F27-D27 -> #N/A | J27: =(E27-G27) -> #N/A
A28: Đào tạo | B28: Chi phí khác | C28: Chi phí khác | D28: 5000000 | E28: =D28/$D$30 -> 0.0025680534 | F28: =vlookup($G$1,'Report_Chi phi'!$A$3:$AD$89,5,0) -> #N/A | G28: =F28/$F$30 -> #N/A | H28: =$H$1*E28 -> 5136106.8 | I28: =F28-D28 -> #N/A | J28: =(E28-G28) -> #N/A
A29: Mua sắm tài sản | B29: Chi phí khác | C29: Chi phí khác | D29: 70000000 | E29: =D29/$D$30 -> 0.035952748 | F29: =vlookup($G$1,'Report_Chi phi'!$A$3:$AD$89,14,0) -> #N/A | G29: =F29/$F$30 -> #N/A | H29: =$H$1*E29 -> 71905496 | I29: =F29-D29 -> #N/A | J29: =(E29-G29) -> #N/A
D30: =sum(D2:D29) -> 1947000000 | E30: =D30/$D$30 -> 1 | F30: =sum(F2:F29) -> #N/A | H30: =sum(H2:H29) -> 2000000000

Sheet Master_data
A1: ID | B1: Phân loại chi | C1: Tài chính | D1: Dòng tiền | F1: Tháng | G1: Năm | I1: Phân loại thu | K1: SAN | L1: Họ tên | M1: Bộ phận | O1: Nha khoa | Q1: TEENNIE | R1: Họ tên | S1: Bộ phận | T1: Tình trạng | U1: Nha khoa | W1: IMPLANT | X1: Họ tên | Y1: Bộ phận | Z1: Tình trạng | AA1: Nha khoa
A2: 2 | B2: Bảo hiểm | C2: Chi phí QLDN | D2: Định phí | F2: 01 | G2: 2018 | I2: Tiền mặt | K2: BS01 | L2: BS Công | M2: Bác sĩ | O2: SAN | Q2: 1 | R2: BS Công | S2: Bác sĩ | T2: Hoạt động | U2: TEENNIE | W2: 1 | X2: BS Công | Y2: Bác sĩ | Z2: Hoạt động | AA2: IMPLANT
A3: 3 | B3: Chi phí Mặt bằng | C3: Chi phí QLDN | D3: Định phí | F3: 02 | G3: 2019 | I3: Cà thẻ | K3: BS02 | L3: Bs Phong | M3: Bác sĩ | O3: SAN | Q3: 2 | R3: Bs Phong | S3: Bác sĩ | T3: Hoạt động | U3: TEENNIE | W3: 2 | X3: Bs Phong | Y3: Bác sĩ | Z3: Hoạt động | AA3: IMPLANT
A4: 4 | B4: Cộng tác viên | C4: Chi phí bán hàng | D4: Biến phí | F4: 03 | G4: 2020 | I4: Chuyển khoản | K4: BS03 | L4: Bs Tú | M4: Bác sĩ | O4: SAN | Q4: 3 | R4: Bs Tú | S4: Bác sĩ | T4: Hoạt động | U4: TEENNIE | W4: 3 | X4: Bs Tú | Y4: Bác sĩ | Z4: Hoạt động | AA4: IMPLANT
A5: 5 | B5: Đào tạo | C5: Chi phí khác | D5: Chi phí khác | F5: 04 | G5: 2021 | I5: Thực nhận cà thẻ | K5: BS04 | L5: Bs Dũng | M5: Bác sĩ | O5: SAN | Q5: 4 | R5: Bs Dũng | S5: Bác sĩ | T5: Hoạt động | U5: TEENNIE | W5: 4 | X5: Bs Dũng | Y5: Bác sĩ | Z5: Hoạt động | AA5: IMPLANT
A6: 6 | B6: Đi trường | C6: Chi phí bán hàng | D6: Định phí | F6: 05 | G6: 2022 | I6: Trả góp | K6: BS05 | L6: Bs Hải Anh | M6: Bác sĩ | O6: SAN
A7: 7 | B7: Điện + Nước | C7: Chi phí hành chính | D7: Định phí | F7: 06 | G7: 2023 | I7: Trả cọc | K7: VP01 | L7: Lương 3CĐ | M7: Văn phòng | O7: SAN
A8: 8 | B8: Hành chính MKT | C8: Chi phí bán hàng | D8: Biến phí | F8: 07 | G8: 2024 | I8: Tổng phí trừ cà thẻ | K8: PT01 | L8: PT Ngọc Tiên | M8: Phụ tá | O8: SAN | Q8: 5 | R8: PT Ngọc Tiên | S8: Phụ tá | T8: Hoạt động | U8: TEENNIE | W8: 5 | X8: PT Ngọc Tiên | Y8: Phụ tá | Z8: Hoạt động | AA8: IMPLANT
A9: 9 | B9: Hoa hồng giới thiệu | C9: Chi phí bán hàng | D9: Biến phí | F9: 08 | G9: 2025 | I9: Phí cà thẻ | K9: PT02 | L9: PT Cẩm Tiên | M9: Phụ tá | O9: SAN | Q9: 6 | R9: PT Cẩm Tiên | S9: Phụ tá | T9: Hoạt động | U9: TEENNIE | W9: 6 | X9: PT Cẩm Tiên | Y9: Phụ tá | Z9: Hoạt động | AA9: IMPLANT
A10: 10 | B10: KPI | C10: Chi phí bán hàng | D10: Biến phí | F10: 09 | G10: 2026 | K10: PT03 | L10: PT Ly | M10: Phụ tá | O10: SAN | Q10: 7 | R10: PT Ly | S10: Phụ tá | T10: Hoạt động | U10: TEENNIE | W10: 7 | X10: PT Ly | Y10: Phụ tá | Z10: Hoạt động | AA10: IMPLANT
A11: 11 | B11: Lương | C11: Chi phí QLDN | D11: Định phí | F11: 10 | G11: 2027 | K11: PT04 | L11: PT Kha | M11: Phụ tá | O11: SAN | Q11: 8 | R11: PT Kha | S11: Phụ tá | T11: Hoạt động | U11: TEENNIE | W11: 8 | X11: PT Kha | Y11: Phụ tá | Z11: Hoạt động | AA11: IMPLANT
A12: 12 | B12: Marketing chạy Quảng cáo | C12: Chi phí bán hàng | D12: Biến phí | G12: 2028 | K12: PT05 | L12: PT Kiều | M12: Phụ tá | O12: SAN | Q12: 9 | R12: PT Kiều | S12: Phụ tá | T12: Hoạt động | U12: TEENNIE | W12: 9 | X12: PT Kiều | Y12: Phụ tá | Z12: Hoạt động | AA12: IMPLANT
A13: 13 | B13: Mua đồ hành chính | C13: Chi phí hành chính | D13: Biến phí | G13: 2029 | K13: PT06 | L13: PT Trân | M13: Phụ tá | O13: SAN | Q13: 10 | R13: PT Trân | S13: Phụ tá | T13: Hoạt động | U13: TEENNIE | W13: 10 | X13: PT Trân | Y13: Phụ tá | Z13: Hoạt động | AA13: IMPLANT
A14: 14 | B14: Mua sắm tài sản | C14: Chi phí khác | D14: Chi phí khác | G14: 2030 | K14: PT07 | L14: PT Thế Anh | M14: Phụ tá | O14: SAN
A15: 15 | B15: Phí cà thẻ | C15: Chi phí bán hàng | D15: Biến phí | K15: PT08 | L15: PT Thanh Loan | M15: Phụ tá | O15: SAN | Q15: 11 | R15: LT Quỳnh Như | S15: Lễ tân | T15: Hoạt động | U15: TEENNIE | W15: 11 | X15: LT Quỳnh Như | Y15: Lễ tân | Z15: Hoạt động | AA15: IMPLANT
A16: 16 | B16: Quỹ thưởng gián tiếp | C16: Chi phí bán hàng | D16: Biến phí | K16: PT09 | L16: PT Thành học việc | M16: Phụ tá | O16: SAN | Q16: 12 | R16: LT Kim Ngân | S16: Lễ tân | T16: Hoạt động | U16: TEENNIE | W16: 12 | X16: LT Kim Ngân | Y16: Lễ tân | Z16: Hoạt động | AA16: IMPLANT
A17: 17 | B17: Quỹ thưởng tổng cuối năm | C17: Chi phí khác | D17: Định phí | K17: PT10 | L17: PT TRƯỞNG Cẩm Loan | M17: Phụ tá | O17: SAN | Q17: 13 | R17: Lt Tú Nhi | S17: Lễ tân | T17: Hoạt động | U17: TEENNIE | W17: 13 | X17: Lt Tú Nhi | Y17: Lễ tân | Z17: Hoạt động | AA17: IMPLANT
A18: 18 | B18: SEO | C18: Chi phí bán hàng | D18: Biến phí | K18: LT01 | L18: LT Quỳnh Như | M18: Lễ tân | O18: SAN | Q18: 14 | R18: LT Văn Tính | S18: Lễ tân | T18: Hoạt động | U18: TEENNIE | W18: 14 | X18: LT Văn Tính | Y18: Lễ tân | Z18: Hoạt động | AA18: IMPLANT
A19: 19 | B19: Sửa chữa | C19: Chi phí hành chính | D19: Định phí | K19: LT02 | L19: LT Kim Ngân | M19: Lễ tân | O19: SAN | Q19: 15 | R19: TV Đông | S19: Tư vấn | T19: Hoạt động | U19: TEENNIE | W19: 15 | X19: TV Đông | Y19: Tư vấn | Z19: Hoạt động | AA19: IMPLANT
A20: 20 | B20: Tặng phẩm khách | C20: Chi phí bán hàng | D20: Biến phí | K20: LT04 | L20: Lt Tú Nhi | M20: Lễ tân | O20: SAN | Q20: 16 | R20: Tv Na | S20: Tư vấn | T20: Hoạt động | U20: TEENNIE | W20: 16 | X20: Tv Na | Y20: Tư vấn | Z20: Hoạt động | AA20: IMPLANT
A21: 21 | B21: Thuê bằng | C21: Chi phí QLDN | D21: Định phí | K21: LT05 | L21: LT Văn Tính | M21: Lễ tân | O21: SAN | Q21: 17 | R21: Telesale Bí Nhi | S21: Telesale | T21: Hoạt động | U21: TEENNIE | W21: 17 | X21: Telesale Bí Nhi | Y21: Telesale | Z21: Hoạt động | AA21: IMPLANT
A22: 22 | B22: Tiền dự trù phát sinh | C22: Chi phí khác | D22: Định phí | K22: TV00 | L22: TV Đông | M22: Tư vấn | O22: SAN | Q22: 18 | R22: Telesale Yến | S22: Telesale | T22: Hoạt động | U22: TEENNIE | W22: 18 | X22: Telesale Yến | Y22: Telesale | Z22: Hoạt động | AA22: IMPLANT
A23: 23 | B23: Tiền Lab | C23: Chi phí giá vốn | D23: Biến phí | K23: TV01 | L23: Tv Na | M23: Tư vấn | O23: SAN | Q23: 19 | R23: Telesale Uyển Nhi | S23: Telesale | T23: Hoạt động | U23: TEENNIE | W23: 19 | X23: Telesale Uyển Nhi | Y23: Telesale | Z23: Hoạt động | AA23: IMPLANT
A24: 24 | B24: Tiền thuê xe | C24: Chi phí hành chính | D24: Định phí | K24: TV02 | L24: Tv Vy | M24: Tư vấn | O24: SAN | Q24: 20 | R24: Thầy Vinh PT | S24: Thầy | T24: Hoạt động | U24: TEENNIE | W24: 20 | X24: Thầy Vinh PT | Y24: Thầy | Z24: Hoạt động | AA24: IMPLANT
A25: 25 | B25: Tiền thưởng nóng + liên hoan | C25: Chi phí khác | D25: Định phí | K25: TV03 | L25: Telesale Bí Nhi | M25: Telesale | O25: SAN
A26: 26 | B26: Tiền vật liệu | C26: Chi phí giá vốn | D26: Biến phí | K26: TV04 | L26: Telesale Yến | M26: Telesale | O26: SAN | Q26: 21 | R26: Anh Hiền | S26: Văn phòng | T26: Hoạt động | U26: TEENNIE | W26: 21 | X26: Anh Hiền | Y26: Văn phòng | Z26: Hoạt động | AA26: IMPLANT
A27: 27 | B27: Tiếp khách | C27: Chi phí hành chính | D27: Định phí | K27: TV05 | L27: Telesale Uyển Nhi | M27: Telesale | O27: SAN | Q27: 22 | R27: Hiến | S27: Văn phòng | T27: Hoạt động | U27: TEENNIE | W27: 22 | X27: Hiến | Y27: Văn phòng | Z27: Hoạt động | AA27: IMPLANT
A28: 28 | B28: Tiktok | C28: Chi phí bán hàng | D28: Biến phí | K28: VP18 | L28: Thầy Vinh PT | M28: Văn phòng | O28: SAN | Q28: 23 | R28: Chị Phượng | S28: Văn phòng | T28: Hoạt động | U28: TEENNIE | W28: 23 | X28: Chị Phượng | Y28: Văn phòng | Z28: Hoạt động | AA28: IMPLANT
K29: TV07 | L29: CSKH Hoàng Lan | M29: CSKH | O29: SAN | Q29: 24 | R29: Duyên HCNS | S29: Văn phòng | T29: Hoạt động | U29: TEENNIE | W29: 24 | X29: Duyên HCNS | Y29: Văn phòng | Z29: Hoạt động | AA29: IMPLANT
K30: VP02 | L30: Anh Hiền | M30: Văn phòng | O30: SAN | Q30: 25 | R30: Kiểm soát Ngọc Lệ | S30: Văn phòng | T30: Hoạt động | U30: TEENNIE | W30: 25 | X30: Kiểm soát Ngọc Lệ | Y30: Văn phòng | Z30: Hoạt động | AA30: IMPLANT
K31: VP03 | L31: Hiến | M31: Văn phòng | O31: SAN | Q31: 26 | R31: Kim Hồng | S31: Văn phòng | T31: Hoạt động | U31: TEENNIE | W31: 26 | X31: Kim Hồng | Y31: Văn phòng | Z31: Hoạt động | AA31: IMPLANT
K32: VP04 | L32: Chị Phượng | M32: Văn phòng | O32: SAN | Q32: 27 | R32: Nhi (ngoc nhi 2727) | S32: Văn phòng | T32: Hoạt động | U32: TEENNIE | W32: 27 | X32: Nhi (ngoc nhi 2727) | Y32: Văn phòng | Z32: Hoạt động | AA32: IMPLANT
K33: VP05 | L33: Duyên HCNS | M33: Văn phòng | O33: SAN
K34: VP06 | L34: Kiểm soát Ngọc Lệ | M34: Văn phòng | O34: SAN | Q34: 28 | R34: MKT Minh Lâm | S34: Marketing | T34: Hoạt động | U34: TEENNIE | W34: 28 | X34: MKT Minh Lâm | Y34: Marketing | Z34: Hoạt động | AA34: IMPLANT
K35: VP07 | L35: Kim Hồng | M35: Văn phòng | O35: SAN | Q35: 29 | R35: MKT Bông | S35: Marketing | T35: Hoạt động | U35: TEENNIE | W35: 29 | X35: MKT Bông | Y35: Marketing | Z35: Hoạt động | AA35: IMPLANT
K36: VP08 | L36: Nhi (ngoc nhi 2727) | M36: Văn phòng | O36: SAN | Q36: 30 | R36: Trung Hào | S36: Marketing | T36: Hoạt động | U36: TEENNIE | W36: 30 | X36: Trung Hào | Y36: Marketing | Z36: Hoạt động | AA36: IMPLANT
K37: VP09 | L37: MKT Minh Lâm | M37: Marketing | O37: SAN | Q37: 31 | R37: Chụp hình Hùng | S37: Marketing | T37: Hoạt động | U37: TEENNIE | W37: 31 | X37: Chụp hình Hùng | Y37: Marketing | Z37: Hoạt động | AA37: IMPLANT
K38: VP10 | L38: MKT Bông | M38: Marketing | O38: SAN | Q38: 32 | R38: Lâm Trần Tuấn | S38: Marketing | T38: Hoạt động | U38: TEENNIE | W38: 32 | X38: Lâm Trần Tuấn | Y38: Marketing | Z38: Hoạt động | AA38: IMPLANT
K39: VP11 | L39: Trung Hào | M39: Marketing | O39: SAN | Q39: 33 | R39: MKT Anh TRung | S39: Marketing | T39: Hoạt động | U39: TEENNIE | W39: 33 | X39: MKT Anh TRung | Y39: Marketing | Z39: Hoạt động | AA39: IMPLANT
K40: VP12 | L40: Chụp hình Hùng | M40: Marketing | O40: SAN | Q40: 34 | R40: Kế toán + thuế | S40: Văn phòng | T40: Hoạt động | U40: TEENNIE | W40: 34 | X40: Kế toán + thuế | Y40: Văn phòng | Z40: Hoạt động | AA40: IMPLANT
...

Sheet Chi phi_San
A1: THÁNG | B1: NỘI DUNG CHI | C1: PHÂN LOẠI | D1: SỐ TIỀN | E1: DÒNG TIỀN | F1: TÀI CHÍNH
A2: 2021.01 | B2: Tổng hợp | C2: Mua đồ hành chính | D2: 0 | E2: =iferror(vlookup(C2,'Master data'!$A$2:$C$29,3,0),"-/-") -> Biến phí | F2: =iferror(vlookup(C2,'Master data'!$A$2:$C$29,2,0),"-/-") -> Chi phí hành chính
A3: 2021.01 | B3: hoa trái cây | C3: Mua đồ hành chính | D3: 948000 | E3: =iferror(vlookup(C3,'Master data'!$A$2:$C$29,3,0),"-/-") -> Biến phí | F3: =iferror(vlookup(C3,'Master data'!$A$2:$C$29,2,0),"-/-") -> Chi phí hành chính
A4: 2021.01 | B4: hoa trái cây | C4: Mua đồ hành chính | D4: 905000 | E4: =iferror(vlookup(C4,'Master data'!$A$2:$C$29,3,0),"-/-") -> Biến phí | F4: =iferror(vlookup(C4,'Master data'!$A$2:$C$29,2,0),"-/-") -> Chi phí hành chính
A5: 2021.01 | B5: hoa bi | C5: Mua đồ hành chính | D5: 120000 | E5: =iferror(vlookup(C5,'Master data'!$A$2:$C$29,3,0),"-/-") -> Biến phí | F5: =iferror(vlookup(C5,'Master data'!$A$2:$C$29,2,0),"-/-") -> Chi phí hành chính
A6: 2021.01 | B6: Lương cứng t1 | C6: Lương | D6: 366774927 | E6: =iferror(vlookup(C6,'Master data'!$A$2:$C$29,3,0),"-/-") -> Định phí | F6: =iferror(vlookup(C6,'Master data'!$A$2:$C$29,2,0),"-/-") -> Chi phí QLDN
A7: 2021.01 | B7: Lương KPI t1 | C7: KPI | D7: 340881611 | E7: =iferror(vlookup(C7,'Master data'!$A$2:$C$29,3,0),"-/-") -> Biến phí | F7: =iferror(vlookup(C7,'Master data'!$A$2:$C$29,2,0),"-/-") -> Chi phí bán hàng
A8: 2021.01 | B8: hoa trái cây | C8: Mua đồ hành chính | D8: 895000 | E8: =iferror(vlookup(C8,'Master data'!$A$2:$C$29,3,0),"-/-") -> Biến phí | F8: =iferror(vlookup(C8,'Master data'!$A$2:$C$29,2,0),"-/-") -> Chi phí hành chính
A9: 2021.01 | B9: cúng m2 | C9: Mua đồ hành chính | D9: 1264000 | E9: =iferror(vlookup(C9,'Master data'!$A$2:$C$29,3,0),"-/-") -> Biến phí | F9: =iferror(vlookup(C9,'Master data'!$A$2:$C$29,2,0),"-/-") -> Chi phí hành chính
A10: 2021.01 | B10: hoa trái cây | C10: Mua đồ hành chính | D10: 910000 | E10: =iferror(vlookup(C10,'Master data'!$A$2:$C$29,3,0),"-/-") -> Biến phí | F10: =iferror(vlookup(C10,'Master data'!$A$2:$C$29,2,0),"-/-") -> Chi phí hành chính
A11: 2021.01 | B11: hoa trái cây | C11: Mua đồ hành chính | D11: 910000 | E11: =iferror(vlookup(C11,'Master data'!$A$2:$C$29,3,0),"-/-") -> Biến phí | F11: =iferror(vlookup(C11,'Master data'!$A$2:$C$29,2,0),"-/-") -> Chi phí hành chính
A12: 2021.01 | B12: cúng m16 | C12: Mua đồ hành chính | D12: 880000 | E12: =iferror(vlookup(C12,'Master data'!$A$2:$C$29,3,0),"-/-") -> Biến phí | F12: =iferror(vlookup(C12,'Master data'!$A$2:$C$29,2,0),"-/-") -> Chi phí hành chính
A13: 2021.01 | B13: 1thang chè vp+203 | C13: Mua đồ hành chính | D13: 1200000 | E13: =iferror(vlookup(C13,'Master data'!$A$2:$C$29,3,0),"-/-") -> Biến phí | F13: =iferror(vlookup(C13,'Master data'!$A$2:$C$29,2,0),"-/-") -> Chi phí hành chính
... A5713: 2025.10 | B5713: đào tạo nhân sự | C5713: Đào tạo | D5713: 5751667 | E5713: =iferror(vlookup(C5713,'Master data'!$A$2:$C$29,3,0),"-/-") -> Chi phí khác | F5713: =iferror(vlookup(C5713,'Master data'!$A$2:$C$29,2,0),"-/-") -> Chi phí khác
D5714: 0 | E5714: =iferror(vlookup(C5714,'Master data'!$A$2:$C$29,3,0),"-/-") -> -/- | F5714: =iferror(vlookup(C5714,'Master data'!$A$2:$C$29,2,0),"-/-") -> -/-
D5715: 0 | E5715: =iferror(vlookup(C5715,'Master data'!$A$2:$C$29,3,0),"-/-") -> -/- | F5715: =iferror(vlookup(C5715,'Master data'!$A$2:$C$29,2,0),"-/-") -> -/-
D5716: 0 | E5716: =iferror(vlookup(C5716,'Master data'!$A$2:$C$29,3,0),"-/-") -> -/- | F5716: =iferror(vlookup(C5716,'Master data'!$A$2:$C$29,2,0),"-/-") -> -/-
D5717: 0 | E5717: =iferror(vlookup(C5717,'Master data'!$A$2:$C$29,3,0),"-/-") -> -/- | F5717: =iferror(vlookup(C5717,'Master data'!$A$2:$C$29,2,0),"-/-") -> -/-
D5718: 0 | E5718: =iferror(vlookup(C5718,'Master data'!$A$2:$C$29,3,0),"-/-") -> -/- | F5718: =iferror(vlookup(C5718,'Master data'!$A$2:$C$29,2,0),"-/-") -> -/-
D5719: 0 | E5719: =iferror(vlookup(C5719,'Master data'!$A$2:$C$29,3,0),"-/-") -> -/- | F5719: =iferror(vlookup(C5719,'Master data'!$A$2:$C$29,2,0),"-/-") -> -/-
D5720: 0 | E5720: =iferror(vlookup(C5720,'Master data'!$A$2:$C$29,3,0),"-/-") -> -/- | F5720: =iferror(vlookup(C5720,'Master data'!$A$2:$C$29,2,0),"-/-") -> -/-
D5721: 0 | E5721: =iferror(vlookup(C5721,'Master data'!$A$2:$C$29,3,0),"-/-") -> -/- | F5721: =iferror(vlookup(C5721,'Master data'!$A$2:$C$29,2,0),"-/-") -> -/-
D5722: 0 | E5722: =iferror(vlookup(C5722,'Master data'!$A$2:$C$29,3,0),"-/-") -> -/- | F5722: =iferror(vlookup(C5722,'Master data'!$A$2:$C$29,2,0),"-/-") -> -/-
D5723: 0 | E5723: =iferror(vlookup(C5723,'Master data'!$A$2:$C$29,3,0),"-/-") -> -/- | F5723: =iferror(vlookup(C5723,'Master data'!$A$2:$C$29,2,0),"-/-") -> -/-
D5724: 0 | E5724: =iferror(vlookup(C5724,'Master data'!$A$2:$C$29,3,0),"-/-") -> -/- | F5724: =iferror(vlookup(C5724,'Master data'!$A$2:$C$29,2,0),"-/-") -> -/-
D5725: 0 | E5725: =iferror(vlookup(C5725,'Master data'!$A$2:$C$29,3,0),"-/-") -> -/- | F5725: =iferror(vlookup(C5725,'Master data'!$A$2:$C$29,2,0),"-/-") -> -/-
... D6940: 0 | E6940: =iferror(vlookup(C6940,'Master data'!$A$2:$C$29,3,0),"-/-") -> -/- | F6940: =iferror(vlookup(C6940,'Master data'!$A$2:$C$29,2,0),"-/-") -> -/-
D6941: 0 | E6941: =vlookup(C6941,'Master data'!$A$2:$C$29,3,0) -> #N/A | F6941: =vlookup(C6941,'Master data'!$A$2:$C$29,2,0) -> #N/A
D6942: 0 | E6942: =vlookup(C6942,'Master data'!$A$2:$C$29,3,0) -> #N/A | F6942: =vlookup(C6942,'Master data'!$A$2:$C$29,2,0) -> #N/A
D6943: 0 | E6943: =vlookup(C6943,'Master data'!$A$2:$C$29,3,0) -> #N/A | F6943: =vlookup(C6943,'Master data'!$A$2:$C$29,2,0) -> #N/A
D6944: 0 | E6944: =vlookup(C6944,'Master data'!$A$2:$C$29,3,0) -> #N/A | F6944: =vlookup(C6944,'Master data'!$A$2:$C$29,2,0) -> #N/A
D6945: 0 | E6945: =vlookup(C6945,'Master data'!$A$2:$C$29,3,0) -> #N/A | F6945: =vlookup(C6945,'Master data'!$A$2:$C$29,2,0) -> #N/A
D6946: 0 | E6946: =vlookup(C6946,'Master data'!$A$2:$C$29,3,0) -> #N/A | F6946: =vlookup(C6946,'Master data'!$A$2:$C$29,2,0) -> #N/A
D6947: 0 | E6947: =vlookup(C6947,'Master data'!$A$2:$C$29,3,0) -> #N/A | F6947: =vlookup(C6947,'Master data'!$A$2:$C$29,2,0) -> #N/A
D6948: 0 | E6948: =vlookup(C6948,'Master data'!$A$2:$C$29,3,0) -> #N/A | F6948: =vlookup(C6948,'Master data'!$A$2:$C$29,2,0) -> #N/A
D6949: 0 | E6949: =vlookup(C6949,'Master data'!$A$2:$C$29,3,0) -> #N/A | F6949: =vlookup(C6949,'Master data'!$A$2:$C$29,2,0) -> #N/A
D6950: 0 | E6950: =vlookup(C6950,'Master data'!$A$2:$C$29,3,0) -> #N/A | F6950: =vlookup(C6950,'Master data'!$A$2:$C$29,2,0) -> #N/A
D6951: 0 | E6951: =vlookup(C6951,'Master data'!$A$2:$C$29,3,0) -> #N/A | F6951: =vlookup(C6951,'Master data'!$A$2:$C$29,2,0) -> #N/A
D6952: 0 | E6952: =vlookup(C6952,'Master data'!$A$2:$C$29,3,0) -> #N/A | F6952: =vlookup(C6952,'Master data'!$A$2:$C$29,2,0) -> #N/A
... D7831: 0 | E7831: =vlookup(C7831,'Master data'!$A$2:$C$29,3,0) -> #N/A | F7831: =vlookup(C7831,'Master data'!$A$2:$C$29,2,0) -> #N/A

Sheet Doanh thu_San
A1: THÁNG | B1: NGÀY | C1: TIỀN MẶT | D1: CÀ THẺ | E1: THỰC NHẬN CÀ THẺ | F1: CHUYỂN KHOẢN | G1: TRẢ GÓP | H1: TRẢ CỌC | I1: TỔNG | J1: TỔNG TRỪ PHÍ CÀ THẺ
A2: 2021.01 | B2: 44197 | C2: 0 | D2: 0 | E2: 0 | F2: 0 | H2: 0 | I2: 0 | J2: 0
A3: 2021.01 | B3: 44198 | C3: 94400000 | D3: 14280000 | E3: 14059710 | F3: 0 | H3: 0 | I3: 108680000 | J3: 108459710
A4: 2021.01 | B4: 44199 | C4: 9308000 | D4: 65000000 | E4: 63903500 | F4: 10400000 | H4: 0 | I4: 84708000 | J4: 83611500
A5: 2021.01 | B5: 44200 | C5: 8401000 | D5: 0 | E5: 0 | F5: 13780000 | H5: 0 | I5: 22181000 | J5: 22181000
A6: 2021.01 | B6: 44201 | C6: 127000000 | D6: 0 | E6: 0 | F6: 45000000 | H6: 0 | I6: 172000000 | J6: 172000000
A7: 2021.01 | B7: 44202 | C7: 36650000 | D7: 40000000 | E7: 39280000 | F7: 21730000 | H7: 0 | I7: 98380000 | J7: 97660000
A8: 2021.01 | B8: 44203 | C8: 5000000 | D8: 10000000 | E8: 9815000 | F8: 0 | H8: 0 | I8: 15000000 | J8: 14815000
A9: 2021.01 | B9: 44204 | C9: 112778000 | D9: 0 | E9: 0 | F9: 10000000 | H9: 10800000 | I9: 122778000 | J9: 122778000
A10: 2021.01 | B10: 44205 | C10: 11000000 | D10: 21870000 | E10: 21476340 | F10: 0 | H10: 0 | I10: 32870000 | J10: 32476340
A11: 2021.01 | B11: 44206 | C11: 12000000 | D11: 9050000 | E11: 8888000 | F11: 37295000 | H11: 0 | I11: 58345000 | J11: 58183000
A12: 2021.01 | B12: 44207 | C12: 0 | D12: 34680000 | E12: 34461385 | F12: 100225000 | H12: 0 | I12: 134905000 | J12: 134686385
A13: 2021.01 | B13: 44208 | C13: 99360000 | D13: 40297500 | E13: 40125364 | F13: 16738000 | H13: 0 | I13: 156395500 | J13: 156223364
... A365: 2021.12 | B365: 44560 | C365: 44780000 | D365: 27180000 | E365: 27016680 | F365: 1450000 | H365: 0 | I365: 73410000 | J365: 73246680
A366: 2021.12 | B366: 44561 | C366: 31200000 | D366: 10000000 | E366: 9939760 | H366: 0 | I366: 41200000 | J366: 41139760
A367: 2022.01 | B367: 44562 | C367: 0 | D367: 0 | E367: 0 | F367: 0 | H367: 0 | I367: 0 | J367: 0
A368: 2022.01 | B368: 44563 | C368: 0 | D368: 0 | E368: 0 | F368: 0 | H368: 0 | I368: 0 | J368: 0
A369: 2022.01 | B369: 44564 | C369: 20700000 | D369: 0 | E369: 0 | F369: 0 | H369: 0 | I369: 20700000 | J369: 20700000
A370: 2022.01 | B370: 44565 | C370: 5000000 | D370: 5350000 | E370: 5317060 | F370: 42450000 | H370: 0 | I370: 52800000 | J370: 52767060
A371: 2022.01 | B371: 44566 | C371: 18930000 | D371: 630000 | E371: 619920 | F371: 70000000 | H371: 1780000 | I371: 87780000 | J371: 87769920
A372: 2022.01 | B372: 44567 | C372: 17350000 | D372: 0 | E372: 0 | F372: 0 | H372: 0 | I372: 17350000 | J372: 17350000
A373: 2022.01 | B373: 44568 | C373: 700000 | D373: 0 | E373: 0 | F373: 100745300 | H373: 10000000 | I373: 91445300 | J373: 91445300
A374: 2022.01 | B374: 44569 | C374: 10123000 | D374: 56000000 | E374: 55103360 | F374: 0 | H374: 0 | I374: 66123000 | J374: 65226360
A375: 2022.01 | B375: 44570 | C375: 2500000 | D375: 11110000 | E375: 10939000 | F375: 129000000 | H375: 0 | I375: 142610000 | J375: 142439000
A376: 2022.01 | B376: 44571 | C376: 8300000 | D376: 100000000 | E376: 98400000 | F376: 0 | H376: 0 | I376: 108300000 | J376: 106700000
A377: 2022.01 | B377: 44572 | C377: 89253000 | D377: 1550000 | E377: 1524000 | F377: 93805000 | H377: 0 | I377: 184608000 | J377: 184582000
A378: 2022.01 | B378: 44573 | C378: 0 | D378: 0 | E378: 0 | F378: 11100000 | H378: 0 | I378: 11100000 | J378: 11100000
... A392: 2022.01 | B392: 44587 | C392: 0 | D392: 0 | E392: 0 | F392: 8600000 | H392: 0 | I392: 8600000 | J392: 8600000
A393: 2022.01 | B393: 44588 | C393: 5750000 | D393: 2500000 | E393: 2458000 | F393: 5100000 | I393: 13350000 | J393: 13308000
A394: 2022.01 | B394: 44589 | C394: 0 | D394: 0 | E394: 0 | F394: 0 | H394: 0 | I394: 0 | J394: 0
A395: 2022.01 | B395: 44590 | C395: 0 | D395: 0 | E395: 0 | F395: 0 | H395: 0 | I395: 0 | J395: 0
A396: 2022.01 | B396: 44591 | C396: 0 | D396: 0 | E396: 0 | F396: 0 | H396: 0 | I396: 0 | J396: 0
A397: 2022.01 | B397: 44592 | C397: 0 | D397: 0 | E397: 0 | F397: 0 | H397: 0 | I397: 0 | J397: 0
A398: 2022.02 | B398: 44593 | C398: 0 | D398: 0 | E398: 0 | F398: 0 | H398: 0 | I398: 0 | J398: 0
A399: 2022.02 | B399: 44594 | C399: 0 | D399: 0 | E399: 0 | F399: 0 | H399: 0 | I399: 0 | J399: 0
A400: 2022.02 | B400: 44595 | C400: 0 | D400: 0 | E400: 0 | F400: 0 | H400: 0 | I400: 0 | J400: 0
A401: 2022.02 | B401: 44596 | C401: 0 | D401: 0 | E401: 0 | F401: 0 | H401: 0 | I401: 0 | J401: 0
A402: 2022.02 | B402: 44597 | C402: 0 | D402: 0 | E402: 0 | F402: 0 | H402: 0 | I402: 0 | J402: 0
A403: 2022.02 | B403: 44598 | C403: 0 | D403: 0 | E403: 0 | F403: 0 | H403: 0 | I403: 0 | J403: 0
A404: 2022.02 | B404: 44599 | C404: 0 | D404: 0 | E404: 0 | F404: 0 | H404: 0 | I404: 0 | J404: 0
...

Sheet Lương_SAN
A1: Tháng | B1: ID | C1: Chức danh | D1: Họ và Tên | E1: LCB | F1: Năng lực | G1: Thâm niên | H1: Kiêm việc | I1: Trợ cấp | J1: Công chuẩn | K1: Công thực tế | L1: Số giờ tăng ca | M1: Tiền tăng ca | N1: Khấu trừ | O1: Tạm ứng | P1: KPI công việc | Q1: KPI doanh số 15 | R1: Lương cứng | S1: Tổng lương | T1: Thực nhận | U1: Cột 21
A2: 2024.01 | B2: BS01 | C2: =iferror(vlookup($B2,Master_data!$K$1:$M$190,3,0),"--") -> Bác sĩ | D2: =iferror(vlookup($B2,Master_data!$K$1:$M$190,2,0),"--") -> BS Công | E2: 25000000 | F2: 0 | G2: 0 | H2: 0 | I2: 0 | J2: 22 | K2: 24 | L2: 0 | M2: 0 | N2: 0 | P2: 0 | Q2: 107565816 | S2: 29790210 | T2: 137356026
A3: 2024.01 | B3: BS02 | C3: =iferror(vlookup($B3,Master_data!$K$1:$M$190,3,0),"--") -> Bác sĩ | D3: =iferror(vlookup($B3,Master_data!$K$1:$M$190,2,0),"--") -> Bs Phong | E3: 15000000 | F3: 0 | G3: 0 | H3: 0 | I3: 0 | J3: 26 | K3: 25 | L3: 0 | M3: 0 | N3: 0 | P3: 0 | Q3: 47337895 | S3: 14423077 | T3: 61760972
A4: 2024.01 | B4: BS03 | C4: =iferror(vlookup($B4,Master_data!$K$1:$M$190,3,0),"--") -> Bác sĩ | D4: =iferror(vlookup($B4,Master_data!$K$1:$M$190,2,0),"--") -> Bs Tú | E4: 15000000 | F4: 0 | G4: 0 | H4: 0 | I4: 0 | J4: 26 | K4: 27.5 | L4: 0 | M4: 0 | N4: 0 | P4: 0 | Q4: 103537080 | S4: 15865385 | T4: 119402465
A5: 2024.01 | B5: BS04 | C5: =iferror(vlookup($B5,Master_data!$K$1:$M$190,3,0),"--") -> Bác sĩ | D5: =iferror(vlookup($B5,Master_data!$K$1:$M$190,2,0),"--") -> Bs Dũng | E5: 0 | F5: 0 | G5: 0 | H5: 0 | I5: 0 | J5: 0 | K5: 0 | L5: 0 | M5: 0 | N5: 0 | P5: 0 | Q5: 152200000 | S5: 0 | T5: 152200000
A6: 2024.01 | B6: PT01 | C6: =iferror(vlookup($B6,Master_data!$K$1:$M$190,3,0),"--") -> Phụ tá | D6: =iferror(vlookup($B6,Master_data!$K$1:$M$190,2,0),"--") -> PT Ngọc Tiên | E6: 5000000 | F6: 500000 | G6: 0 | H6: 0 | I6: 300000 | J6: 26 | K6: 32.5 | L6: 0 | M6: 0 | N6: 0 | P6: 0 | Q6: 5300000 | S6: 8550000 | T6: 13850000
A7: 2024.01 | B7: PT02 | C7: =iferror(vlookup($B7,Master_data!$K$1:$M$190,3,0),"--") -> Phụ tá | D7: =iferror(vlookup($B7,Master_data!$K$1:$M$190,2,0),"--") -> PT Cẩm Tiên | E7: 5000000 | F7: 500000 | G7: 0 | H7: 500000 | I7: 300000 | J7: 26 | K7: 27.965 | L7: 0 | M7: 0 | N7: 525840 | P7: 1500000 | Q7: 4235000 | S7: 7652045 | T7: 12412885
A8: 2024.01 | B8: PT03 | C8: =iferror(vlookup($B8,Master_data!$K$1:$M$190,3,0),"--") -> Phụ tá | D8: =iferror(vlookup($B8,Master_data!$K$1:$M$190,2,0),"--") -> PT Ly | E8: 5000000 | F8: 1000000 | G8: 1000000 | H8: 0 | I8: 300000 | J8: 26 | K8: 31.8 | L8: 0 | M8: 0 | N8: 525840 | P8: 1500000 | Q8: 6075000 | S8: 9389545 | T8: 15990385
A9: 2024.01 | B9: PT04 | C9: =iferror(vlookup($B9,Master_data!$K$1:$M$190,3,0),"--") -> Phụ tá | D9: =iferror(vlookup($B9,Master_data!$K$1:$M$190,2,0),"--") -> PT Kha | E9: 5000000 | F9: 1000000 | G9: 0 | H9: 0 | I9: 300000 | J9: 26 | K9: 28.68 | L9: 0 | M9: 0 | N9: 0 | P9: 1500000 | Q9: 3790000 | S9: 8315385 | T9: 12105385
A10: 2024.01 | B10: PT05 | C10: =iferror(vlookup($B10,Master_data!$K$1:$M$190,3,0),"--") -> Phụ tá | D10: =iferror(vlookup($B10,Master_data!$K$1:$M$190,2,0),"--") -> PT Kiều | E10: 6800000 | F10: 0 | G10: 0 | H10: 0 | I10: 0 | J10: 26 | K10: 27.0625 | L10: 0 | M10: 0 | N10: 0 | P10: 1500000 | Q10: 1110000 | S10: 7148317 | T10: 8258317
A11: 2024.01 | B11: PT06 | C11: =iferror(vlookup($B11,Master_data!$K$1:$M$190,3,0),"--") -> Phụ tá | D11: =iferror(vlookup($B11,Master_data!$K$1:$M$190,2,0),"--") -> PT Trân | E11: 7650000 | F11: 0 | G11: 0 | H11: 0 | I11: 0 | J11: 26 | K11: 28.206 | L11: 0 | M11: 0 | N11: 0 | P11: -200000 | Q11: 0 | S11: 8249073 | T11: 8249073
A12: 2024.01 | B12: LT01 | C12: =iferror(vlookup($B12,Master_data!$K$1:$M$190,3,0),"--") -> Lễ tân | D12: =iferror(vlookup($B12,Master_data!$K$1:$M$190,2,0),"--") -> LT Quỳnh Như | E12: 3500000 | F12: 2500000 | G12: 0 | H12: 0 | I12: 300000 | J12: 26 | K12: 26 | L12: 0 | M12: 0 | N12: 5525840 | P12: -50000 | Q12: 2196062 | S12: 774160 | T12: 8496062
A13: 2024.01 | B13: LT02 | C13: =iferror(vlookup($B13,Master_data!$K$1:$M$190,3,0),"--") -> Lễ tân | D13: =iferror(vlookup($B13,Master_data!$K$1:$M$190,2,0),"--") -> LT Kim Ngân | E13: 2500000 | F13: 1000000 | G13: 0 | H13: 0 | I13: 150000 | J13: 26 | K13: 26.3125 | L13: 0 | M13: 0 | N13: 5525840 | P13: 0 | Q13: 2196062 | S13: -1170792 | T13: 6551110
... A47: 2024.02 | B47: BS04 | C47: =iferror(vlookup($B47,Master_data!$K$1:$M$190,3,0),"--") -> Bác sĩ | D47: =iferror(vlookup($B47,Master_data!$K$1:$M$190,2,0),"--") -> Bs Dũng | E47: 0 | F47: 0 | G47: 0 | H47: 0 | I47: 0 | J47: 0 | K47: 0 | L47: 0 | M47: 0 | N47: 0 | P47: 0 | Q47: 0 | S47: 0 | T47: 0
A48: 2024.02 | B48: PT01 | C48: =iferror(vlookup($B48,Master_data!$K$1:$M$190,3,0),"--") -> Phụ tá | D48: =iferror(vlookup($B48,Master_data!$K$1:$M$190,2,0),"--") -> PT Ngọc Tiên | E48: 5000000 | F48: 500000 | G48: 0 | H48: 0 | I48: 300000 | J48: 26 | K48: 25.75 | L48: 16.4 | M48: 394231 | P48: 1500000 | Q48: 2465000 | S48: 7646154 | T48: 10111154
A49: 2024.02 | B49: PT02 | C49: =iferror(vlookup($B49,Master_data!$K$1:$M$190,3,0),"--") -> Phụ tá | D49: =iferror(vlookup($B49,Master_data!$K$1:$M$190,2,0),"--") -> PT Cẩm Tiên | E49: 5000000 | F49: 500000 | G49: 0 | H49: 500000 | I49: 300000 | J49: 26 | K49: 26 | L49: 9.7 | M49: 233173 | N49: 525840 | P49: 1500000 | Q49: 1310000 | S49: 7507333 | T49: 9343173
A50: 2024.02 | B50: PT03 | C50: =iferror(vlookup($B50,Master_data!$K$1:$M$190,3,0),"--") -> Phụ tá | D50: =iferror(vlookup($B50,Master_data!$K$1:$M$190,2,0),"--") -> PT Ly | E50: 5000000 | F50: 1000000 | G50: 1000000 | I50: 300000 | J50: 26 | K50: 26 | L50: 14.65 | M50: 352163 | N50: 525840 | P50: 1500000 | Q50: 2200000 | S50: 8626323 | T50: 11352163
A51: 2024.02 | B51: PT04 | C51: =iferror(vlookup($B51,Master_data!$K$1:$M$190,3,0),"--") -> Phụ tá | D51: =iferror(vlookup($B51,Master_data!$K$1:$M$190,2,0),"--") -> PT Kha | E51: 5000000 | F51: 1000000 | I51: 300000 | J51: 26 | K51: 22.70625 | L51: 8.1 | M51: 194712 | P51: 1500000 | Q51: 2490000 | S51: 7361298 | T51: 9851298
A52: 2024.02 | B52: PT05 | C52: =iferror(vlookup($B52,Master_data!$K$1:$M$190,3,0),"--") -> Phụ tá | D52: =iferror(vlookup($B52,Master_data!$K$1:$M$190,2,0),"--") -> PT Kiều | E52: 6800000 | F52: 500000 | I52: 300000 | J52: 26 | K52: 22.875 | L52: 9.4 | M52: 225962 | P52: 1500000 | Q52: 1560000 | S52: 6925000 | T52: 8485000
A53: 2024.02 | B53: PT06 | C53: =iferror(vlookup($B53,Master_data!$K$1:$M$190,3,0),"--") -> Phụ tá | D53: =iferror(vlookup($B53,Master_data!$K$1:$M$190,2,0),"--") -> PT Trân | E53: 7650000 | F53: 500000 | G53: 0 | H53: 0 | I53: 300000 | J53: 26 | K53: 23.1375 | L53: 10.8 | M53: 259615 | P53: 1500000 | Q53: 1255000 | S53: 7009135 | T53: 8264135
A54: 2024.02 | B54: LT01 | C54: =iferror(vlookup($B54,Master_data!$K$1:$M$190,3,0),"--") -> Lễ tân | D54: =iferror(vlookup($B54,Master_data!$K$1:$M$190,2,0),"--") -> LT Quỳnh Như | E54: 3500000 | F54: 2500000 | G54: 0 | H54: 0 | I54: 300000 | J54: 26 | K54: 24.5 | L54: 0 | M54: 0 | N54: 2525840 | P54: 0 | Q54: 544458 | S54: 3572237 | T54: 6642535
A55: 2024.02 | B55: LT02 | C55: =iferror(vlookup($B55,Master_data!$K$1:$M$190,3,0),"--") -> Lễ tân | D55: =iferror(vlookup($B55,Master_data!$K$1:$M$190,2,0),"--") -> LT Kim Ngân | E55: 2500000 | F55: 1000000 | G55: 0 | H55: 0 | I55: 150000 | J55: 26 | K55: 22.5 | L55: 5 | M55: 60096 | N55: 525840 | P55: 725000 | Q55: 544458 | S55: 3572718 | T55: 4643016
A56: 2024.02 | B56: LT04 | C56: =iferror(vlookup($B56,Master_data!$K$1:$M$190,3,0),"--") -> Lễ tân | D56: =iferror(vlookup($B56,Master_data!$K$1:$M$190,2,0),"--") -> Lt Tú Nhi | E56: 2500000 | F56: 750000 | G56: 0 | H56: 0 | I56: 150000 | J56: 26 | K56: 26 | L56: 4 | M56: 48077 | N56: 525840 | P56: 725000 | Q56: 544458 | S56: 3647237 | T56: 4717535
A57: 2024.02 | B57: LT05 | C57: =iferror(vlookup($B57,Master_data!$K$1:$M$190,3,0),"--") -> Lễ tân | D57: =iferror(vlookup($B57,Master_data!$K$1:$M$190,2,0),"--") -> LT Văn Tính | E57: 2500000 | F57: 750000 | G57: 0 | H57: 0 | I57: 150000 | J57: 26 | K57: 25.75 | L57: 4 | M57: 48077 | N57: 525840 | P57: 700000 | Q57: 544458 | S57: 3598198 | T57: 4668496
A58: 2024.02 | B58: TV00 | C58: =iferror(vlookup($B58,Master_data!$K$1:$M$190,3,0),"--") -> Tư vấn | D58: =iferror(vlookup($B58,Master_data!$K$1:$M$190,2,0),"--") -> TV Đông | E58: 2500000 | F58: 500000 | G58: 0 | H58: 0 | I58: 150000 | J58: 26 | K58: 24.22 | L58: 0 | M58: 0 | N58: 525840 | P58: 50000 | Q58: 5628279 | S58: 2503006 | T58: 8657125
A59: 2024.02 | B59: TV01 | C59: =iferror(vlookup($B59,Master_data!$K$1:$M$190,3,0),"--") -> Tư vấn | D59: =iferror(vlookup($B59,Master_data!$K$1:$M$190,2,0),"--") -> Tv Na | E59: 2500000 | F59: 500000 | G59: 0 | H59: 0 | I59: 150000 | J59: 26 | K59: 24.85 | L59: 5.7 | M59: 68510 | N59: 525840 | P59: 50000 | Q59: 5121267 | S59: 2632093 | T59: 8279200
A60: 2024.02 | B60: TV03 | C60: =iferror(vlookup($B60,Master_data!$K$1:$M$190,3,0),"--") -> Telesale | D60: =iferror(vlookup($B60,Master_data!$K$1:$M$190,2,0),"--") -> Telesale Bí Nhi | E60: 1666667 | F60: 333333 | G60: 0 | H60: 0 | I60: 100000 | J60: 26 | K60: 34 | L60: 0 | M60: 0 | N60: 525840 | P60: -100000 | Q60: 6379914 | S60: 1986981 | T60: 8892735
A61: 2024.02 | B61: TV04 | C61: =iferror(vlookup($B61,Master_data!$K$1:$M$190,3,0),"--") -> Telesale | D61: =iferror(vlookup($B61,Master_data!$K$1:$M$190,2,0),"--") -> Telesale Yến | E61: 1666667 | F61: 333333 | G61: 0 | H61: 0 | I61: 100000 | J61: 26 | K61: 31.5 | L61: 0 | M61: 0 | P61: -50000 | Q61: 5866132 | S61: 2402564 | T61: 8268696
A62: 2024.02 | B62: TV05 | C62: =iferror(vlookup($B62,Master_data!$K$1:$M$190,3,0),"--") -> Telesale | D62: =iferror(vlookup($B62,Master_data!$K$1:$M$190,2,0),"--") -> Telesale Uyển Nhi | E62: 3333333 | F62: 0 | G62: 0 | H62: 0 | I62: 0 | J62: 26 | K62: 26 | L62: 0 | M62: 0 | N62: 525840 | P62: 0 | Q62: 0 | S62: 2807493 | T62: 3333333
A63: 2024.02 | B63: VP02 | C63: =iferror(vlookup($B63,Master_data!$K$1:$M$190,3,0),"--") -> Văn phòng | D63: =iferror(vlookup($B63,Master_data!$K$1:$M$190,2,0),"--") -> Anh Hiền | E63: 20333333 | F63: 0 | G63: 0 | H63: 0 | I63: 0 | J63: 26 | K63: 26 | L63: 0 | M63: 0 | N63: 333333 | P63: 0 | Q63: 0 | S63: 20000000 | T63: 20333333
A64: 2024.02 | B64: VP03 | C64: =iferror(vlookup($B64,Master_data!$K$1:$M$190,3,0),"--") -> Văn phòng | D64: =iferror(vlookup($B64,Master_data!$K$1:$M$190,2,0),"--") -> Hiến | E64: 18333333 | F64: 0 | G64: 0 | H64: 0 | I64: 0 | J64: 26 | K64: 26 | L64: 0 | M64: 0 | N64: 525840 | P64: 0 | Q64: 0 | S64: 17807493 | T64: 18333333
A65: 2024.02 | B65: VP04 | C65: =iferror(vlookup($B65,Master_data!$K$1:$M$190,3,0),"--") -> Văn phòng | D65: =iferror(vlookup($B65,Master_data!$K$1:$M$190,2,0),"--") -> Chị Phượng | E65: 15000000 | F65: 0 | G65: 0 | H65: 0 | I65: 0 | J65: 26 | K65: 26 | L65: 0 | M65: 0 | N65: 1383333 | P65: 0 | Q65: 0 | S65: 13616667 | T65: 15000000
A66: 2024.02 | B66: VP05 | C66: =iferror(vlookup($B66,Master_data!$K$1:$M$190,3,0),"--") -> Văn phòng | D66: =iferror(vlookup($B66,Master_data!$K$1:$M$190,2,0),"--") -> Duyên HCNS | E66: 5333333 | F66: 0 | G66: 0 | H66: 0 | I66: 0 | J66: 26 | K66: 26 | L66: 0 | M66: 0 | N66: 333333 | P66: 0 | Q66: 0 | S66: 5000000 | T66: 5333333
A67: 2024.02 | B67: VP06 | C67: =iferror(vlookup($B67,Master_data!$K$1:$M$190,3,0),"--") -> Văn phòng | D67: =iferror(vlookup($B67,Master_data!$K$1:$M$190,2,0),"--") -> Kiểm soát Ngọc Lệ | E67: 6000000 | F67: 0 | G67: 0 | H67: 0 | I67: 0 | J67: 26 | K67: 26 | L67: 0 | M67: 0 | N67: 525840 | P67: 0 | Q67: 0 | S67: 5474160 | T67: 6000000
A68: 2024.02 | B68: VP07 | C68: =iferror(vlookup($B68,Master_data!$K$1:$M$190,3,0),"--") -> Văn phòng | D68: =iferror(vlookup($B68,Master_data!$K$1:$M$190,2,0),"--") -> Kim Hồng | E68: 4166667 | F68: 0 | G68: 0 | H68: 0 | I68: 0 | J68: 26 | K68: 23.5 | L68: 0 | M68: 0 | N68: 0 | P68: 0 | Q68: 527778 | S68: 3766026 | T68: 4293803
